Workbook

Sheet Inputs
B1: MA E3 TOU Sensitivity — Input Parameters
B3: SYSTEM SPECIFICATIONS
B4: PV Capacity | C4: 4.72 | D4: kW | E4: State median (MA)
B5: Battery Capacity | C5: 13.5 | D5: kWh
B6: Battery Power | C6: 5 | D6: kW
B7: PV Annual Generation | C7: 5794 | D7: kWh | E7: PySAM v3, Boston 2023
B9: SYSTEM COSTS (Tao Sun MA)
B10: Solar $/kW | C10: 3540 | E10: Tao Sun Supp Table 15
B11: Solar Total | C11: =C4*C10
B12: Battery $/kWh | C12: 1488 | E12: Tao Sun Supp Table 15
B13: Battery Total | C13: =C5*C12
B14: PV+S Total | C14: =C11+C13
B16: FINANCIAL PARAMETERS
B17: Loan Interest Rate | C17: 0.0724
B18: Loan Term | C18: 25 | D18: years
B19: Customer Discount Rate | C19: 0.064
B20: Electricity Cost Escalation | C20: 0.025
B22: E3 TOU RATES (2035 Illustrative) | E22: E3 Long-Term Ratemaking Study (Feb 2025), Fig 8
B23: Winter On-Peak (5-8pm) | C23: 0.43 | D23: $/kWh
B24: Winter Mid-Peak | C24: 0.33
B25: Winter Off-Peak | C25: 0.21
B26: Summer On-Peak (5-8pm) | C26: 0.27
B27: Summer Mid-Peak | C27: 0.23
B28: Summer Off-Peak | C28: 0.19
B29: Fixed Monthly Charge | C29: 40 | D29: $/mo
B30: Bill w/o System (E3 TOU) | C30: 2852.74 | D30: $/yr | E30: PySAM v3
B32: INCENTIVES
B33: Federal ITC | C33: 0 | D33: % | E33: Expired Dec 2025
B34: State Tax Credit | C34: 1000 | D34: $ | E34: 15% cap $1,000, Mass.gov
B35: SMART Solar Only $/yr | C35: 348 | E35: 5,794 kWh × $0.06, 225 CMR 28.13
B36: SMART PV+S $/yr | C36: 579 | E36: 5,794 kWh × $0.10, 225 CMR 28.13
B37: ConnectedSolutions $/yr | C37: 1375 | E37: $275/kW × 5kW, MassSave
B38: SMART Term | C38: 20 | D38: years | E38: 225 CMR 28.13(1)
B39: ConnSol Lock Period | C39: 5 | D39: years | E39: Rate locked first 5 summers
B41: PYSAM BILL SAVINGS (Year 1)
B42: Export Scenario | C42: Solar Only | D42: PV+S
B43: NM (1:1 at TOU) | C43: 1528.17 | D43: 1509.69
B44: NB100 (100%) | C44: 1528.17 | D44: 1509.69
B45: NB75 (75%) | C45: 1494.6 | D45: 1488.15
B46: NB50 (50%) | C46: 1307.57 | D46: 1320.44

Sheet TOU NM
A5: Solar Only — All Incentives
A6: Year | B6: 0 | C6: 1 | D6: 2 | E6: 3 | F6: 4 | G6: 5 | H6: 6 | I6: 7 | J6: 8 | K6: 9 | L6: 10 | M6: 11 | N6: 12 | O6: 13 | P6: 14 | Q6: 15 | R6: 16 | S6: 17 | T6: 18 | U6: 19 | V6: 20 | W6: 21 | X6: 22 | Y6: 23 | Z6: 24 | AA6: 25
A7: Debt Balance ($) | B7: =Inputs!C11-Inputs!C34 | C7: =B7-C9 | D7: =C7-D9 | E7: =D7-E9 | F7: =E7-F9 | G7: =F7-G9 | H7: =G7-H9 | I7: =H7-I9 | J7: =I7-J9 | ... AA7: =Z7-AA9
A8: Interest Payment ($) | B8: 0 | C8: =B7*Inputs!$C$17 | D8: =C7*Inputs!$C$17 | E8: =D7*Inputs!$C$17 | F8: =E7*Inputs!$C$17 | G8: =F7*Inputs!$C$17 | H8: =G7*Inputs!$C$17 | I8: =H7*Inputs!$C$17 | J8: =I7*Inputs!$C$17 | ... AA8: =Z7*Inputs!$C$17
A9: Principal Payment ($) | B9: 0 | C9: =-PMT(Inputs!$C$17,Inputs!$C$18,$B$7)-C8 | D9: =-PMT(Inputs!$C$17,Inputs!$C$18,$B$7)-D8 | E9: =-PMT(Inputs!$C$17,Inputs!$C$18,$B$7)-E8 | F9: =-PMT(Inputs!$C$17,Inputs!$C$18,$B$7)-F8 | G9: =-PMT(Inputs!$C$17,Inputs!$C$18,$B$7)-G8 | H9: =-PMT(Inputs!$C$17,Inputs!$C$18,$B$7)-H8 | I9: =-PMT(Inputs!$C$17,Inputs!$C$18,$B$7)-I8 | J9: =-PMT(Inputs!$C$17,Inputs!$C$18,$B$7)-J8 | ... AA9: =-PMT(Inputs!$C$17,Inputs!$C$18,$B$7)-AA8
A10: Total P&I Payment ($) | B10: 0 | C10: =C8+C9 | D10: =D8+D9 | E10: =E8+E9 | F10: =F8+F9 | G10: =G8+G9 | H10: =H8+H9 | I10: =I8+I9 | J10: =J8+J9 | ... AA10: =AA8+AA9
A11: Bill w/o System ($) | B11: 0 | C11: =Inputs!$C$30 | D11: =C11*(1+Inputs!$C$20) | E11: =D11*(1+Inputs!$C$20) | F11: =E11*(1+Inputs!$C$20) | G11: =F11*(1+Inputs!$C$20) | H11: =G11*(1+Inputs!$C$20) | I11: =H11*(1+Inputs!$C$20) | J11: =I11*(1+Inputs!$C$20) | K11: =J11*(1+Inputs!$C$20) | ... AA11: =Z11*(1+Inputs!$C$20)
A12: Bill w/ System ($) | B12: 0 | C12: =C11-Inputs!$C$43 | D12: =D11-Inputs!$C$43*(1+Inputs!$C$20)^(2-1) | E12: =E11-Inputs!$C$43*(1+Inputs!$C$20)^(3-1) | F12: =F11-Inputs!$C$43*(1+Inputs!$C$20)^(4-1) | G12: =G11-Inputs!$C$43*(1+Inputs!$C$20)^(5-1) | H12: =H11-Inputs!$C$43*(1+Inputs!$C$20)^(6-1) | I12: =I11-Inputs!$C$43*(1+Inputs!$C$20)^(7-1) | J12: =J11-Inputs!$C$43*(1+Inputs!$C$20)^(8-1) | K12: =K11-Inputs!$C$43*(1+Inputs!$C$20)^(9-1) | L12: =L11-Inputs!$C$43*(1+Inputs!$C$20)^(10-1) | M12: =M11-Inputs!$C$43*(1+Inputs!$C$20)^(11-1) | N12: =N11-Inputs!$C$43*(1+Inputs!$C$20)^(12-1) | O12: =O11-Inputs!$C$43*(1+Inputs!$C$20)^(13-1) | P12: =P11-Inputs!$C$43*(1+Inputs!$C$20)^(14-1) | Q12: =Q11-Inputs!$C$43*(1+Inputs!$C$20)^(15-1) | R12: =R11-Inputs!$C$43*(1+Inputs!$C$20)^(16-1) | S12: =S11-Inputs!$C$43*(1+Inputs!$C$20)^(17-1) | T12: =T11-Inputs!$C$43*(1+Inputs!$C$20)^(18-1) | U12: =U11-Inputs!$C$43*(1+Inputs!$C$20)^(19-1) | V12: =V11-Inputs!$C$43*(1+Inputs!$C$20)^(20-1) | W12: =W11-Inputs!$C$43*(1+Inputs!$C$20)^(21-1) | X12: =X11-Inputs!$C$43*(1+Inputs!$C$20)^(22-1) | Y12: =Y11-Inputs!$C$43*(1+Inputs!$C$20)^(23-1) | Z12: =Z11-Inputs!$C$43*(1+Inputs!$C$20)^(24-1) | AA12: =AA11-Inputs!$C$43*(1+Inputs!$C$20)^(25-1)
A13: Bill Savings ($) | B13: 0 | C13: =C11-C12 | D13: =D11-D12 | E13: =E11-E12 | F13: =F11-F12 | G13: =G11-G12 | H13: =H11-H12 | I13: =I11-I12 | J13: =J11-J12 | ... AA13: =AA11-AA12
A14: Incentive Annual ($) | B14: 0 | C14: =IF(1<=Inputs!$C$38,Inputs!$C$35,0) | D14: =IF(2<=Inputs!$C$38,Inputs!$C$35,0) | E14: =IF(3<=Inputs!$C$38,Inputs!$C$35,0) | F14: =IF(4<=Inputs!$C$38,Inputs!$C$35,0) | G14: =IF(5<=Inputs!$C$38,Inputs!$C$35,0) | H14: =IF(6<=Inputs!$C$38,Inputs!$C$35,0) | I14: =IF(7<=Inputs!$C$38,Inputs!$C$35,0) | J14: =IF(8<=Inputs!$C$38,Inputs!$C$35,0) | K14: =IF(9<=Inputs!$C$38,Inputs!$C$35,0) | L14: =IF(10<=Inputs!$C$38,Inputs!$C$35,0) | M14: =IF(11<=Inputs!$C$38,Inputs!$C$35,0) | N14: =IF(12<=Inputs!$C$38,Inputs!$C$35,0) | O14: =IF(13<=Inputs!$C$38,Inputs!$C$35,0) | P14: =IF(14<=Inputs!$C$38,Inputs!$C$35,0) | Q14: =IF(15<=Inputs!$C$38,Inputs!$C$35,0) | R14: =IF(16<=Inputs!$C$38,Inputs!$C$35,0) | S14: =IF(17<=Inputs!$C$38,Inputs!$C$35,0) | T14: =IF(18<=Inputs!$C$38,Inputs!$C$35,0) | U14: =IF(19<=Inputs!$C$38,Inputs!$C$35,0) | V14: =IF(20<=Inputs!$C$38,Inputs!$C$35,0) | W14: =IF(21<=Inputs!$C$38,Inputs!$C$35,0) | X14: =IF(22<=Inputs!$C$38,Inputs!$C$35,0) | Y14: =IF(23<=Inputs!$C$38,Inputs!$C$35,0) | Z14: =IF(24<=Inputs!$C$38,Inputs!$C$35,0) | AA14: =IF(25<=Inputs!$C$38,Inputs!$C$35,0)
A15: Total Savings ($) | B15: 0 | C15: =C13+C14 | D15: =D13+D14 | E15: =E13+E14 | F15: =F13+F14 | G15: =G13+G14 | H15: =H13+H14 | I15: =I13+I14 | J15: =J13+J14 | ... AA15: =AA13+AA14
A16: Net Savings ($) | B16: 0 | C16: =C15-C10 | D16: =D15-D10 | E16: =E15-E10 | F16: =F15-F10 | G16: =G15-G10 | H16: =H15-H10 | I16: =I15-I10 | J16: =J15-J10 | ... AA16: =AA15-AA10
A17: Cumulative NPV ($) | B17: 0 | C17: =C16/(1+Inputs!$C$19)^1 | D17: =C17+D16/(1+Inputs!$C$19)^2 | E17: =D17+E16/(1+Inputs!$C$19)^3 | F17: =E17+F16/(1+Inputs!$C$19)^4 | G17: =F17+G16/(1+Inputs!$C$19)^5 | H17: =G17+H16/(1+Inputs!$C$19)^6 | I17: =H17+I16/(1+Inputs!$C$19)^7 | J17: =I17+J16/(1+Inputs!$C$19)^8 | K17: =J17+K16/(1+Inputs!$C$19)^9 | L17: =K17+L16/(1+Inputs!$C$19)^10 | M17: =L17+M16/(1+Inputs!$C$19)^11 | N17: =M17+N16/(1+Inputs!$C$19)^12 | O17: =N17+O16/(1+Inputs!$C$19)^13 | P17: =O17+P16/(1+Inputs!$C$19)^14 | Q17: =P17+Q16/(1+Inputs!$C$19)^15 | R17: =Q17+R16/(1+Inputs!$C$19)^16 | S17: =R17+S16/(1+Inputs!$C$19)^17 | T17: =S17+T16/(1+Inputs!$C$19)^18 | U17: =T17+U16/(1+Inputs!$C$19)^19 | V17: =U17+V16/(1+Inputs!$C$19)^20 | W17: =V17+W16/(1+Inputs!$C$19)^21 | X17: =W17+X16/(1+Inputs!$C$19)^22 | Y17: =X17+Y16/(1+Inputs!$C$19)^23 | Z17: =Y17+Z16/(1+Inputs!$C$19)^24 | AA17: =Z17+AA16/(1+Inputs!$C$19)^25
A18: Simple Payback (yr) | B18: =IF((C13+C14)>0,B7/(C13+C14),"N/A")
A19: NPV Breakeven Year | B19: See Cumulative NPV row 17 for first year ≥ 0
A22: Solar Only — No Incentives
A23: Year | B23: 0 | C23: 1 | D23: 2 | E23: 3 | F23: 4 | G23: 5 | H23: 6 | I23: 7 | J23: 8 | K23: 9 | L23: 10 | M23: 11 | N23: 12 | O23: 13 | P23: 14 | Q23: 15 | R23: 16 | S23: 17 | T23: 18 | U23: 19 | V23: 20 | W23: 21 | X23: 22 | Y23: 23 | Z23: 24 | AA23: 25
A24: Debt Balance ($) | B24: =Inputs!C11 | C24: =B24-C26 | D24: =C24-D26 | E24: =D24-E26 | F24: =E24-F26 | G24: =F24-G26 | H24: =G24-H26 | I24: =H24-I26 | J24: =I24-J26 | ... AA24: =Z24-AA26
A25: Interest Payment ($) | B25: 0 | C25: =B24*Inputs!$C$17 | D25: =C24*Inputs!$C$17 | E25: =D24*Inputs!$C$17 | F25: =E24*Inputs!$C$17 | G25: =F24*Inputs!$C$17 | H25: =G24*Inputs!$C$17 | I25: =H24*Inputs!$C$17 | J25: =I24*Inputs!$C$17 | ... AA25: =Z24*Inputs!$C$17
A26: Principal Payment ($) | B26: 0 | C26: =-PMT(Inputs!$C$17,Inputs!$C$18,$B$24)-C25 | D26: =-PMT(Inputs!$C$17,Inputs!$C$18,$B$24)-D25 | E26: =-PMT(Inputs!$C$17,Inputs!$C$18,$B$24)-E25 | F26: =-PMT(Inputs!$C$17,Inputs!$C$18,$B$24)-F25 | G26: =-PMT(Inputs!$C$17,Inputs!$C$18,$B$24)-G25 | H26: =-PMT(Inputs!$C$17,Inputs!$C$18,$B$24)-H25 | I26: =-PMT(Inputs!$C$17,Inputs!$C$18,$B$24)-I25 | J26: =-PMT(Inputs!$C$17,Inputs!$C$18,$B$24)-J25 | ... AA26: =-PMT(Inputs!$C$17,Inputs!$C$18,$B$24)-AA25
A27: Total P&I Payment ($) | B27: 0 | C27: =C25+C26 | D27: =D25+D26 | E27: =E25+E26 | F27: =F25+F26 | G27: =G25+G26 | H27: =H25+H26 | I27: =I25+I26 | J27: =J25+J26 | ... AA27: =AA25+AA26
A28: Bill w/o System ($) | B28: 0 | C28: =Inputs!$C$30 | D28: =C28*(1+Inputs!$C$20) | E28: =D28*(1+Inputs!$C$20) | F28: =E28*(1+Inputs!$C$20) | G28: =F28*(1+Inputs!$C$20) | H28: =G28*(1+Inputs!$C$20) | I28: =H28*(1+Inputs!$C$20) | J28: =I28*(1+Inputs!$C$20) | K28: =J28*(1+Inputs!$C$20) | ... AA28: =Z28*(1+Inputs!$C$20)
A29: Bill w/ System ($) | B29: 0 | C29: =C28-Inputs!$C$43 | D29: =D28-Inputs!$C$43*(1+Inputs!$C$20)^(2-1) | E29: =E28-Inputs!$C$43*(1+Inputs!$C$20)^(3-1) | F29: =F28-Inputs!$C$43*(1+Inputs!$C$20)^(4-1) | G29: =G28-Inputs!$C$43*(1+Inputs!$C$20)^(5-1) | H29: =H28-Inputs!$C$43*(1+Inputs!$C$20)^(6-1) | I29: =I28-Inputs!$C$43*(1+Inputs!$C$20)^(7-1) | J29: =J28-Inputs!$C$43*(1+Inputs!$C$20)^(8-1) | K29: =K28-Inputs!$C$43*(1+Inputs!$C$20)^(9-1) | L29: =L28-Inputs!$C$43*(1+Inputs!$C$20)^(10-1) | M29: =M28-Inputs!$C$43*(1+Inputs!$C$20)^(11-1) | N29: =N28-Inputs!$C$43*(1+Inputs!$C$20)^(12-1) | O29: =O28-Inputs!$C$43*(1+Inputs!$C$20)^(13-1) | P29: =P28-Inputs!$C$43*(1+Inputs!$C$20)^(14-1) | Q29: =Q28-Inputs!$C$43*(1+Inputs!$C$20)^(15-1) | R29: =R28-Inputs!$C$43*(1+Inputs!$C$20)^(16-1) | S29: =S28-Inputs!$C$43*(1+Inputs!$C$20)^(17-1) | T29: =T28-Inputs!$C$43*(1+Inputs!$C$20)^(18-1) | U29: =U28-Inputs!$C$43*(1+Inputs!$C$20)^(19-1) | V29: =V28-Inputs!$C$43*(1+Inputs!$C$20)^(20-1) | W29: =W28-Inputs!$C$43*(1+Inputs!$C$20)^(21-1) | X29: =X28-Inputs!$C$43*(1+Inputs!$C$20)^(22-1) | Y29: =Y28-Inputs!$C$43*(1+Inputs!$C$20)^(23-1) | Z29: =Z28-Inputs!$C$43*(1+Inputs!$C$20)^(24-1) | AA29: =AA28-Inputs!$C$43*(1+Inputs!$C$20)^(25-1)
A30: Bill Savings ($) | B30: 0 | C30: =C28-C29 | D30: =D28-D29 | E30: =E28-E29 | F30: =F28-F29 | G30: =G28-G29 | H30: =H28-H29 | I30: =I28-I29 | J30: =J28-J29 | ... AA30: =AA28-AA29
A31: Incentive Annual ($) | B31: 0 | C31: 0 | D31: 0 | E31: 0 | F31: 0 | G31: 0 | H31: 0 | I31: 0 | J31: 0 | K31: 0 | L31: 0 | M31: 0 | N31: 0 | O31: 0 | P31: 0 | Q31: 0 | R31: 0 | S31: 0 | T31: 0 | U31: 0 | V31: 0 | W31: 0 | X31: 0 | Y31: 0 | Z31: 0 | AA31: 0
A32: Total Savings ($) | B32: 0 | C32: =C30+C31 | D32: =D30+D31 | E32: =E30+E31 | F32: =F30+F31 | G32: =G30+G31 | H32: =H30+H31 | I32: =I30+I31 | J32: =J30+J31 | ... AA32: =AA30+AA31
A33: Net Savings ($) | B33: 0 | C33: =C32-C27 | D33: =D32-D27 | E33: =E32-E27 | F33: =F32-F27 | G33: =G32-G27 | H33: =H32-H27 | I33: =I32-I27 | J33: =J32-J27 | ... AA33: =AA32-AA27
A34: Cumulative NPV ($) | B34: 0 | C34: =C33/(1+Inputs!$C$19)^1 | D34: =C34+D33/(1+Inputs!$C$19)^2 | E34: =D34+E33/(1+Inputs!$C$19)^3 | F34: =E34+F33/(1+Inputs!$C$19)^4 | G34: =F34+G33/(1+Inputs!$C$19)^5 | H34: =G34+H33/(1+Inputs!$C$19)^6 | I34: =H34+I33/(1+Inputs!$C$19)^7 | J34: =I34+J33/(1+Inputs!$C$19)^8 | K34: =J34+K33/(1+Inputs!$C$19)^9 | L34: =K34+L33/(1+Inputs!$C$19)^10 | M34: =L34+M33/(1+Inputs!$C$19)^11 | N34: =M34+N33/(1+Inputs!$C$19)^12 | O34: =N34+O33/(1+Inputs!$C$19)^13 | P34: =O34+P33/(1+Inputs!$C$19)^14 | Q34: =P34+Q33/(1+Inputs!$C$19)^15 | R34: =Q34+R33/(1+Inputs!$C$19)^16 | S34: =R34+S33/(1+Inputs!$C$19)^17 | T34: =S34+T33/(1+Inputs!$C$19)^18 | U34: =T34+U33/(1+Inputs!$C$19)^19 | V34: =U34+V33/(1+Inputs!$C$19)^20 | W34: =V34+W33/(1+Inputs!$C$19)^21 | X34: =W34+X33/(1+Inputs!$C$19)^22 | Y34: =X34+Y33/(1+Inputs!$C$19)^23 | Z34: =Y34+Z33/(1+Inputs!$C$19)^24 | AA34: =Z34+AA33/(1+Inputs!$C$19)^25
A35: Simple Payback (yr) | B35: =IF((C30+C31)>0,B24/(C30+C31),"N/A")
A36: NPV Breakeven Year | B36: See Cumulative NPV row 34 for first year ≥ 0
A39: PV+Storage — All Incentives
A40: Year | B40: 0 | C40: 1 | D40: 2 | E40: 3 | F40: 4 | G40: 5 | H40: 6 | I40: 7 | J40: 8 | K40: 9 | L40: 10 | M40: 11 | N40: 12 | O40: 13 | P40: 14 | Q40: 15 | R40: 16 | S40: 17 | T40: 18 | U40: 19 | V40: 20 | W40: 21 | X40: 22 | Y40: 23 | Z40: 24 | AA40: 25
A41: Debt Balance ($) | B41: =Inputs!C14-Inputs!C34 | C41: =B41-C43 | D41: =C41-D43 | E41: =D41-E43 | F41: =E41-F43 | G41: =F41-G43 | H41: =G41-H43 | I41: =H41-I43 | J41: =I41-J43 | ... AA41: =Z41-AA43
A42: Interest Payment ($) | B42: 0 | C42: =B41*Inputs!$C$17 | D42: =C41*Inputs!$C$17 | E42: =D41*Inputs!$C$17 | F42: =E41*Inputs!$C$17 | G42: =F41*Inputs!$C$17 | H42: =G41*Inputs!$C$17 | I42: =H41*Inputs!$C$17 | J42: =I41*Inputs!$C$17 | ... AA42: =Z41*Inputs!$C$17
A43: Principal Payment ($) | B43: 0 | C43: =-PMT(Inputs!$C$17,Inputs!$C$18,$B$41)-C42 | D43: =-PMT(Inputs!$C$17,Inputs!$C$18,$B$41)-D42 | E43: =-PMT(Inputs!$C$17,Inputs!$C$18,$B$41)-E42 | F43: =-PMT(Inputs!$C$17,Inputs!$C$18,$B$41)-F42 | G43: =-PMT(Inputs!$C$17,Inputs!$C$18,$B$41)-G42 | H43: =-PMT(Inputs!$C$17,Inputs!$C$18,$B$41)-H42 | I43: =-PMT(Inputs!$C$17,Inputs!$C$18,$B$41)-I42 | J43: =-PMT(Inputs!$C$17,Inputs!$C$18,$B$41)-J42 | ... AA43: =-PMT(Inputs!$C$17,Inputs!$C$18,$B$41)-AA42
A44: Total P&I Payment ($) | B44: 0 | C44: =C42+C43 | D44: =D42+D43 | E44: =E42+E43 | F44: =F42+F43 | G44: =G42+G43 | H44: =H42+H43 | I44: =I42+I43 | J44: =J42+J43 | ... AA44: =AA42+AA43
A45: Bill w/o System ($) | B45: 0 | C45: =Inputs!$C$30 | D45: =C45*(1+Inputs!$C$20) | E45: =D45*(1+Inputs!$C$20) | F45: =E45*(1+Inputs!$C$20) | G45: =F45*(1+Inputs!$C$20) | H45: =G45*(1+Inputs!$C$20) | I45: =H45*(1+Inputs!$C$20) | J45: =I45*(1+Inputs!$C$20) | K45: =J45*(1+Inputs!$C$20) | ... AA45: =Z45*(1+Inputs!$C$20)
A46: Bill w/ System ($) | B46: 0 | C46: =C45-Inputs!$D$43 | D46: =D45-Inputs!$D$43*(1+Inputs!$C$20)^(2-1) | E46: =E45-Inputs!$D$43*(1+Inputs!$C$20)^(3-1) | F46: =F45-Inputs!$D$43*(1+Inputs!$C$20)^(4-1) | G46: =G45-Inputs!$D$43*(1+Inputs!$C$20)^(5-1) | H46: =H45-Inputs!$D$43*(1+Inputs!$C$20)^(6-1) | I46: =I45-Inputs!$D$43*(1+Inputs!$C$20)^(7-1) | J46: =J45-Inputs!$D$43*(1+Inputs!$C$20)^(8-1) | K46: =K45-Inputs!$D$43*(1+Inputs!$C$20)^(9-1) | L46: =L45-Inputs!$D$43*(1+Inputs!$C$20)^(10-1) | M46: =M45-Inputs!$D$43*(1+Inputs!$C$20)^(11-1) | N46: =N45-Inputs!$D$43*(1+Inputs!$C$20)^(12-1) | O46: =O45-Inputs!$D$43*(1+Inputs!$C$20)^(13-1) | P46: =P45-Inputs!$D$43*(1+Inputs!$C$20)^(14-1) | Q46: =Q45-Inputs!$D$43*(1+Inputs!$C$20)^(15-1) | R46: =R45-Inputs!$D$43*(1+Inputs!$C$20)^(16-1) | S46: =S45-Inputs!$D$43*(1+Inputs!$C$20)^(17-1) | T46: =T45-Inputs!$D$43*(1+Inputs!$C$20)^(18-1) | U46: =U45-Inputs!$D$43*(1+Inputs!$C$20)^(19-1) | V46: =V45-Inputs!$D$43*(1+Inputs!$C$20)^(20-1) | W46: =W45-Inputs!$D$43*(1+Inputs!$C$20)^(21-1) | X46: =X45-Inputs!$D$43*(1+Inputs!$C$20)^(22-1) | Y46: =Y45-Inputs!$D$43*(1+Inputs!$C$20)^(23-1) | Z46: =Z45-Inputs!$D$43*(1+Inputs!$C$20)^(24-1) | AA46: =AA45-Inputs!$D$43*(1+Inputs!$C$20)^(25-1)
A47: Bill Savings ($) | B47: 0 | C47: =C45-C46 | D47: =D45-D46 | E47: =E45-E46 | F47: =F45-F46 | G47: =G45-G46 | H47: =H45-H46 | I47: =I45-I46 | J47: =J45-J46 | ... AA47: =AA45-AA46
A48: Incentive Annual ($) | B48: 0 | C48: =IF(1<=Inputs!$C$38,Inputs!$C$36,0)+Inputs!$C$37 | D48: =IF(2<=Inputs!$C$38,Inputs!$C$36,0)+Inputs!$C$37 | E48: =IF(3<=Inputs!$C$38,Inputs!$C$36,0)+Inputs!$C$37 | F48: =IF(4<=Inputs!$C$38,Inputs!$C$36,0)+Inputs!$C$37 | G48: =IF(5<=Inputs!$C$38,Inputs!$C$36,0)+Inputs!$C$37 | H48: =IF(6<=Inputs!$C$38,Inputs!$C$36,0)+Inputs!$C$37 | I48: =IF(7<=Inputs!$C$38,Inputs!$C$36,0)+Inputs!$C$37 | J48: =IF(8<=Inputs!$C$38,Inputs!$C$36,0)+Inputs!$C$37 | K48: =IF(9<=Inputs!$C$38,Inputs!$C$36,0)+Inputs!$C$37 | L48: =IF(10<=Inputs!$C$38,Inputs!$C$36,0)+Inputs!$C$37 | M48: =IF(11<=Inputs!$C$38,Inputs!$C$36,0)+Inputs!$C$37 | N48: =IF(12<=Inputs!$C$38,Inputs!$C$36,0)+Inputs!$C$37 | O48: =IF(13<=Inputs!$C$38,Inputs!$C$36,0)+Inputs!$C$37 | P48: =IF(14<=Inputs!$C$38,Inputs!$C$36,0)+Inputs!$C$37 | Q48: =IF(15<=Inputs!$C$38,Inputs!$C$36,0)+Inputs!$C$37 | R48: =IF(16<=Inputs!$C$38,Inputs!$C$36,0)+Inputs!$C$37 | S48: =IF(17<=Inputs!$C$38,Inputs!$C$36,0)+Inputs!$C$37 | T48: =IF(18<=Inputs!$C$38,Inputs!$C$36,0)+Inputs!$C$37 | U48: =IF(19<=Inputs!$C$38,Inputs!$C$36,0)+Inputs!$C$37 | V48: =IF(20<=Inputs!$C$38,Inputs!$C$36,0)+Inputs!$C$37 | W48: =IF(21<=Inputs!$C$38,Inputs!$C$36,0)+Inputs!$C$37 | X48: =IF(22<=Inputs!$C$38,Inputs!$C$36,0)+Inputs!$C$37 | Y48: =IF(23<=Inputs!$C$38,Inputs!$C$36,0)+Inputs!$C$37 | Z48: =IF(24<=Inputs!$C$38,Inputs!$C$36,0)+Inputs!$C$37 | AA48: =IF(25<=Inputs!$C$38,Inputs!$C$36,0)+Inputs!$C$37
...

Sheet TOU NB75
A5: Solar Only — All Incentives
A6: Year | B6: 0 | C6: 1 | D6: 2 | E6: 3 | F6: 4 | G6: 5 | H6: 6 | I6: 7 | J6: 8 | K6: 9 | L6: 10 | M6: 11 | N6: 12 | O6: 13 | P6: 14 | Q6: 15 | R6: 16 | S6: 17 | T6: 18 | U6: 19 | V6: 20 | W6: 21 | X6: 22 | Y6: 23 | Z6: 24 | AA6: 25
A7: Debt Balance ($) | B7: =Inputs!C11-Inputs!C34 | C7: =B7-C9 | D7: =C7-D9 | E7: =D7-E9 | F7: =E7-F9 | G7: =F7-G9 | H7: =G7-H9 | I7: =H7-I9 | J7: =I7-J9 | ... AA7: =Z7-AA9
A8: Interest Payment ($) | B8: 0 | C8: =B7*Inputs!$C$17 | D8: =C7*Inputs!$C$17 | E8: =D7*Inputs!$C$17 | F8: =E7*Inputs!$C$17 | G8: =F7*Inputs!$C$17 | H8: =G7*Inputs!$C$17 | I8: =H7*Inputs!$C$17 | J8: =I7*Inputs!$C$17 | ... AA8: =Z7*Inputs!$C$17
A9: Principal Payment ($) | B9: 0 | C9: =-PMT(Inputs!$C$17,Inputs!$C$18,$B$7)-C8 | D9: =-PMT(Inputs!$C$17,Inputs!$C$18,$B$7)-D8 | E9: =-PMT(Inputs!$C$17,Inputs!$C$18,$B$7)-E8 | F9: =-PMT(Inputs!$C$17,Inputs!$C$18,$B$7)-F8 | G9: =-PMT(Inputs!$C$17,Inputs!$C$18,$B$7)-G8 | H9: =-PMT(Inputs!$C$17,Inputs!$C$18,$B$7)-H8 | I9: =-PMT(Inputs!$C$17,Inputs!$C$18,$B$7)-I8 | J9: =-PMT(Inputs!$C$17,Inputs!$C$18,$B$7)-J8 | ... AA9: =-PMT(Inputs!$C$17,Inputs!$C$18,$B$7)-AA8
A10: Total P&I Payment ($) | B10: 0 | C10: =C8+C9 | D10: =D8+D9 | E10: =E8+E9 | F10: =F8+F9 | G10: =G8+G9 | H10: =H8+H9 | I10: =I8+I9 | J10: =J8+J9 | ... AA10: =AA8+AA9
A11: Bill w/o System ($) | B11: 0 | C11: =Inputs!$C$30 | D11: =C11*(1+Inputs!$C$20) | E11: =D11*(1+Inputs!$C$20) | F11: =E11*(1+Inputs!$C$20) | G11: =F11*(1+Inputs!$C$20) | H11: =G11*(1+Inputs!$C$20) | I11: =H11*(1+Inputs!$C$20) | J11: =I11*(1+Inputs!$C$20) | K11: =J11*(1+Inputs!$C$20) | ... AA11: =Z11*(1+Inputs!$C$20)
A12: Bill w/ System ($) | B12: 0 | C12: =C11-Inputs!$C$45 | D12: =D11-Inputs!$C$45*(1+Inputs!$C$20)^(2-1) | E12: =E11-Inputs!$C$45*(1+Inputs!$C$20)^(3-1) | F12: =F11-Inputs!$C$45*(1+Inputs!$C$20)^(4-1) | G12: =G11-Inputs!$C$45*(1+Inputs!$C$20)^(5-1) | H12: =H11-Inputs!$C$45*(1+Inputs!$C$20)^(6-1) | I12: =I11-Inputs!$C$45*(1+Inputs!$C$20)^(7-1) | J12: =J11-Inputs!$C$45*(1+Inputs!$C$20)^(8-1) | K12: =K11-Inputs!$C$45*(1+Inputs!$C$20)^(9-1) | L12: =L11-Inputs!$C$45*(1+Inputs!$C$20)^(10-1) | M12: =M11-Inputs!$C$45*(1+Inputs!$C$20)^(11-1) | N12: =N11-Inputs!$C$45*(1+Inputs!$C$20)^(12-1) | O12: =O11-Inputs!$C$45*(1+Inputs!$C$20)^(13-1) | P12: =P11-Inputs!$C$45*(1+Inputs!$C$20)^(14-1) | Q12: =Q11-Inputs!$C$45*(1+Inputs!$C$20)^(15-1) | R12: =R11-Inputs!$C$45*(1+Inputs!$C$20)^(16-1) | S12: =S11-Inputs!$C$45*(1+Inputs!$C$20)^(17-1) | T12: =T11-Inputs!$C$45*(1+Inputs!$C$20)^(18-1) | U12: =U11-Inputs!$C$45*(1+Inputs!$C$20)^(19-1) | V12: =V11-Inputs!$C$45*(1+Inputs!$C$20)^(20-1) | W12: =W11-Inputs!$C$45*(1+Inputs!$C$20)^(21-1) | X12: =X11-Inputs!$C$45*(1+Inputs!$C$20)^(22-1) | Y12: =Y11-Inputs!$C$45*(1+Inputs!$C$20)^(23-1) | Z12: =Z11-Inputs!$C$45*(1+Inputs!$C$20)^(24-1) | AA12: =AA11-Inputs!$C$45*(1+Inputs!$C$20)^(25-1)
A13: Bill Savings ($) | B13: 0 | C13: =C11-C12 | D13: =D11-D12 | E13: =E11-E12 | F13: =F11-F12 | G13: =G11-G12 | H13: =H11-H12 | I13: =I11-I12 | J13: =J11-J12 | ... AA13: =AA11-AA12
A14: Incentive Annual ($) | B14: 0 | C14: =IF(1<=Inputs!$C$38,Inputs!$C$35,0) | D14: =IF(2<=Inputs!$C$38,Inputs!$C$35,0) | E14: =IF(3<=Inputs!$C$38,Inputs!$C$35,0) | F14: =IF(4<=Inputs!$C$38,Inputs!$C$35,0) | G14: =IF(5<=Inputs!$C$38,Inputs!$C$35,0) | H14: =IF(6<=Inputs!$C$38,Inputs!$C$35,0) | I14: =IF(7<=Inputs!$C$38,Inputs!$C$35,0) | J14: =IF(8<=Inputs!$C$38,Inputs!$C$35,0) | K14: =IF(9<=Inputs!$C$38,Inputs!$C$35,0) | L14: =IF(10<=Inputs!$C$38,Inputs!$C$35,0) | M14: =IF(11<=Inputs!$C$38,Inputs!$C$35,0) | N14: =IF(12<=Inputs!$C$38,Inputs!$C$35,0) | O14: =IF(13<=Inputs!$C$38,Inputs!$C$35,0) | P14: =IF(14<=Inputs!$C$38,Inputs!$C$35,0) | Q14: =IF(15<=Inputs!$C$38,Inputs!$C$35,0) | R14: =IF(16<=Inputs!$C$38,Inputs!$C$35,0) | S14: =IF(17<=Inputs!$C$38,Inputs!$C$35,0) | T14: =IF(18<=Inputs!$C$38,Inputs!$C$35,0) | U14: =IF(19<=Inputs!$C$38,Inputs!$C$35,0) | V14: =IF(20<=Inputs!$C$38,Inputs!$C$35,0) | W14: =IF(21<=Inputs!$C$38,Inputs!$C$35,0) | X14: =IF(22<=Inputs!$C$38,Inputs!$C$35,0) | Y14: =IF(23<=Inputs!$C$38,Inputs!$C$35,0) | Z14: =IF(24<=Inputs!$C$38,Inputs!$C$35,0) | AA14: =IF(25<=Inputs!$C$38,Inputs!$C$35,0)
A15: Total Savings ($) | B15: 0 | C15: =C13+C14 | D15: =D13+D14 | E15: =E13+E14 | F15: =F13+F14 | G15: =G13+G14 | H15: =H13+H14 | I15: =I13+I14 | J15: =J13+J14 | ... AA15: =AA13+AA14
A16: Net Savings ($) | B16: 0 | C16: =C15-C10 | D16: =D15-D10 | E16: =E15-E10 | F16: =F15-F10 | G16: =G15-G10 | H16: =H15-H10 | I16: =I15-I10 | J16: =J15-J10 | ... AA16: =AA15-AA10
A17: Cumulative NPV ($) | B17: 0 | C17: =C16/(1+Inputs!$C$19)^1 | D17: =C17+D16/(1+Inputs!$C$19)^2 | E17: =D17+E16/(1+Inputs!$C$19)^3 | F17: =E17+F16/(1+Inputs!$C$19)^4 | G17: =F17+G16/(1+Inputs!$C$19)^5 | H17: =G17+H16/(1+Inputs!$C$19)^6 | I17: =H17+I16/(1+Inputs!$C$19)^7 | J17: =I17+J16/(1+Inputs!$C$19)^8 | K17: =J17+K16/(1+Inputs!$C$19)^9 | L17: =K17+L16/(1+Inputs!$C$19)^10 | M17: =L17+M16/(1+Inputs!$C$19)^11 | N17: =M17+N16/(1+Inputs!$C$19)^12 | O17: =N17+O16/(1+Inputs!$C$19)^13 | P17: =O17+P16/(1+Inputs!$C$19)^14 | Q17: =P17+Q16/(1+Inputs!$C$19)^15 | R17: =Q17+R16/(1+Inputs!$C$19)^16 | S17: =R17+S16/(1+Inputs!$C$19)^17 | T17: =S17+T16/(1+Inputs!$C$19)^18 | U17: =T17+U16/(1+Inputs!$C$19)^19 | V17: =U17+V16/(1+Inputs!$C$19)^20 | W17: =V17+W16/(1+Inputs!$C$19)^21 | X17: =W17+X16/(1+Inputs!$C$19)^22 | Y17: =X17+Y16/(1+Inputs!$C$19)^23 | Z17: =Y17+Z16/(1+Inputs!$C$19)^24 | AA17: =Z17+AA16/(1+Inputs!$C$19)^25
A18: Simple Payback (yr) | B18: =IF((C13+C14)>0,B7/(C13+C14),"N/A")
A19: NPV Breakeven Year | B19: See Cumulative NPV row 17 for first year ≥ 0
A22: Solar Only — No Incentives
A23: Year | B23: 0 | C23: 1 | D23: 2 | E23: 3 | F23: 4 | G23: 5 | H23: 6 | I23: 7 | J23: 8 | K23: 9 | L23: 10 | M23: 11 | N23: 12 | O23: 13 | P23: 14 | Q23: 15 | R23: 16 | S23: 17 | T23: 18 | U23: 19 | V23: 20 | W23: 21 | X23: 22 | Y23: 23 | Z23: 24 | AA23: 25
A24: Debt Balance ($) | B24: =Inputs!C11 | C24: =B24-C26 | D24: =C24-D26 | E24: =D24-E26 | F24: =E24-F26 | G24: =F24-G26 | H24: =G24-H26 | I24: =H24-I26 | J24: =I24-J26 | ... AA24: =Z24-AA26
A25: Interest Payment ($) | B25: 0 | C25: =B24*Inputs!$C$17 | D25: =C24*Inputs!$C$17 | E25: =D24*Inputs!$C$17 | F25: =E24*Inputs!$C$17 | G25: =F24*Inputs!$C$17 | H25: =G24*Inputs!$C$17 | I25: =H24*Inputs!$C$17 | J25: =I24*Inputs!$C$17 | ... AA25: =Z24*Inputs!$C$17
A26: Principal Payment ($) | B26: 0 | C26: =-PMT(Inputs!$C$17,Inputs!$C$18,$B$24)-C25 | D26: =-PMT(Inputs!$C$17,Inputs!$C$18,$B$24)-D25 | E26: =-PMT(Inputs!$C$17,Inputs!$C$18,$B$24)-E25 | F26: =-PMT(Inputs!$C$17,Inputs!$C$18,$B$24)-F25 | G26: =-PMT(Inputs!$C$17,Inputs!$C$18,$B$24)-G25 | H26: =-PMT(Inputs!$C$17,Inputs!$C$18,$B$24)-H25 | I26: =-PMT(Inputs!$C$17,Inputs!$C$18,$B$24)-I25 | J26: =-PMT(Inputs!$C$17,Inputs!$C$18,$B$24)-J25 | ... AA26: =-PMT(Inputs!$C$17,Inputs!$C$18,$B$24)-AA25
A27: Total P&I Payment ($) | B27: 0 | C27: =C25+C26 | D27: =D25+D26 | E27: =E25+E26 | F27: =F25+F26 | G27: =G25+G26 | H27: =H25+H26 | I27: =I25+I26 | J27: =J25+J26 | ... AA27: =AA25+AA26
A28: Bill w/o System ($) | B28: 0 | C28: =Inputs!$C$30 | D28: =C28*(1+Inputs!$C$20) | E28: =D28*(1+Inputs!$C$20) | F28: =E28*(1+Inputs!$C$20) | G28: =F28*(1+Inputs!$C$20) | H28: =G28*(1+Inputs!$C$20) | I28: =H28*(1+Inputs!$C$20) | J28: =I28*(1+Inputs!$C$20) | K28: =J28*(1+Inputs!$C$20) | ... AA28: =Z28*(1+Inputs!$C$20)
A29: Bill w/ System ($) | B29: 0 | C29: =C28-Inputs!$C$45 | D29: =D28-Inputs!$C$45*(1+Inputs!$C$20)^(2-1) | E29: =E28-Inputs!$C$45*(1+Inputs!$C$20)^(3-1) | F29: =F28-Inputs!$C$45*(1+Inputs!$C$20)^(4-1) | G29: =G28-Inputs!$C$45*(1+Inputs!$C$20)^(5-1) | H29: =H28-Inputs!$C$45*(1+Inputs!$C$20)^(6-1) | I29: =I28-Inputs!$C$45*(1+Inputs!$C$20)^(7-1) | J29: =J28-Inputs!$C$45*(1+Inputs!$C$20)^(8-1) | K29: =K28-Inputs!$C$45*(1+Inputs!$C$20)^(9-1) | L29: =L28-Inputs!$C$45*(1+Inputs!$C$20)^(10-1) | M29: =M28-Inputs!$C$45*(1+Inputs!$C$20)^(11-1) | N29: =N28-Inputs!$C$45*(1+Inputs!$C$20)^(12-1) | O29: =O28-Inputs!$C$45*(1+Inputs!$C$20)^(13-1) | P29: =P28-Inputs!$C$45*(1+Inputs!$C$20)^(14-1) | Q29: =Q28-Inputs!$C$45*(1+Inputs!$C$20)^(15-1) | R29: =R28-Inputs!$C$45*(1+Inputs!$C$20)^(16-1) | S29: =S28-Inputs!$C$45*(1+Inputs!$C$20)^(17-1) | T29: =T28-Inputs!$C$45*(1+Inputs!$C$20)^(18-1) | U29: =U28-Inputs!$C$45*(1+Inputs!$C$20)^(19-1) | V29: =V28-Inputs!$C$45*(1+Inputs!$C$20)^(20-1) | W29: =W28-Inputs!$C$45*(1+Inputs!$C$20)^(21-1) | X29: =X28-Inputs!$C$45*(1+Inputs!$C$20)^(22-1) | Y29: =Y28-Inputs!$C$45*(1+Inputs!$C$20)^(23-1) | Z29: =Z28-Inputs!$C$45*(1+Inputs!$C$20)^(24-1) | AA29: =AA28-Inputs!$C$45*(1+Inputs!$C$20)^(25-1)
A30: Bill Savings ($) | B30: 0 | C30: =C28-C29 | D30: =D28-D29 | E30: =E28-E29 | F30: =F28-F29 | G30: =G28-G29 | H30: =H28-H29 | I30: =I28-I29 | J30: =J28-J29 | ... AA30: =AA28-AA29
A31: Incentive Annual ($) | B31: 0 | C31: 0 | D31: 0 | E31: 0 | F31: 0 | G31: 0 | H31: 0 | I31: 0 | J31: 0 | K31: 0 | L31: 0 | M31: 0 | N31: 0 | O31: 0 | P31: 0 | Q31: 0 | R31: 0 | S31: 0 | T31: 0 | U31: 0 | V31: 0 | W31: 0 | X31: 0 | Y31: 0 | Z31: 0 | AA31: 0
A32: Total Savings ($) | B32: 0 | C32: =C30+C31 | D32: =D30+D31 | E32: =E30+E31 | F32: =F30+F31 | G32: =G30+G31 | H32: =H30+H31 | I32: =I30+I31 | J32: =J30+J31 | ... AA32: =AA30+AA31
A33: Net Savings ($) | B33: 0 | C33: =C32-C27 | D33: =D32-D27 | E33: =E32-E27 | F33: =F32-F27 | G33: =G32-G27 | H33: =H32-H27 | I33: =I32-I27 | J33: =J32-J27 | ... AA33: =AA32-AA27
A34: Cumulative NPV ($) | B34: 0 | C34: =C33/(1+Inputs!$C$19)^1 | D34: =C34+D33/(1+Inputs!$C$19)^2 | E34: =D34+E33/(1+Inputs!$C$19)^3 | F34: =E34+F33/(1+Inputs!$C$19)^4 | G34: =F34+G33/(1+Inputs!$C$19)^5 | H34: =G34+H33/(1+Inputs!$C$19)^6 | I34: =H34+I33/(1+Inputs!$C$19)^7 | J34: =I34+J33/(1+Inputs!$C$19)^8 | K34: =J34+K33/(1+Inputs!$C$19)^9 | L34: =K34+L33/(1+Inputs!$C$19)^10 | M34: =L34+M33/(1+Inputs!$C$19)^11 | N34: =M34+N33/(1+Inputs!$C$19)^12 | O34: =N34+O33/(1+Inputs!$C$19)^13 | P34: =O34+P33/(1+Inputs!$C$19)^14 | Q34: =P34+Q33/(1+Inputs!$C$19)^15 | R34: =Q34+R33/(1+Inputs!$C$19)^16 | S34: =R34+S33/(1+Inputs!$C$19)^17 | T34: =S34+T33/(1+Inputs!$C$19)^18 | U34: =T34+U33/(1+Inputs!$C$19)^19 | V34: =U34+V33/(1+Inputs!$C$19)^20 | W34: =V34+W33/(1+Inputs!$C$19)^21 | X34: =W34+X33/(1+Inputs!$C$19)^22 | Y34: =X34+Y33/(1+Inputs!$C$19)^23 | Z34: =Y34+Z33/(1+Inputs!$C$19)^24 | AA34: =Z34+AA33/(1+Inputs!$C$19)^25
A35: Simple Payback (yr) | B35: =IF((C30+C31)>0,B24/(C30+C31),"N/A")
A36: NPV Breakeven Year | B36: See Cumulative NPV row 34 for first year ≥ 0
A39: PV+Storage — All Incentives
A40: Year | B40: 0 | C40: 1 | D40: 2 | E40: 3 | F40: 4 | G40: 5 | H40: 6 | I40: 7 | J40: 8 | K40: 9 | L40: 10 | M40: 11 | N40: 12 | O40: 13 | P40: 14 | Q40: 15 | R40: 16 | S40: 17 | T40: 18 | U40: 19 | V40: 20 | W40: 21 | X40: 22 | Y40: 23 | Z40: 24 | AA40: 25
A41: Debt Balance ($) | B41: =Inputs!C14-Inputs!C34 | C41: =B41-C43 | D41: =C41-D43 | E41: =D41-E43 | F41: =E41-F43 | G41: =F41-G43 | H41: =G41-H43 | I41: =H41-I43 | J41: =I41-J43 | ... AA41: =Z41-AA43
A42: Interest Payment ($) | B42: 0 | C42: =B41*Inputs!$C$17 | D42: =C41*Inputs!$C$17 | E42: =D41*Inputs!$C$17 | F42: =E41*Inputs!$C$17 | G42: =F41*Inputs!$C$17 | H42: =G41*Inputs!$C$17 | I42: =H41*Inputs!$C$17 | J42: =I41*Inputs!$C$17 | ... AA42: =Z41*Inputs!$C$17
A43: Principal Payment ($) | B43: 0 | C43: =-PMT(Inputs!$C$17,Inputs!$C$18,$B$41)-C42 | D43: =-PMT(Inputs!$C$17,Inputs!$C$18,$B$41)-D42 | E43: =-PMT(Inputs!$C$17,Inputs!$C$18,$B$41)-E42 | F43: =-PMT(Inputs!$C$17,Inputs!$C$18,$B$41)-F42 | G43: =-PMT(Inputs!$C$17,Inputs!$C$18,$B$41)-G42 | H43: =-PMT(Inputs!$C$17,Inputs!$C$18,$B$41)-H42 | I43: =-PMT(Inputs!$C$17,Inputs!$C$18,$B$41)-I42 | J43: =-PMT(Inputs!$C$17,Inputs!$C$18,$B$41)-J42 | ... AA43: =-PMT(Inputs!$C$17,Inputs!$C$18,$B$41)-AA42
A44: Total P&I Payment ($) | B44: 0 | C44: =C42+C43 | D44: =D42+D43 | E44: =E42+E43 | F44: =F42+F43 | G44: =G42+G43 | H44: =H42+H43 | I44: =I42+I43 | J44: =J42+J43 | ... AA44: =AA42+AA43
A45: Bill w/o System ($) | B45: 0 | C45: =Inputs!$C$30 | D45: =C45*(1+Inputs!$C$20) | E45: =D45*(1+Inputs!$C$20) | F45: =E45*(1+Inputs!$C$20) | G45: =F45*(1+Inputs!$C$20) | H45: =G45*(1+Inputs!$C$20) | I45: =H45*(1+Inputs!$C$20) | J45: =I45*(1+Inputs!$C$20) | K45: =J45*(1+Inputs!$C$20) | ... AA45: =Z45*(1+Inputs!$C$20)
A46: Bill w/ System ($) | B46: 0 | C46: =C45-Inputs!$D$45 | D46: =D45-Inputs!$D$45*(1+Inputs!$C$20)^(2-1) | E46: =E45-Inputs!$D$45*(1+Inputs!$C$20)^(3-1) | F46: =F45-Inputs!$D$45*(1+Inputs!$C$20)^(4-1) | G46: =G45-Inputs!$D$45*(1+Inputs!$C$20)^(5-1) | H46: =H45-Inputs!$D$45*(1+Inputs!$C$20)^(6-1) | I46: =I45-Inputs!$D$45*(1+Inputs!$C$20)^(7-1) | J46: =J45-Inputs!$D$45*(1+Inputs!$C$20)^(8-1) | K46: =K45-Inputs!$D$45*(1+Inputs!$C$20)^(9-1) | L46: =L45-Inputs!$D$45*(1+Inputs!$C$20)^(10-1) | M46: =M45-Inputs!$D$45*(1+Inputs!$C$20)^(11-1) | N46: =N45-Inputs!$D$45*(1+Inputs!$C$20)^(12-1) | O46: =O45-Inputs!$D$45*(1+Inputs!$C$20)^(13-1) | P46: =P45-Inputs!$D$45*(1+Inputs!$C$20)^(14-1) | Q46: =Q45-Inputs!$D$45*(1+Inputs!$C$20)^(15-1) | R46: =R45-Inputs!$D$45*(1+Inputs!$C$20)^(16-1) | S46: =S45-Inputs!$D$45*(1+Inputs!$C$20)^(17-1) | T46: =T45-Inputs!$D$45*(1+Inputs!$C$20)^(18-1) | U46: =U45-Inputs!$D$45*(1+Inputs!$C$20)^(19-1) | V46: =V45-Inputs!$D$45*(1+Inputs!$C$20)^(20-1) | W46: =W45-Inputs!$D$45*(1+Inputs!$C$20)^(21-1) | X46: =X45-Inputs!$D$45*(1+Inputs!$C$20)^(22-1) | Y46: =Y45-Inputs!$D$45*(1+Inputs!$C$20)^(23-1) | Z46: =Z45-Inputs!$D$45*(1+Inputs!$C$20)^(24-1) | AA46: =AA45-Inputs!$D$45*(1+Inputs!$C$20)^(25-1)
A47: Bill Savings ($) | B47: 0 | C47: =C45-C46 | D47: =D45-D46 | E47: =E45-E46 | F47: =F45-F46 | G47: =G45-G46 | H47: =H45-H46 | I47: =I45-I46 | J47: =J45-J46 | ... AA47: =AA45-AA46
A48: Incentive Annual ($) | B48: 0 | C48: =IF(1<=Inputs!$C$38,Inputs!$C$36,0)+Inputs!$C$37 | D48: =IF(2<=Inputs!$C$38,Inputs!$C$36,0)+Inputs!$C$37 | E48: =IF(3<=Inputs!$C$38,Inputs!$C$36,0)+Inputs!$C$37 | F48: =IF(4<=Inputs!$C$38,Inputs!$C$36,0)+Inputs!$C$37 | G48: =IF(5<=Inputs!$C$38,Inputs!$C$36,0)+Inputs!$C$37 | H48: =IF(6<=Inputs!$C$38,Inputs!$C$36,0)+Inputs!$C$37 | I48: =IF(7<=Inputs!$C$38,Inputs!$C$36,0)+Inputs!$C$37 | J48: =IF(8<=Inputs!$C$38,Inputs!$C$36,0)+Inputs!$C$37 | K48: =IF(9<=Inputs!$C$38,Inputs!$C$36,0)+Inputs!$C$37 | L48: =IF(10<=Inputs!$C$38,Inputs!$C$36,0)+Inputs!$C$37 | M48: =IF(11<=Inputs!$C$38,Inputs!$C$36,0)+Inputs!$C$37 | N48: =IF(12<=Inputs!$C$38,Inputs!$C$36,0)+Inputs!$C$37 | O48: =IF(13<=Inputs!$C$38,Inputs!$C$36,0)+Inputs!$C$37 | P48: =IF(14<=Inputs!$C$38,Inputs!$C$36,0)+Inputs!$C$37 | Q48: =IF(15<=Inputs!$C$38,Inputs!$C$36,0)+Inputs!$C$37 | R48: =IF(16<=Inputs!$C$38,Inputs!$C$36,0)+Inputs!$C$37 | S48: =IF(17<=Inputs!$C$38,Inputs!$C$36,0)+Inputs!$C$37 | T48: =IF(18<=Inputs!$C$38,Inputs!$C$36,0)+Inputs!$C$37 | U48: =IF(19<=Inputs!$C$38,Inputs!$C$36,0)+Inputs!$C$37 | V48: =IF(20<=Inputs!$C$38,Inputs!$C$36,0)+Inputs!$C$37 | W48: =IF(21<=Inputs!$C$38,Inputs!$C$36,0)+Inputs!$C$37 | X48: =IF(22<=Inputs!$C$38,Inputs!$C$36,0)+Inputs!$C$37 | Y48: =IF(23<=Inputs!$C$38,Inputs!$C$36,0)+Inputs!$C$37 | Z48: =IF(24<=Inputs!$C$38,Inputs!$C$36,0)+Inputs!$C$37 | AA48: =IF(25<=Inputs!$C$38,Inputs!$C$36,0)+Inputs!$C$37
...

Sheet TOU NB50
A5: Solar Only — All Incentives
A6: Year | B6: 0 | C6: 1 | D6: 2 | E6: 3 | F6: 4 | G6: 5 | H6: 6 | I6: 7 | J6: 8 | K6: 9 | L6: 10 | M6: 11 | N6: 12 | O6: 13 | P6: 14 | Q6: 15 | R6: 16 | S6: 17 | T6: 18 | U6: 19 | V6: 20 | W6: 21 | X6: 22 | Y6: 23 | Z6: 24 | AA6: 25
A7: Debt Balance ($) | B7: =Inputs!C11-Inputs!C34 | C7: =B7-C9 | D7: =C7-D9 | E7: =D7-E9 | F7: =E7-F9 | G7: =F7-G9 | H7: =G7-H9 | I7: =H7-I9 | J7: =I7-J9 | ... AA7: =Z7-AA9
A8: Interest Payment ($) | B8: 0 | C8: =B7*Inputs!$C$17 | D8: =C7*Inputs!$C$17 | E8: =D7*Inputs!$C$17 | F8: =E7*Inputs!$C$17 | G8: =F7*Inputs!$C$17 | H8: =G7*Inputs!$C$17 | I8: =H7*Inputs!$C$17 | J8: =I7*Inputs!$C$17 | ... AA8: =Z7*Inputs!$C$17
A9: Principal Payment ($) | B9: 0 | C9: =-PMT(Inputs!$C$17,Inputs!$C$18,$B$7)-C8 | D9: =-PMT(Inputs!$C$17,Inputs!$C$18,$B$7)-D8 | E9: =-PMT(Inputs!$C$17,Inputs!$C$18,$B$7)-E8 | F9: =-PMT(Inputs!$C$17,Inputs!$C$18,$B$7)-F8 | G9: =-PMT(Inputs!$C$17,Inputs!$C$18,$B$7)-G8 | H9: =-PMT(Inputs!$C$17,Inputs!$C$18,$B$7)-H8 | I9: =-PMT(Inputs!$C$17,Inputs!$C$18,$B$7)-I8 | J9: =-PMT(Inputs!$C$17,Inputs!$C$18,$B$7)-J8 | ... AA9: =-PMT(Inputs!$C$17,Inputs!$C$18,$B$7)-AA8
A10: Total P&I Payment ($) | B10: 0 | C10: =C8+C9 | D10: =D8+D9 | E10: =E8+E9 | F10: =F8+F9 | G10: =G8+G9 | H10: =H8+H9 | I10: =I8+I9 | J10: =J8+J9 | ... AA10: =AA8+AA9
A11: Bill w/o System ($) | B11: 0 | C11: =Inputs!$C$30 | D11: =C11*(1+Inputs!$C$20) | E11: =D11*(1+Inputs!$C$20) | F11: =E11*(1+Inputs!$C$20) | G11: =F11*(1+Inputs!$C$20) | H11: =G11*(1+Inputs!$C$20) | I11: =H11*(1+Inputs!$C$20) | J11: =I11*(1+Inputs!$C$20) | K11: =J11*(1+Inputs!$C$20) | ... AA11: =Z11*(1+Inputs!$C$20)
A12: Bill w/ System ($) | B12: 0 | C12: =C11-Inputs!$C$46 | D12: =D11-Inputs!$C$46*(1+Inputs!$C$20)^(2-1) | E12: =E11-Inputs!$C$46*(1+Inputs!$C$20)^(3-1) | F12: =F11-Inputs!$C$46*(1+Inputs!$C$20)^(4-1) | G12: =G11-Inputs!$C$46*(1+Inputs!$C$20)^(5-1) | H12: =H11-Inputs!$C$46*(1+Inputs!$C$20)^(6-1) | I12: =I11-Inputs!$C$46*(1+Inputs!$C$20)^(7-1) | J12: =J11-Inputs!$C$46*(1+Inputs!$C$20)^(8-1) | K12: =K11-Inputs!$C$46*(1+Inputs!$C$20)^(9-1) | L12: =L11-Inputs!$C$46*(1+Inputs!$C$20)^(10-1) | M12: =M11-Inputs!$C$46*(1+Inputs!$C$20)^(11-1) | N12: =N11-Inputs!$C$46*(1+Inputs!$C$20)^(12-1) | O12: =O11-Inputs!$C$46*(1+Inputs!$C$20)^(13-1) | P12: =P11-Inputs!$C$46*(1+Inputs!$C$20)^(14-1) | Q12: =Q11-Inputs!$C$46*(1+Inputs!$C$20)^(15-1) | R12: =R11-Inputs!$C$46*(1+Inputs!$C$20)^(16-1) | S12: =S11-Inputs!$C$46*(1+Inputs!$C$20)^(17-1) | T12: =T11-Inputs!$C$46*(1+Inputs!$C$20)^(18-1) | U12: =U11-Inputs!$C$46*(1+Inputs!$C$20)^(19-1) | V12: =V11-Inputs!$C$46*(1+Inputs!$C$20)^(20-1) | W12: =W11-Inputs!$C$46*(1+Inputs!$C$20)^(21-1) | X12: =X11-Inputs!$C$46*(1+Inputs!$C$20)^(22-1) | Y12: =Y11-Inputs!$C$46*(1+Inputs!$C$20)^(23-1) | Z12: =Z11-Inputs!$C$46*(1+Inputs!$C$20)^(24-1) | AA12: =AA11-Inputs!$C$46*(1+Inputs!$C$20)^(25-1)
A13: Bill Savings ($) | B13: 0 | C13: =C11-C12 | D13: =D11-D12 | E13: =E11-E12 | F13: =F11-F12 | G13: =G11-G12 | H13: =H11-H12 | I13: =I11-I12 | J13: =J11-J12 | ... AA13: =AA11-AA12
A14: Incentive Annual ($) | B14: 0 | C14: =IF(1<=Inputs!$C$38,Inputs!$C$35,0) | D14: =IF(2<=Inputs!$C$38,Inputs!$C$35,0) | E14: =IF(3<=Inputs!$C$38,Inputs!$C$35,0) | F14: =IF(4<=Inputs!$C$38,Inputs!$C$35,0) | G14: =IF(5<=Inputs!$C$38,Inputs!$C$35,0) | H14: =IF(6<=Inputs!$C$38,Inputs!$C$35,0) | I14: =IF(7<=Inputs!$C$38,Inputs!$C$35,0) | J14: =IF(8<=Inputs!$C$38,Inputs!$C$35,0) | K14: =IF(9<=Inputs!$C$38,Inputs!$C$35,0) | L14: =IF(10<=Inputs!$C$38,Inputs!$C$35,0) | M14: =IF(11<=Inputs!$C$38,Inputs!$C$35,0) | N14: =IF(12<=Inputs!$C$38,Inputs!$C$35,0) | O14: =IF(13<=Inputs!$C$38,Inputs!$C$35,0) | P14: =IF(14<=Inputs!$C$38,Inputs!$C$35,0) | Q14: =IF(15<=Inputs!$C$38,Inputs!$C$35,0) | R14: =IF(16<=Inputs!$C$38,Inputs!$C$35,0) | S14: =IF(17<=Inputs!$C$38,Inputs!$C$35,0) | T14: =IF(18<=Inputs!$C$38,Inputs!$C$35,0) | U14: =IF(19<=Inputs!$C$38,Inputs!$C$35,0) | V14: =IF(20<=Inputs!$C$38,Inputs!$C$35,0) | W14: =IF(21<=Inputs!$C$38,Inputs!$C$35,0) | X14: =IF(22<=Inputs!$C$38,Inputs!$C$35,0) | Y14: =IF(23<=Inputs!$C$38,Inputs!$C$35,0) | Z14: =IF(24<=Inputs!$C$38,Inputs!$C$35,0) | AA14: =IF(25<=Inputs!$C$38,Inputs!$C$35,0)
A15: Total Savings ($) | B15: 0 | C15: =C13+C14 | D15: =D13+D14 | E15: =E13+E14 | F15: =F13+F14 | G15: =G13+G14 | H15: =H13+H14 | I15: =I13+I14 | J15: =J13+J14 | ... AA15: =AA13+AA14
A16: Net Savings ($) | B16: 0 | C16: =C15-C10 | D16: =D15-D10 | E16: =E15-E10 | F16: =F15-F10 | G16: =G15-G10 | H16: =H15-H10 | I16: =I15-I10 | J16: =J15-J10 | ... AA16: =AA15-AA10
A17: Cumulative NPV ($) | B17: 0 | C17: =C16/(1+Inputs!$C$19)^1 | D17: =C17+D16/(1+Inputs!$C$19)^2 | E17: =D17+E16/(1+Inputs!$C$19)^3 | F17: =E17+F16/(1+Inputs!$C$19)^4 | G17: =F17+G16/(1+Inputs!$C$19)^5 | H17: =G17+H16/(1+Inputs!$C$19)^6 | I17: =H17+I16/(1+Inputs!$C$19)^7 | J17: =I17+J16/(1+Inputs!$C$19)^8 | K17: =J17+K16/(1+Inputs!$C$19)^9 | L17: =K17+L16/(1+Inputs!$C$19)^10 | M17: =L17+M16/(1+Inputs!$C$19)^11 | N17: =M17+N16/(1+Inputs!$C$19)^12 | O17: =N17+O16/(1+Inputs!$C$19)^13 | P17: =O17+P16/(1+Inputs!$C$19)^14 | Q17: =P17+Q16/(1+Inputs!$C$19)^15 | R17: =Q17+R16/(1+Inputs!$C$19)^16 | S17: =R17+S16/(1+Inputs!$C$19)^17 | T17: =S17+T16/(1+Inputs!$C$19)^18 | U17: =T17+U16/(1+Inputs!$C$19)^19 | V17: =U17+V16/(1+Inputs!$C$19)^20 | W17: =V17+W16/(1+Inputs!$C$19)^21 | X17: =W17+X16/(1+Inputs!$C$19)^22 | Y17: =X17+Y16/(1+Inputs!$C$19)^23 | Z17: =Y17+Z16/(1+Inputs!$C$19)^24 | AA17: =Z17+AA16/(1+Inputs!$C$19)^25
A18: Simple Payback (yr) | B18: =IF((C13+C14)>0,B7/(C13+C14),"N/A")
A19: NPV Breakeven Year | B19: See Cumulative NPV row 17 for first year ≥ 0
A22: Solar Only — No Incentives
A23: Year | B23: 0 | C23: 1 | D23: 2 | E23: 3 | F23: 4 | G23: 5 | H23: 6 | I23: 7 | J23: 8 | K23: 9 | L23: 10 | M23: 11 | N23: 12 | O23: 13 | P23: 14 | Q23: 15 | R23: 16 | S23: 17 | T23: 18 | U23: 19 | V23: 20 | W23: 21 | X23: 22 | Y23: 23 | Z23: 24 | AA23: 25
A24: Debt Balance ($) | B24: =Inputs!C11 | C24: =B24-C26 | D24: =C24-D26 | E24: =D24-E26 | F24: =E24-F26 | G24: =F24-G26 | H24: =G24-H26 | I24: =H24-I26 | J24: =I24-J26 | ... AA24: =Z24-AA26
A25: Interest Payment ($) | B25: 0 | C25: =B24*Inputs!$C$17 | D25: =C24*Inputs!$C$17 | E25: =D24*Inputs!$C$17 | F25: =E24*Inputs!$C$17 | G25: =F24*Inputs!$C$17 | H25: =G24*Inputs!$C$17 | I25: =H24*Inputs!$C$17 | J25: =I24*Inputs!$C$17 | ... AA25: =Z24*Inputs!$C$17
A26: Principal Payment ($) | B26: 0 | C26: =-PMT(Inputs!$C$17,Inputs!$C$18,$B$24)-C25 | D26: =-PMT(Inputs!$C$17,Inputs!$C$18,$B$24)-D25 | E26: =-PMT(Inputs!$C$17,Inputs!$C$18,$B$24)-E25 | F26: =-PMT(Inputs!$C$17,Inputs!$C$18,$B$24)-F25 | G26: =-PMT(Inputs!$C$17,Inputs!$C$18,$B$24)-G25 | H26: =-PMT(Inputs!$C$17,Inputs!$C$18,$B$24)-H25 | I26: =-PMT(Inputs!$C$17,Inputs!$C$18,$B$24)-I25 | J26: =-PMT(Inputs!$C$17,Inputs!$C$18,$B$24)-J25 | ... AA26: =-PMT(Inputs!$C$17,Inputs!$C$18,$B$24)-AA25
A27: Total P&I Payment ($) | B27: 0 | C27: =C25+C26 | D27: =D25+D26 | E27: =E25+E26 | F27: =F25+F26 | G27: =G25+G26 | H27: =H25+H26 | I27: =I25+I26 | J27: =J25+J26 | ... AA27: =AA25+AA26
A28: Bill w/o System ($) | B28: 0 | C28: =Inputs!$C$30 | D28: =C28*(1+Inputs!$C$20) | E28: =D28*(1+Inputs!$C$20) | F28: =E28*(1+Inputs!$C$20) | G28: =F28*(1+Inputs!$C$20) | H28: =G28*(1+Inputs!$C$20) | I28: =H28*(1+Inputs!$C$20) | J28: =I28*(1+Inputs!$C$20) | K28: =J28*(1+Inputs!$C$20) | ... AA28: =Z28*(1+Inputs!$C$20)
A29: Bill w/ System ($) | B29: 0 | C29: =C28-Inputs!$C$46 | D29: =D28-Inputs!$C$46*(1+Inputs!$C$20)^(2-1) | E29: =E28-Inputs!$C$46*(1+Inputs!$C$20)^(3-1) | F29: =F28-Inputs!$C$46*(1+Inputs!$C$20)^(4-1) | G29: =G28-Inputs!$C$46*(1+Inputs!$C$20)^(5-1) | H29: =H28-Inputs!$C$46*(1+Inputs!$C$20)^(6-1) | I29: =I28-Inputs!$C$46*(1+Inputs!$C$20)^(7-1) | J29: =J28-Inputs!$C$46*(1+Inputs!$C$20)^(8-1) | K29: =K28-Inputs!$C$46*(1+Inputs!$C$20)^(9-1) | L29: =L28-Inputs!$C$46*(1+Inputs!$C$20)^(10-1) | M29: =M28-Inputs!$C$46*(1+Inputs!$C$20)^(11-1) | N29: =N28-Inputs!$C$46*(1+Inputs!$C$20)^(12-1) | O29: =O28-Inputs!$C$46*(1+Inputs!$C$20)^(13-1) | P29: =P28-Inputs!$C$46*(1+Inputs!$C$20)^(14-1) | Q29: =Q28-Inputs!$C$46*(1+Inputs!$C$20)^(15-1) | R29: =R28-Inputs!$C$46*(1+Inputs!$C$20)^(16-1) | S29: =S28-Inputs!$C$46*(1+Inputs!$C$20)^(17-1) | T29: =T28-Inputs!$C$46*(1+Inputs!$C$20)^(18-1) | U29: =U28-Inputs!$C$46*(1+Inputs!$C$20)^(19-1) | V29: =V28-Inputs!$C$46*(1+Inputs!$C$20)^(20-1) | W29: =W28-Inputs!$C$46*(1+Inputs!$C$20)^(21-1) | X29: =X28-Inputs!$C$46*(1+Inputs!$C$20)^(22-1) | Y29: =Y28-Inputs!$C$46*(1+Inputs!$C$20)^(23-1) | Z29: =Z28-Inputs!$C$46*(1+Inputs!$C$20)^(24-1) | AA29: =AA28-Inputs!$C$46*(1+Inputs!$C$20)^(25-1)
A30: Bill Savings ($) | B30: 0 | C30: =C28-C29 | D30: =D28-D29 | E30: =E28-E29 | F30: =F28-F29 | G30: =G28-G29 | H30: =H28-H29 | I30: =I28-I29 | J30: =J28-J29 | ... AA30: =AA28-AA29
A31: Incentive Annual ($) | B31: 0 | C31: 0 | D31: 0 | E31: 0 | F31: 0 | G31: 0 | H31: 0 | I31: 0 | J31: 0 | K31: 0 | L31: 0 | M31: 0 | N31: 0 | O31: 0 | P31: 0 | Q31: 0 | R31: 0 | S31: 0 | T31: 0 | U31: 0 | V31: 0 | W31: 0 | X31: 0 | Y31: 0 | Z31: 0 | AA31: 0
A32: Total Savings ($) | B32: 0 | C32: =C30+C31 | D32: =D30+D31 | E32: =E30+E31 | F32: =F30+F31 | G32: =G30+G31 | H32: =H30+H31 | I32: =I30+I31 | J32: =J30+J31 | ... AA32: =AA30+AA31
A33: Net Savings ($) | B33: 0 | C33: =C32-C27 | D33: =D32-D27 | E33: =E32-E27 | F33: =F32-F27 | G33: =G32-G27 | H33: =H32-H27 | I33: =I32-I27 | J33: =J32-J27 | ... AA33: =AA32-AA27
A34: Cumulative NPV ($) | B34: 0 | C34: =C33/(1+Inputs!$C$19)^1 | D34: =C34+D33/(1+Inputs!$C$19)^2 | E34: =D34+E33/(1+Inputs!$C$19)^3 | F34: =E34+F33/(1+Inputs!$C$19)^4 | G34: =F34+G33/(1+Inputs!$C$19)^5 | H34: =G34+H33/(1+Inputs!$C$19)^6 | I34: =H34+I33/(1+Inputs!$C$19)^7 | J34: =I34+J33/(1+Inputs!$C$19)^8 | K34: =J34+K33/(1+Inputs!$C$19)^9 | L34: =K34+L33/(1+Inputs!$C$19)^10 | M34: =L34+M33/(1+Inputs!$C$19)^11 | N34: =M34+N33/(1+Inputs!$C$19)^12 | O34: =N34+O33/(1+Inputs!$C$19)^13 | P34: =O34+P33/(1+Inputs!$C$19)^14 | Q34: =P34+Q33/(1+Inputs!$C$19)^15 | R34: =Q34+R33/(1+Inputs!$C$19)^16 | S34: =R34+S33/(1+Inputs!$C$19)^17 | T34: =S34+T33/(1+Inputs!$C$19)^18 | U34: =T34+U33/(1+Inputs!$C$19)^19 | V34: =U34+V33/(1+Inputs!$C$19)^20 | W34: =V34+W33/(1+Inputs!$C$19)^21 | X34: =W34+X33/(1+Inputs!$C$19)^22 | Y34: =X34+Y33/(1+Inputs!$C$19)^23 | Z34: =Y34+Z33/(1+Inputs!$C$19)^24 | AA34: =Z34+AA33/(1+Inputs!$C$19)^25
A35: Simple Payback (yr) | B35: =IF((C30+C31)>0,B24/(C30+C31),"N/A")
A36: NPV Breakeven Year | B36: See Cumulative NPV row 34 for first year ≥ 0
A39: PV+Storage — All Incentives
A40: Year | B40: 0 | C40: 1 | D40: 2 | E40: 3 | F40: 4 | G40: 5 | H40: 6 | I40: 7 | J40: 8 | K40: 9 | L40: 10 | M40: 11 | N40: 12 | O40: 13 | P40: 14 | Q40: 15 | R40: 16 | S40: 17 | T40: 18 | U40: 19 | V40: 20 | W40: 21 | X40: 22 | Y40: 23 | Z40: 24 | AA40: 25
A41: Debt Balance ($) | B41: =Inputs!C14-Inputs!C34 | C41: =B41-C43 | D41: =C41-D43 | E41: =D41-E43 | F41: =E41-F43 | G41: =F41-G43 | H41: =G41-H43 | I41: =H41-I43 | J41: =I41-J43 | ... AA41: =Z41-AA43
A42: Interest Payment ($) | B42: 0 | C42: =B41*Inputs!$C$17 | D42: =C41*Inputs!$C$17 | E42: =D41*Inputs!$C$17 | F42: =E41*Inputs!$C$17 | G42: =F41*Inputs!$C$17 | H42: =G41*Inputs!$C$17 | I42: =H41*Inputs!$C$17 | J42: =I41*Inputs!$C$17 | ... AA42: =Z41*Inputs!$C$17
A43: Principal Payment ($) | B43: 0 | C43: =-PMT(Inputs!$C$17,Inputs!$C$18,$B$41)-C42 | D43: =-PMT(Inputs!$C$17,Inputs!$C$18,$B$41)-D42 | E43: =-PMT(Inputs!$C$17,Inputs!$C$18,$B$41)-E42 | F43: =-PMT(Inputs!$C$17,Inputs!$C$18,$B$41)-F42 | G43: =-PMT(Inputs!$C$17,Inputs!$C$18,$B$41)-G42 | H43: =-PMT(Inputs!$C$17,Inputs!$C$18,$B$41)-H42 | I43: =-PMT(Inputs!$C$17,Inputs!$C$18,$B$41)-I42 | J43: =-PMT(Inputs!$C$17,Inputs!$C$18,$B$41)-J42 | ... AA43: =-PMT(Inputs!$C$17,Inputs!$C$18,$B$41)-AA42
A44: Total P&I Payment ($) | B44: 0 | C44: =C42+C43 | D44: =D42+D43 | E44: =E42+E43 | F44: =F42+F43 | G44: =G42+G43 | H44: =H42+H43 | I44: =I42+I43 | J44: =J42+J43 | ... AA44: =AA42+AA43
A45: Bill w/o System ($) | B45: 0 | C45: =Inputs!$C$30 | D45: =C45*(1+Inputs!$C$20) | E45: =D45*(1+Inputs!$C$20) | F45: =E45*(1+Inputs!$C$20) | G45: =F45*(1+Inputs!$C$20) | H45: =G45*(1+Inputs!$C$20) | I45: =H45*(1+Inputs!$C$20) | J45: =I45*(1+Inputs!$C$20) | K45: =J45*(1+Inputs!$C$20) | ... AA45: =Z45*(1+Inputs!$C$20)
A46: Bill w/ System ($) | B46: 0 | C46: =C45-Inputs!$D$46 | D46: =D45-Inputs!$D$46*(1+Inputs!$C$20)^(2-1) | E46: =E45-Inputs!$D$46*(1+Inputs!$C$20)^(3-1) | F46: =F45-Inputs!$D$46*(1+Inputs!$C$20)^(4-1) | G46: =G45-Inputs!$D$46*(1+Inputs!$C$20)^(5-1) | H46: =H45-Inputs!$D$46*(1+Inputs!$C$20)^(6-1) | I46: =I45-Inputs!$D$46*(1+Inputs!$C$20)^(7-1) | J46: =J45-Inputs!$D$46*(1+Inputs!$C$20)^(8-1) | K46: =K45-Inputs!$D$46*(1+Inputs!$C$20)^(9-1) | L46: =L45-Inputs!$D$46*(1+Inputs!$C$20)^(10-1) | M46: =M45-Inputs!$D$46*(1+Inputs!$C$20)^(11-1) | N46: =N45-Inputs!$D$46*(1+Inputs!$C$20)^(12-1) | O46: =O45-Inputs!$D$46*(1+Inputs!$C$20)^(13-1) | P46: =P45-Inputs!$D$46*(1+Inputs!$C$20)^(14-1) | Q46: =Q45-Inputs!$D$46*(1+Inputs!$C$20)^(15-1) | R46: =R45-Inputs!$D$46*(1+Inputs!$C$20)^(16-1) | S46: =S45-Inputs!$D$46*(1+Inputs!$C$20)^(17-1) | T46: =T45-Inputs!$D$46*(1+Inputs!$C$20)^(18-1) | U46: =U45-Inputs!$D$46*(1+Inputs!$C$20)^(19-1) | V46: =V45-Inputs!$D$46*(1+Inputs!$C$20)^(20-1) | W46: =W45-Inputs!$D$46*(1+Inputs!$C$20)^(21-1) | X46: =X45-Inputs!$D$46*(1+Inputs!$C$20)^(22-1) | Y46: =Y45-Inputs!$D$46*(1+Inputs!$C$20)^(23-1) | Z46: =Z45-Inputs!$D$46*(1+Inputs!$C$20)^(24-1) | AA46: =AA45-Inputs!$D$46*(1+Inputs!$C$20)^(25-1)
A47: Bill Savings ($) | B47: 0 | C47: =C45-C46 | D47: =D45-D46 | E47: =E45-E46 | F47: =F45-F46 | G47: =G45-G46 | H47: =H45-H46 | I47: =I45-I46 | J47: =J45-J46 | ... AA47: =AA45-AA46
A48: Incentive Annual ($) | B48: 0 | C48: =IF(1<=Inputs!$C$38,Inputs!$C$36,0)+Inputs!$C$37 | D48: =IF(2<=Inputs!$C$38,Inputs!$C$36,0)+Inputs!$C$37 | E48: =IF(3<=Inputs!$C$38,Inputs!$C$36,0)+Inputs!$C$37 | F48: =IF(4<=Inputs!$C$38,Inputs!$C$36,0)+Inputs!$C$37 | G48: =IF(5<=Inputs!$C$38,Inputs!$C$36,0)+Inputs!$C$37 | H48: =IF(6<=Inputs!$C$38,Inputs!$C$36,0)+Inputs!$C$37 | I48: =IF(7<=Inputs!$C$38,Inputs!$C$36,0)+Inputs!$C$37 | J48: =IF(8<=Inputs!$C$38,Inputs!$C$36,0)+Inputs!$C$37 | K48: =IF(9<=Inputs!$C$38,Inputs!$C$36,0)+Inputs!$C$37 | L48: =IF(10<=Inputs!$C$38,Inputs!$C$36,0)+Inputs!$C$37 | M48: =IF(11<=Inputs!$C$38,Inputs!$C$36,0)+Inputs!$C$37 | N48: =IF(12<=Inputs!$C$38,Inputs!$C$36,0)+Inputs!$C$37 | O48: =IF(13<=Inputs!$C$38,Inputs!$C$36,0)+Inputs!$C$37 | P48: =IF(14<=Inputs!$C$38,Inputs!$C$36,0)+Inputs!$C$37 | Q48: =IF(15<=Inputs!$C$38,Inputs!$C$36,0)+Inputs!$C$37 | R48: =IF(16<=Inputs!$C$38,Inputs!$C$36,0)+Inputs!$C$37 | S48: =IF(17<=Inputs!$C$38,Inputs!$C$36,0)+Inputs!$C$37 | T48: =IF(18<=Inputs!$C$38,Inputs!$C$36,0)+Inputs!$C$37 | U48: =IF(19<=Inputs!$C$38,Inputs!$C$36,0)+Inputs!$C$37 | V48: =IF(20<=Inputs!$C$38,Inputs!$C$36,0)+Inputs!$C$37 | W48: =IF(21<=Inputs!$C$38,Inputs!$C$36,0)+Inputs!$C$37 | X48: =IF(22<=Inputs!$C$38,Inputs!$C$36,0)+Inputs!$C$37 | Y48: =IF(23<=Inputs!$C$38,Inputs!$C$36,0)+Inputs!$C$37 | Z48: =IF(24<=Inputs!$C$38,Inputs!$C$36,0)+Inputs!$C$37 | AA48: =IF(25<=Inputs!$C$38,Inputs!$C$36,0)+Inputs!$C$37
...

Sheet Summary
A1: MA E3 TOU Sensitivity — Summary
A3: Scenario | B3: Bill w/o | C3: Bill Savings Y1 | D3: + Incentives Y1 | E3: PMT | F3: Net Y1 | G3: 25yr NPV
A4: TOU NM Solar All | B4: 2852.74 | C4: 1528 | D4: 348 | E4: 1377 | F4: 499 | G4: 10688
A5: TOU NM Solar None | B5: 2852.74 | C5: 1528 | D5: 0 | E5: 1465 | F5: 63 | G5: 5743
A6: TOU NM PV+S All | B6: 2852.74 | C6: 1510 | D6: 1954 | E6: 3138 | F6: 325 | G6: 8211
A7: TOU NM PV+S None | B7: 2852.74 | C7: 1510 | D7: 0 | E7: 3226 | F7: -1716 | G7: -16228
A8: TOU NB75 Solar All | B8: 2852.74 | C8: 1495 | D8: 348 | E8: 1377 | F8: 465 | G8: 10165
A9: TOU NB75 Solar None | B9: 2852.74 | C9: 1495 | D9: 0 | E9: 1465 | F9: 30 | G9: 5221
A10: TOU NB75 PV+S All | B10: 2852.74 | C10: 1488 | D10: 1954 | E10: 3138 | F10: 304 | G10: 7876
A11: TOU NB75 PV+S None | B11: 2852.74 | C11: 1488 | D11: 0 | E11: 3226 | F11: -1738 | G11: -16563
A12: TOU NB50 Solar All | B12: 2852.74 | C12: 1308 | D12: 348 | E12: 1377 | F12: 278 | G12: 7255
A13: TOU NB50 Solar None | B13: 2852.74 | C13: 1308 | D13: 0 | E13: 1465 | F13: -157 | G13: 2310
A14: TOU NB50 PV+S All | B14: 2852.74 | C14: 1320 | D14: 1954 | E14: 3138 | F14: 136 | G14: 5266
A15: TOU NB50 PV+S None | B15: 2852.74 | C15: 1320 | D15: 0 | E15: 3226 | F15: -1906 | G15: -19172
