Workbook

Sheet Inputs
A1: NC TOBF Financial Model — Input Parameters
A2: 🟡 Yellow cells are editable inputs — change them to see all sheets update automatically
A3: 🔵 Blue = NC official data | 🟢 Green = Minnesota proxy | ⬜ Gray = Calculated (formula)
A5: SYSTEM PARAMETERS
B6: Solar PV Capacity | C6: 5.8 | D6: kW | E6: Given | F6: User specified rooftop solar size
B7: Energy Storage Capacity | C7: 13.5 | D7: kWh | E7: Given | F7: User specified battery size (e.g. Tesla Powerwall)
B8: Solar Installed Cost | C8: 3 | D8: $/W | E8: ⚠️ ASSUMPTION | F8: NREL ATB 2024 mid-range NC residential. Range: $2.75-$3.50/W
B9: Battery Installed Cost | C9: 900 | D9: $/kWh | E9: ⚠️ ASSUMPTION | F9: Industry avg 2024 incl. inverter & labor. Range: $800-$1,200/kWh
B10: Total Solar Cost | C10: =C6*1000*C8 | D10: $ | E10: Calculated | F10: =kW × 1000 × $/W
B11: Total Battery Cost | C11: =C7*C9 | D11: $ | E11: Calculated
B12: ★ Total System Cost | C12: =C10+C11 | D12: $ | F12: =Solar cost + Battery cost
B13: System Useful Life | C13: 25 | D13: years | E13: ⚠️ ASSUMPTION | F13: Industry standard solar panel warranty/life
B14: Solar Annual Degradation | C14: 0.005 | D14: %/yr | E14: ⚠️ ASSUMPTION | F14: Typical crystalline silicon panel degradation
B15: Solar Capacity Factor | C15: 1400 | D15: kWh/kW/yr | E15: ⚠️ ASSUMPTION | F15: NC avg ~4.5-5.0 peak sun hrs/day. Range: 1,300-1,500
B16: Annual Solar Production (Year 1) | C16: =C6*C15 | D16: kWh/yr | E16: Calculated | F16: =kW × kWh/kW/yr
A18: ELECTRICITY & CUSTOMER SAVINGS (NC Data)
B19: Annual Electricity Bill (no system) | C19: 1624 | D19: $/yr | E19: NC Data | F19: From existing NMBPowerPair Excel model, NC residential
B20: Annual Electricity Bill (with system) | C20: 1048 | D20: $/yr | E20: NC Data | F20: From existing model — reflects solar+battery bill reduction
B21: ★ Year 1 Electricity Savings | C21: =C19-C20 | D21: $/yr
B22: Monthly Electricity Savings (Year 1) | C22: =C21/12 | D22: $/mo
B23: Electricity Cost Escalation Rate | C23: 0.025 | D23: %/yr | E23: NC Data | F23: Based on NC historical utility rate trends from existing model
B24: Customer Discount Rate | C24: 0.064 | D24: % | E24: NC Data | F24: From existing Excel model — customer perspective discount rate
A26: UTILITY COST OF CAPITAL (NC Utilities Commission Approved)
B27: DEC Overall Rate of Return (WACC) | C27: 0.075 | D27: % | E27: NC Approved | F27: NC Utilities Commission Docket E-7, Sub 1276
B28: DEP Overall Rate of Return (WACC) | C28: 0.0709 | D28: % | E28: NC Approved | F28: NC Utilities Commission Docket E-2, Sub 1300
B29: Equity Ratio (DEC & DEP) | C29: 0.53 | D29: % | E29: NC Approved
B30: DEC Return on Equity | C30: 0.101 | D30: % | E30: NC Approved
B31: DEC Long-Term Debt Cost | C31: 0.0456 | D31: % | E31: NC Approved
B32: ★ TOBF Tariff Rate (= Utility WACC) | C32: =C27 | D32: % | F32: Default = DEC WACC. User can override to test different rates.
A34: AVOIDED COSTS (NC Utility Data)
B35: Avoided Energy+Capacity Cost (DEC) | C35: 0.032 | D35: $/kWh | E35: NC Data | F35: Combined 10yr Avoided E&C chart, 2021 value
B36: Avoided Energy+Capacity Cost (DEP) | C36: 0.04 | D36: $/kWh | E36: NC Data
B37: ★ Avoided Cost (model input) | C37: =AVERAGE(C35,C36) | D37: $/kWh | F37: Default = avg DEC/DEP. User can override.
B38: Avoided Cost Annual Escalation | C38: 0.02 | D38: %/yr | E38: ⚠️ ASSUMPTION | F38: Conservative. Historically volatile; range 0-4%/yr
B39: Annual Avoided Cost to Utility (Year 1) | C39: =C16*C37 | D39: $/yr | F39: =Annual kWh × Avoided cost $/kWh
A41: PROGRAM & ADMIN COSTS (Minnesota BCA Proxy)
B42: Per-Participant Admin Cost | C42: 1090 | D42: $ | E42: MN Proxy | F42: Avg of EEtility $1,130 & CenterPoint $1,050 (MN BCA p.54-55)
B43: Loss Reserve Rate | C43: 0.01 | D43: % | E43: MN Proxy | F43: MN BCA Table 45 fn41. 1% standard; PAYS historical: 0%-0.5%
B44: Loss Reserve Amount | C44: =C12*C43 | D44: $
A46: TOBF TARIFF STRUCTURE
...

Sheet TOBF Cash Flow
A1: NC TOBF Model — 25-Year Cash Flow (All formulas reference Inputs sheet)
B3: Year 0 | C3: Year 1 | D3: Year 2 | E3: Year 3 | F3: Year 4 | G3: Year 5 | H3: Year 6 | I3: Year 7 | J3: Year 8 | K3: Year 9 | L3: Year 10 | M3: Year 11 | N3: Year 12 | O3: Year 13 | P3: Year 14 | Q3: Year 15 | R3: Year 16 | S3: Year 17 | T3: Year 18 | U3: Year 19 | V3: Year 20 | W3: Year 21 | X3: Year 22 | Y3: Year 23 | Z3: Year 24 | AA3: Year 25 | AB3: Total ($) | AC3: NPV ($)
A4: CUSTOMER PERSPECTIVE
A5: Year | B5: 0 | C5: 1 | D5: 2 | E5: 3 | F5: 4 | G5: 5 | H5: 6 | I5: 7 | J5: 8 | K5: 9 | L5: 10 | M5: 11 | N5: 12 | O5: 13 | P5: 14 | Q5: 15 | R5: 16 | S5: 17 | T5: 18 | U5: 19 | V5: 20 | W5: 21 | X5: 22 | Y5: 23 | Z5: 24 | AA5: 25
A6: Elec. Bill (no system) ($) | B6: 0 | C6: =Inputs!C19 | D6: =C6*(1+Inputs!$C$23) | E6: =D6*(1+Inputs!$C$23) | F6: =E6*(1+Inputs!$C$23) | G6: =F6*(1+Inputs!$C$23) | H6: =G6*(1+Inputs!$C$23) | I6: =H6*(1+Inputs!$C$23) | J6: =I6*(1+Inputs!$C$23) | K6: =J6*(1+Inputs!$C$23) | ... AA6: =Z6*(1+Inputs!$C$23) | AB6: =SUM(C6:AA6) | AC6: =C6/(1+Inputs!$C$24)^1+D6/(1+Inputs!$C$24)^2+E6/(1+Inputs!$C$24)^3+F6/(1+Inputs!$C$24)^4+G6/(1+Inputs!$C$24)^5+H6/(1+Inputs!$C$24)^6+I6/(1+Inputs!$C$24)^7+J6/(1+Inputs!$C$24)^8+K6/(1+Inputs!$C$24)^9+L6/(1+Inputs!$C$24)^10+M6/(1+Inputs!$C$24)^11+N6/(1+Inputs!$C$24)^12+O6/(1+Inputs!$C$24)^13+P6/(1+Inputs!$C$24)^14+Q6/(1+Inputs!$C$24)^15+R6/(1+Inputs!$C$24)^16+S6/(1+Inputs!$C$24)^17+T6/(1+Inputs!$C$24)^18+U6/(1+Inputs!$C$24)^19+V6/(1+Inputs!$C$24)^20+W6/(1+Inputs!$C$24)^21+X6/(1+Inputs!$C$24)^22+Y6/(1+Inputs!$C$24)^23+Z6/(1+Inputs!$C$24)^24+AA6/(1+Inputs!$C$24)^25
A7: Elec. Bill (with system) ($) | B7: 0 | C7: =Inputs!C20 | D7: =C7*(1+Inputs!$C$23) | E7: =D7*(1+Inputs!$C$23) | F7: =E7*(1+Inputs!$C$23) | G7: =F7*(1+Inputs!$C$23) | H7: =G7*(1+Inputs!$C$23) | I7: =H7*(1+Inputs!$C$23) | J7: =I7*(1+Inputs!$C$23) | K7: =J7*(1+Inputs!$C$23) | ... AA7: =Z7*(1+Inputs!$C$23) | AB7: =SUM(C7:AA7) | AC7: =C7/(1+Inputs!$C$24)^1+D7/(1+Inputs!$C$24)^2+E7/(1+Inputs!$C$24)^3+F7/(1+Inputs!$C$24)^4+G7/(1+Inputs!$C$24)^5+H7/(1+Inputs!$C$24)^6+I7/(1+Inputs!$C$24)^7+J7/(1+Inputs!$C$24)^8+K7/(1+Inputs!$C$24)^9+L7/(1+Inputs!$C$24)^10+M7/(1+Inputs!$C$24)^11+N7/(1+Inputs!$C$24)^12+O7/(1+Inputs!$C$24)^13+P7/(1+Inputs!$C$24)^14+Q7/(1+Inputs!$C$24)^15+R7/(1+Inputs!$C$24)^16+S7/(1+Inputs!$C$24)^17+T7/(1+Inputs!$C$24)^18+U7/(1+Inputs!$C$24)^19+V7/(1+Inputs!$C$24)^20+W7/(1+Inputs!$C$24)^21+X7/(1+Inputs!$C$24)^22+Y7/(1+Inputs!$C$24)^23+Z7/(1+Inputs!$C$24)^24+AA7/(1+Inputs!$C$24)^25
A8: ★ Electricity Savings ($) | B8: =B6-B7 | C8: =C6-C7 | D8: =D6-D7 | E8: =E6-E7 | F8: =F6-F7 | G8: =G6-G7 | H8: =H6-H7 | I8: =I6-I7 | ... AA8: =AA6-AA7 | AB8: =SUM(B8:AA8) | AC8: =C8/(1+Inputs!$C$24)^1+D8/(1+Inputs!$C$24)^2+E8/(1+Inputs!$C$24)^3+F8/(1+Inputs!$C$24)^4+G8/(1+Inputs!$C$24)^5+H8/(1+Inputs!$C$24)^6+I8/(1+Inputs!$C$24)^7+J8/(1+Inputs!$C$24)^8+K8/(1+Inputs!$C$24)^9+L8/(1+Inputs!$C$24)^10+M8/(1+Inputs!$C$24)^11+N8/(1+Inputs!$C$24)^12+O8/(1+Inputs!$C$24)^13+P8/(1+Inputs!$C$24)^14+Q8/(1+Inputs!$C$24)^15+R8/(1+Inputs!$C$24)^16+S8/(1+Inputs!$C$24)^17+T8/(1+Inputs!$C$24)^18+U8/(1+Inputs!$C$24)^19+V8/(1+Inputs!$C$24)^20+W8/(1+Inputs!$C$24)^21+X8/(1+Inputs!$C$24)^22+Y8/(1+Inputs!$C$24)^23+Z8/(1+Inputs!$C$24)^24+AA8/(1+Inputs!$C$24)^25
A9: TOBF Tariff Charge ($) | B9: 0 | C9: =IF(C5<=Inputs!$C$49,Inputs!$C$54,0) | D9: =IF(D5<=Inputs!$C$49,Inputs!$C$54,0) | E9: =IF(E5<=Inputs!$C$49,Inputs!$C$54,0) | F9: =IF(F5<=Inputs!$C$49,Inputs!$C$54,0) | G9: =IF(G5<=Inputs!$C$49,Inputs!$C$54,0) | H9: =IF(H5<=Inputs!$C$49,Inputs!$C$54,0) | I9: =IF(I5<=Inputs!$C$49,Inputs!$C$54,0) | J9: =IF(J5<=Inputs!$C$49,Inputs!$C$54,0) | ... AA9: =IF(AA5<=Inputs!$C$49,Inputs!$C$54,0) | AB9: =SUM(B9:AA9) | AC9: =C9/(1+Inputs!$C$24)^1+D9/(1+Inputs!$C$24)^2+E9/(1+Inputs!$C$24)^3+F9/(1+Inputs!$C$24)^4+G9/(1+Inputs!$C$24)^5+H9/(1+Inputs!$C$24)^6+I9/(1+Inputs!$C$24)^7+J9/(1+Inputs!$C$24)^8+K9/(1+Inputs!$C$24)^9+L9/(1+Inputs!$C$24)^10+M9/(1+Inputs!$C$24)^11+N9/(1+Inputs!$C$24)^12+O9/(1+Inputs!$C$24)^13+P9/(1+Inputs!$C$24)^14+Q9/(1+Inputs!$C$24)^15+R9/(1+Inputs!$C$24)^16+S9/(1+Inputs!$C$24)^17+T9/(1+Inputs!$C$24)^18+U9/(1+Inputs!$C$24)^19+V9/(1+Inputs!$C$24)^20+W9/(1+Inputs!$C$24)^21+X9/(1+Inputs!$C$24)^22+Y9/(1+Inputs!$C$24)^23+Z9/(1+Inputs!$C$24)^24+AA9/(1+Inputs!$C$24)^25
A10: ⚡ Net Customer Impact ($) | B10: =B8-B9 | C10: =C8-C9 | D10: =D8-D9 | E10: =E8-E9 | F10: =F8-F9 | G10: =G8-G9 | H10: =H8-H9 | I10: =I8-I9 | ... AA10: =AA8-AA9 | AB10: =SUM(B10:AA10) | AC10: =C10/(1+Inputs!$C$24)^1+D10/(1+Inputs!$C$24)^2+E10/(1+Inputs!$C$24)^3+F10/(1+Inputs!$C$24)^4+G10/(1+Inputs!$C$24)^5+H10/(1+Inputs!$C$24)^6+I10/(1+Inputs!$C$24)^7+J10/(1+Inputs!$C$24)^8+K10/(1+Inputs!$C$24)^9+L10/(1+Inputs!$C$24)^10+M10/(1+Inputs!$C$24)^11+N10/(1+Inputs!$C$24)^12+O10/(1+Inputs!$C$24)^13+P10/(1+Inputs!$C$24)^14+Q10/(1+Inputs!$C$24)^15+R10/(1+Inputs!$C$24)^16+S10/(1+Inputs!$C$24)^17+T10/(1+Inputs!$C$24)^18+U10/(1+Inputs!$C$24)^19+V10/(1+Inputs!$C$24)^20+W10/(1+Inputs!$C$24)^21+X10/(1+Inputs!$C$24)^22+Y10/(1+Inputs!$C$24)^23+Z10/(1+Inputs!$C$24)^24+AA10/(1+Inputs!$C$24)^25
A11: Monthly Net Impact ($/mo) | B11: =B10/12 | C11: =C10/12 | D11: =D10/12 | E11: =E10/12 | F11: =F10/12 | G11: =G10/12 | H11: =H10/12 | I11: =I10/12 | ... AA11: =AA10/12
A12: Tariff/Savings Ratio | C12: =IF(C8>0,C9/C8,0) | D12: =IF(D8>0,D9/D8,0) | E12: =IF(E8>0,E9/E8,0) | F12: =IF(F8>0,F9/F8,0) | G12: =IF(G8>0,G9/G8,0) | H12: =IF(H8>0,H9/H8,0) | I12: =IF(I8>0,I9/I8,0) | J12: =IF(J8>0,J9/J8,0) | ... AA12: =IF(AA8>0,AA9/AA8,0)
A13: Cumulative Net Impact ($) | B13: =B10 | C13: =B13+C10 | D13: =C13+D10 | E13: =D13+E10 | F13: =E13+F10 | G13: =F13+G10 | H13: =G13+H10 | I13: =H13+I10 | J13: =I13+J10 | ... AA13: =Z13+AA10
A15: UTILITY PERSPECTIVE
A16: Utility Investment ($) | B16: =-(Inputs!C12+Inputs!C42+Inputs!C44) | C16: =IF(C5=Inputs!$C$74,-Inputs!$C$75,0) | D16: =IF(D5=Inputs!$C$74,-Inputs!$C$75,0) | E16: =IF(E5=Inputs!$C$74,-Inputs!$C$75,0) | F16: =IF(F5=Inputs!$C$74,-Inputs!$C$75,0) | G16: =IF(G5=Inputs!$C$74,-Inputs!$C$75,0) | H16: =IF(H5=Inputs!$C$74,-Inputs!$C$75,0) | I16: =IF(I5=Inputs!$C$74,-Inputs!$C$75,0) | J16: =IF(J5=Inputs!$C$74,-Inputs!$C$75,0) | ... AA16: =IF(AA5=Inputs!$C$74,-Inputs!$C$75,0) | AB16: =SUM(B16:AA16) | AC16: =B16+C16/(1+Inputs!$C$32)^1+D16/(1+Inputs!$C$32)^2+E16/(1+Inputs!$C$32)^3+F16/(1+Inputs!$C$32)^4+G16/(1+Inputs!$C$32)^5+H16/(1+Inputs!$C$32)^6+I16/(1+Inputs!$C$32)^7+J16/(1+Inputs!$C$32)^8+K16/(1+Inputs!$C$32)^9+L16/(1+Inputs!$C$32)^10+M16/(1+Inputs!$C$32)^11+N16/(1+Inputs!$C$32)^12+O16/(1+Inputs!$C$32)^13+P16/(1+Inputs!$C$32)^14+Q16/(1+Inputs!$C$32)^15+R16/(1+Inputs!$C$32)^16+S16/(1+Inputs!$C$32)^17+T16/(1+Inputs!$C$32)^18+U16/(1+Inputs!$C$32)^19+V16/(1+Inputs!$C$32)^20+W16/(1+Inputs!$C$32)^21+X16/(1+Inputs!$C$32)^22+Y16/(1+Inputs!$C$32)^23+Z16/(1+Inputs!$C$32)^24+AA16/(1+Inputs!$C$32)^25
A17: Tariff Revenue ($) | B17: 0 | C17: =C9 | D17: =D9 | E17: =E9 | F17: =F9 | G17: =G9 | H17: =H9 | I17: =I9 | J17: =J9 | ... AA17: =AA9 | AB17: =SUM(C17:AA17) | AC17: =C17/(1+Inputs!$C$32)^1+D17/(1+Inputs!$C$32)^2+E17/(1+Inputs!$C$32)^3+F17/(1+Inputs!$C$32)^4+G17/(1+Inputs!$C$32)^5+H17/(1+Inputs!$C$32)^6+I17/(1+Inputs!$C$32)^7+J17/(1+Inputs!$C$32)^8+K17/(1+Inputs!$C$32)^9+L17/(1+Inputs!$C$32)^10+M17/(1+Inputs!$C$32)^11+N17/(1+Inputs!$C$32)^12+O17/(1+Inputs!$C$32)^13+P17/(1+Inputs!$C$32)^14+Q17/(1+Inputs!$C$32)^15+R17/(1+Inputs!$C$32)^16+S17/(1+Inputs!$C$32)^17+T17/(1+Inputs!$C$32)^18+U17/(1+Inputs!$C$32)^19+V17/(1+Inputs!$C$32)^20+W17/(1+Inputs!$C$32)^21+X17/(1+Inputs!$C$32)^22+Y17/(1+Inputs!$C$32)^23+Z17/(1+Inputs!$C$32)^24+AA17/(1+Inputs!$C$32)^25
A18: Avoided Costs ($) | B18: 0 | C18: =Inputs!C39 | D18: =C18*(1+Inputs!$C$38)*(1-Inputs!$C$14) | E18: =D18*(1+Inputs!$C$38)*(1-Inputs!$C$14) | F18: =E18*(1+Inputs!$C$38)*(1-Inputs!$C$14) | G18: =F18*(1+Inputs!$C$38)*(1-Inputs!$C$14) | H18: =G18*(1+Inputs!$C$38)*(1-Inputs!$C$14) | I18: =H18*(1+Inputs!$C$38)*(1-Inputs!$C$14) | J18: =I18*(1+Inputs!$C$38)*(1-Inputs!$C$14) | K18: =J18*(1+Inputs!$C$38)*(1-Inputs!$C$14) | ... AA18: =Z18*(1+Inputs!$C$38)*(1-Inputs!$C$14) | AB18: =SUM(C18:AA18) | AC18: =C18/(1+Inputs!$C$32)^1+D18/(1+Inputs!$C$32)^2+E18/(1+Inputs!$C$32)^3+F18/(1+Inputs!$C$32)^4+G18/(1+Inputs!$C$32)^5+H18/(1+Inputs!$C$32)^6+I18/(1+Inputs!$C$32)^7+J18/(1+Inputs!$C$32)^8+K18/(1+Inputs!$C$32)^9+L18/(1+Inputs!$C$32)^10+M18/(1+Inputs!$C$32)^11+N18/(1+Inputs!$C$32)^12+O18/(1+Inputs!$C$32)^13+P18/(1+Inputs!$C$32)^14+Q18/(1+Inputs!$C$32)^15+R18/(1+Inputs!$C$32)^16+S18/(1+Inputs!$C$32)^17+T18/(1+Inputs!$C$32)^18+U18/(1+Inputs!$C$32)^19+V18/(1+Inputs!$C$32)^20+W18/(1+Inputs!$C$32)^21+X18/(1+Inputs!$C$32)^22+Y18/(1+Inputs!$C$32)^23+Z18/(1+Inputs!$C$32)^24+AA18/(1+Inputs!$C$32)^25
A19: Lost Retail Revenue ($) | B19: =-B8 | C19: =-C8 | D19: =-D8 | E19: =-E8 | F19: =-F8 | G19: =-G8 | H19: =-H8 | I19: =-I8 | ... AA19: =-AA8 | AB19: =SUM(B19:AA19) | AC19: =C19/(1+Inputs!$C$32)^1+D19/(1+Inputs!$C$32)^2+E19/(1+Inputs!$C$32)^3+F19/(1+Inputs!$C$32)^4+G19/(1+Inputs!$C$32)^5+H19/(1+Inputs!$C$32)^6+I19/(1+Inputs!$C$32)^7+J19/(1+Inputs!$C$32)^8+K19/(1+Inputs!$C$32)^9+L19/(1+Inputs!$C$32)^10+M19/(1+Inputs!$C$32)^11+N19/(1+Inputs!$C$32)^12+O19/(1+Inputs!$C$32)^13+P19/(1+Inputs!$C$32)^14+Q19/(1+Inputs!$C$32)^15+R19/(1+Inputs!$C$32)^16+S19/(1+Inputs!$C$32)^17+T19/(1+Inputs!$C$32)^18+U19/(1+Inputs!$C$32)^19+V19/(1+Inputs!$C$32)^20+W19/(1+Inputs!$C$32)^21+X19/(1+Inputs!$C$32)^22+Y19/(1+Inputs!$C$32)^23+Z19/(1+Inputs!$C$32)^24+AA19/(1+Inputs!$C$32)^25
A20: ⚡ Utility Net Cash Flow ($) | B20: =B16+B17+B18+B19 | C20: =C16+C17+C18+C19 | D20: =D16+D17+D18+D19 | E20: =E16+E17+E18+E19 | F20: =F16+F17+F18+F19 | G20: =G16+G17+G18+G19 | H20: =H16+H17+H18+H19 | I20: =I16+I17+I18+I19 | ... AA20: =AA16+AA17+AA18+AA19 | AB20: =SUM(B20:AA20) | AC20: =B20+C20/(1+Inputs!$C$32)^1+D20/(1+Inputs!$C$32)^2+E20/(1+Inputs!$C$32)^3+F20/(1+Inputs!$C$32)^4+G20/(1+Inputs!$C$32)^5+H20/(1+Inputs!$C$32)^6+I20/(1+Inputs!$C$32)^7+J20/(1+Inputs!$C$32)^8+K20/(1+Inputs!$C$32)^9+L20/(1+Inputs!$C$32)^10+M20/(1+Inputs!$C$32)^11+N20/(1+Inputs!$C$32)^12+O20/(1+Inputs!$C$32)^13+P20/(1+Inputs!$C$32)^14+Q20/(1+Inputs!$C$32)^15+R20/(1+Inputs!$C$32)^16+S20/(1+Inputs!$C$32)^17+T20/(1+Inputs!$C$32)^18+U20/(1+Inputs!$C$32)^19+V20/(1+Inputs!$C$32)^20+W20/(1+Inputs!$C$32)^21+X20/(1+Inputs!$C$32)^22+Y20/(1+Inputs!$C$32)^23+Z20/(1+Inputs!$C$32)^24+AA20/(1+Inputs!$C$32)^25
A21: Cumulative Utility CF ($) | B21: =B20 | C21: =B21+C20 | D21: =C21+D20 | E21: =D21+E20 | F21: =E21+F20 | G21: =F21+G20 | H21: =G21+H20 | I21: =H21+I20 | J21: =I21+J20 | ... AA21: =Z21+AA20

Sheet Debt Comparison
A1: Debt Financing Cash Flow — For Comparison with TOBF
B3: Year 0 | C3: Year 1 | D3: Year 2 | E3: Year 3 | F3: Year 4 | G3: Year 5 | H3: Year 6 | I3: Year 7 | J3: Year 8 | K3: Year 9 | L3: Year 10 | M3: Year 11 | N3: Year 12 | O3: Year 13 | P3: Year 14 | Q3: Year 15 | R3: Year 16 | S3: Year 17 | T3: Year 18 | U3: Year 19 | V3: Year 20 | W3: Year 21 | X3: Year 22 | Y3: Year 23 | Z3: Year 24 | AA3: Year 25 | AB3: Total ($) | AC3: NPV ($)
A4: Year | B4: 0 | C4: 1 | D4: 2 | E4: 3 | F4: 4 | G4: 5 | H4: 6 | I4: 7 | J4: 8 | K4: 9 | L4: 10 | M4: 11 | N4: 12 | O4: 13 | P4: 14 | Q4: 15 | R4: 16 | S4: 17 | T4: 18 | U4: 19 | V4: 20 | W4: 21 | X4: 22 | Y4: 23 | Z4: 24 | AA4: 25
A5: Debt Balance ($) | B5: =Inputs!C12 | C5: =IF(C4<=Inputs!$C$67,MAX(0,B5*(1+Inputs!$C$66)-Inputs!$C$68),0) | D5: =IF(D4<=Inputs!$C$67,MAX(0,C5*(1+Inputs!$C$66)-Inputs!$C$68),0) | E5: =IF(E4<=Inputs!$C$67,MAX(0,D5*(1+Inputs!$C$66)-Inputs!$C$68),0) | F5: =IF(F4<=Inputs!$C$67,MAX(0,E5*(1+Inputs!$C$66)-Inputs!$C$68),0) | G5: =IF(G4<=Inputs!$C$67,MAX(0,F5*(1+Inputs!$C$66)-Inputs!$C$68),0) | H5: =IF(H4<=Inputs!$C$67,MAX(0,G5*(1+Inputs!$C$66)-Inputs!$C$68),0) | I5: =IF(I4<=Inputs!$C$67,MAX(0,H5*(1+Inputs!$C$66)-Inputs!$C$68),0) | J5: =IF(J4<=Inputs!$C$67,MAX(0,I5*(1+Inputs!$C$66)-Inputs!$C$68),0) | ... AA5: =IF(AA4<=Inputs!$C$67,MAX(0,Z5*(1+Inputs!$C$66)-Inputs!$C$68),0)
A6: Debt Payment ($) | B6: 0 | C6: =IF(C4<=Inputs!$C$67,Inputs!$C$68,0) | D6: =IF(D4<=Inputs!$C$67,Inputs!$C$68,0) | E6: =IF(E4<=Inputs!$C$67,Inputs!$C$68,0) | F6: =IF(F4<=Inputs!$C$67,Inputs!$C$68,0) | G6: =IF(G4<=Inputs!$C$67,Inputs!$C$68,0) | H6: =IF(H4<=Inputs!$C$67,Inputs!$C$68,0) | I6: =IF(I4<=Inputs!$C$67,Inputs!$C$68,0) | J6: =IF(J4<=Inputs!$C$67,Inputs!$C$68,0) | ... AA6: =IF(AA4<=Inputs!$C$67,Inputs!$C$68,0) | AB6: =SUM(B6:AA6)
A7: Electricity Savings ($) | B7: 0 | C7: =Inputs!C21 | D7: =C7*(1+Inputs!$C$23) | E7: =D7*(1+Inputs!$C$23) | F7: =E7*(1+Inputs!$C$23) | G7: =F7*(1+Inputs!$C$23) | H7: =G7*(1+Inputs!$C$23) | I7: =H7*(1+Inputs!$C$23) | J7: =I7*(1+Inputs!$C$23) | K7: =J7*(1+Inputs!$C$23) | ... AA7: =Z7*(1+Inputs!$C$23) | AB7: =SUM(C7:AA7)
A8: ⚡ Net Impact: Debt ($) | B8: =B7-B6 | C8: =C7-C6 | D8: =D7-D6 | E8: =E7-E6 | F8: =F7-F6 | G8: =G7-G6 | H8: =H7-H6 | I8: =I7-I6 | ... AA8: =AA7-AA6 | AB8: =SUM(B8:AA8) | AC8: =C8/(1+Inputs!$C$24)^1+D8/(1+Inputs!$C$24)^2+E8/(1+Inputs!$C$24)^3+F8/(1+Inputs!$C$24)^4+G8/(1+Inputs!$C$24)^5+H8/(1+Inputs!$C$24)^6+I8/(1+Inputs!$C$24)^7+J8/(1+Inputs!$C$24)^8+K8/(1+Inputs!$C$24)^9+L8/(1+Inputs!$C$24)^10+M8/(1+Inputs!$C$24)^11+N8/(1+Inputs!$C$24)^12+O8/(1+Inputs!$C$24)^13+P8/(1+Inputs!$C$24)^14+Q8/(1+Inputs!$C$24)^15+R8/(1+Inputs!$C$24)^16+S8/(1+Inputs!$C$24)^17+T8/(1+Inputs!$C$24)^18+U8/(1+Inputs!$C$24)^19+V8/(1+Inputs!$C$24)^20+W8/(1+Inputs!$C$24)^21+X8/(1+Inputs!$C$24)^22+Y8/(1+Inputs!$C$24)^23+Z8/(1+Inputs!$C$24)^24+AA8/(1+Inputs!$C$24)^25
A9: ⚡ Net Impact: TOBF ($) | B9: ='TOBF Cash Flow'!B10 | C9: ='TOBF Cash Flow'!C10 | D9: ='TOBF Cash Flow'!D10 | E9: ='TOBF Cash Flow'!E10 | F9: ='TOBF Cash Flow'!F10 | G9: ='TOBF Cash Flow'!G10 | H9: ='TOBF Cash Flow'!H10 | I9: ='TOBF Cash Flow'!I10 | ... AA9: ='TOBF Cash Flow'!AA10 | AB9: =SUM(B9:AA9)
A10: TOBF Advantage over Debt ($) | B10: =B9-B8 | C10: =C9-C8 | D10: =D9-D8 | E10: =E9-E8 | F10: =F9-F8 | G10: =G9-G8 | H10: =H9-H8 | I10: =I9-I8 | ... AA10: =AA9-AA8 | AB10: =SUM(B10:AA10)
A12: SUMMARY COMPARISON (all formulas, auto-update)
A13: Metric | B13: Debt Financing | C13: TOBF | D13: Difference | E13: Notes
A14: Financing Rate | B14: =Inputs!C66 | C14: =Inputs!C32 | D14: =Inputs!C32-Inputs!C66
A15: Term (years) | B15: =Inputs!C67 | C15: =Inputs!C49 | D15: =Inputs!C49-Inputs!C67
A16: Total Cost Financed | B16: =Inputs!C12 | C16: =Inputs!C52 | D16: =Inputs!C52-Inputs!C12
A17: Annual Payment | B17: =Inputs!C68 | C17: =Inputs!C54 | D17: =Inputs!C54-Inputs!C68
A18: Monthly Payment | B18: =Inputs!C69 | C18: =Inputs!C55 | D18: =Inputs!C55-Inputs!C69
A19: Year 1 Savings | B19: =Inputs!C21 | C19: =Inputs!C21 | D19: =0
A20: Net Monthly Y1 | B20: =Inputs!C21/12-Inputs!C69 | C20: =Inputs!C59 | D20: =Inputs!C59-(Inputs!C21/12-Inputs!C69)

Sheet BCA Analysis
A1: Benefit-Cost Analysis — Four Standard Tests (All Formulas)
A3: 25-Year NPV Calculation Helper (Discount Rate from Inputs)
A4: Component | B4: Year 1 Value | C4: Annual Growth | D4: Discount Rate | E4: 25yr NPV | F4: Formula
A5: Retail Savings (PCT dr) | B5: =Inputs!C21 | C5: =Inputs!C23 | D5: =Inputs!C62 | E5: =IF(D5=C5, B5*25/(1+D5), B5/(D5-C5)*(1-((1+C5)/(1+D5))^25)) | F5: Growing annuity PV formula
A6: Retail Savings (UCT/RIM dr) | B6: =Inputs!C21 | C6: =Inputs!C23 | D6: =Inputs!C63 | E6: =IF(D6=C6, B6*25/(1+D6), B6/(D6-C6)*(1-((1+C6)/(1+D6))^25))
A7: Avoided Costs (SCT dr) | B7: =Inputs!C39 | C7: =Inputs!C38-Inputs!C14 | D7: =Inputs!C62 | E7: =IF(D7=C7, B7*25/(1+D7), B7/(D7-C7)*(1-((1+C7)/(1+D7))^25))
A8: Avoided Costs (UCT/RIM dr) | B8: =Inputs!C39 | C8: =Inputs!C38-Inputs!C14 | D8: =Inputs!C63 | E8: =IF(D8=C8, B8*25/(1+D8), B8/(D8-C8)*(1-((1+C8)/(1+D8))^25))
A9: Tariff Payments (PCT dr) | B9: =Inputs!C54 | C9: 0 | D9: =Inputs!C62 | E9: =B9*(1-(1+D9)^(-Inputs!C49))/D9 | F9: PV of annuity for recovery period
A10: Program Costs (upfront) | E10: =Inputs!C42+Inputs!C44 | F10: Admin + Loss reserve (already at present value)
A11: Total Investment (upfront) | E11: =Inputs!C52
A13: BCA TEST RESULTS
A14: Test | B14: NPV Benefits ($) | C14: NPV Costs ($) | D14: B/C Ratio | E14: Pass (≥1.0)? | F14: What it measures
A15: SCT (Societal) | B15: =E7 | C15: =E11 | D15: =IF(C15>0,B15/C15,0) | E15: =IF(D15>=1,"YES ✅","NO ❌") | F15: Society: avoided costs vs total investment
A16: PCT (Participant) | B16: =E5 | C16: =E9 | D16: =IF(C16>0,B16/C16,0) | E16: =IF(D16>=1,"YES ✅","NO ❌") | F16: Customer: retail savings vs tariff payments
A17: UCT (Utility) | B17: =E8 | C17: =E10 | D17: =IF(C17>0,B17/C17,0) | E17: =IF(D17>=1,"YES ✅","NO ❌") | F17: Utility: avoided costs vs program costs (tariff recovers investment)
A18: RIM (Ratepayer) | B18: =E8 | C18: =E10+E6 | D18: =IF(C18>0,B18/C18,0) | E18: =IF(D18>=1,"YES ✅","NO ❌") | F18: All ratepayers: avoided costs vs program costs + lost retail revenue

Sheet Sensitivity
A1: Sensitivity Analysis — Change Inputs sheet values to see all results update
A3: LIVE DASHBOARD (linked to Inputs sheet)
A4: Output Metric | B4: Current Value | C4: Unit | D4: Source Cell
A5: Total System Cost | B5: =Inputs!C12 | D5: Inputs!C12
A6: Total Investment | B6: =Inputs!C52 | D6: Inputs!C52
A7: Monthly Tariff | B7: =Inputs!C55 | D7: Inputs!C55
A8: Monthly Savings (Y1) | B8: =Inputs!C22 | D8: Inputs!C22
A9: Tariff/Savings Ratio | B9: =Inputs!C57 | D9: Inputs!C57
A10: PAYS® Compliant? | B10: =Inputs!C58 | D10: Inputs!C58
A11: Net Monthly Impact (Y1) | B11: =Inputs!C59 | D11: Inputs!C59
A12: TOBF Rate (WACC) | B12: =Inputs!C32 | D12: Inputs!C32
A13: Recovery Period | B13: =Inputs!C49 | D13: Inputs!C49
A14: SCT B/C Ratio | B14: ='BCA Analysis'!D15 | D14: BCA!D15
A15: PCT B/C Ratio | B15: ='BCA Analysis'!D16 | D15: BCA!D16
A16: UCT B/C Ratio | B16: ='BCA Analysis'!D17 | D16: BCA!D17
A17: RIM B/C Ratio | B17: ='BCA Analysis'!D18 | D17: BCA!D18
A19: SCENARIO GUIDE — Change these inputs to test different scenarios:
A20: Scenario | B20: What to Change | C20: Cell | D20: Try This Value | E20: Expected Effect
A21: Solar-only (no battery) | B21: Battery Installed Cost → $0 | C21: Inputs!C9 | D21: $0 | E21: System cost drops ~$12K, tariff drops significantly
A22: Cheaper solar | B22: Solar Installed Cost → $2.00/W | C22: Inputs!C8 | D22: $2.00 | E22: System cost drops $5.8K, tariff drops ~20%
A23: Higher savings | B23: Bill with system → $800/yr | C23: Inputs!C20 | D23: $800 | E23: Savings rise to $824/yr, ratio improves
A24: Lower WACC | B24: TOBF Tariff Rate → 4% | C24: Inputs!C32 | D24: 4.00% | E24: Tariff drops significantly, tests subsidized rate
A25: Zero interest | B25: TOBF Tariff Rate → 0% | C25: Inputs!C32 | D25: 0.00% | E25: Best case: tariff = investment/years
A26: Longer term | B26: Recovery Period → 25 | C26: Inputs!C49 | D26: 25 | E26: Lower annual payment, tests full life recovery
A27: Higher avoided costs | B27: Avoided Cost → $0.08/kWh | C27: Inputs!C37 | D27: $0.080 | E27: Tests future high avoided cost environment
A28: Low admin cost | B28: Admin Cost → $500 | C28: Inputs!C42 | D28: $500 | E28: Reduces total investment slightly
A29: High elec escalation | B29: Escalation → 5%/yr | C29: Inputs!C23 | D29: 5.00% | E29: Future savings grow faster, improves NPV
A30: EE-like cost ($3K) | B30: Solar cost $0.52/W, Battery $0 | C30: Inputs!C8 | D30: $0.52/W & $0 batt | E30: Simulates an EE measure cost, should pass PAYS
A32: BREAKEVEN CALCULATIONS (auto-update)
A33: Metric | B33: Value | C33: Formula
A34: Max investment for PAYS (current rate/term) | B34: =Inputs!C21*Inputs!C47/Inputs!C53 | C34: =(Y1 savings × 80%) / CRF
A35: Required subsidy for PAYS compliance | B35: =MAX(0, Inputs!C52-B34) | C35: =MAX(0, Total Investment - Max PAYS investment)
A36: Required retail rate for PAYS ($/kWh) | B36: =Inputs!C54/(Inputs!C47*Inputs!C16) | C36: =Annual tariff / (80% × annual kWh)
A37: Max system cost for PAYS compliance | B37: =(B34-Inputs!C42)/(1+Inputs!C43)
