Workbook

Sheet Inputs
B1: TX VPP Scenario (Oncor + Chariot GreenVolt + North Hub VPP)
B3: SYSTEM
B4: PV Capacity | C4: 5.95 | D4: kW
B5: Battery | C5: 13.5 | D5: kWh
B6: Solar Cost | C6: 16481.5 | E6: $2,770/kW × 5.95, Tao Sun TX
B7: PV+S Cost | C7: 31358.5
B8: Loan Rate | C8: 0.0724
B9: Loan Term | C9: 25
B10: Discount Rate | C10: 0.064
B11: Escalation | C11: 0.025
B13: RATE STRUCTURE
B14: Buy Rate | C14: 0.1582 | E14: Chariot GreenVolt 10.2¢ + Oncor TDU 5.62¢
B15: Buyback Rate | C15: 0.07 | E15: Chariot GreenVolt 7¢ fixed
B16: Fixed Monthly | C16: 34.18
B18: VPP REVENUE
B19: VPP Annual Revenue | C19: 253 | D19: $/yr | E19: North Hub 2025 full year arbitrage, after 30% aggregator take
B20: Source | C20: ERCOT RTM SPP | E20: rpt.00013061 RTMLZHBSPP_2025.xlsx, 12 months, HB_NORTH
B21: Gross Revenue | C21: 361 | E21: $361/yr gross, $72/kW/yr. 30% take → $253 net to homeowner
B22: Caveat | C22: Optimistic | E22: Assumes perfect daily cycling, zero degradation, constant 2025 prices. Actual revenue volatile.
B24: PYSAM RESULTS
B25: Bill w/o System | C25: 2786.95
B26: Solar Savings Y1 | C26: 1088.02
B27: PV+S Savings Y1 | C27: 1098.8

Sheet Cash Flows
A5: PV+Storage — Base Case (No VPP)
A6: Year | B6: 0 | C6: 1 | D6: 2 | E6: 3 | F6: 4 | G6: 5 | H6: 6 | I6: 7 | J6: 8 | K6: 9 | L6: 10 | M6: 11 | N6: 12 | O6: 13 | P6: 14 | Q6: 15 | R6: 16 | S6: 17 | T6: 18 | U6: 19 | V6: 20 | W6: 21 | X6: 22 | Y6: 23 | Z6: 24 | AA6: 25
A7: Debt Balance ($) | B7: 31358.5 | C7: =B7-C9 | D7: =C7-D9 | E7: =D7-E9 | F7: =E7-F9 | G7: =F7-G9 | H7: =G7-H9 | I7: =H7-I9 | J7: =I7-J9 | ... AA7: =Z7-AA9
A8: Interest Payment ($) | B8: 0 | C8: =B7*Inputs!$C$8 | D8: =C7*Inputs!$C$8 | E8: =D7*Inputs!$C$8 | F8: =E7*Inputs!$C$8 | G8: =F7*Inputs!$C$8 | H8: =G7*Inputs!$C$8 | I8: =H7*Inputs!$C$8 | J8: =I7*Inputs!$C$8 | ... AA8: =Z7*Inputs!$C$8
A9: Principal Payment ($) | B9: 0 | C9: =-PMT(Inputs!$C$8,Inputs!$C$9,$B$7)-C8 | D9: =-PMT(Inputs!$C$8,Inputs!$C$9,$B$7)-D8 | E9: =-PMT(Inputs!$C$8,Inputs!$C$9,$B$7)-E8 | F9: =-PMT(Inputs!$C$8,Inputs!$C$9,$B$7)-F8 | G9: =-PMT(Inputs!$C$8,Inputs!$C$9,$B$7)-G8 | H9: =-PMT(Inputs!$C$8,Inputs!$C$9,$B$7)-H8 | I9: =-PMT(Inputs!$C$8,Inputs!$C$9,$B$7)-I8 | J9: =-PMT(Inputs!$C$8,Inputs!$C$9,$B$7)-J8 | ... AA9: =-PMT(Inputs!$C$8,Inputs!$C$9,$B$7)-AA8
A10: Total P&I Payment ($) | B10: 0 | C10: =C8+C9 | D10: =D8+D9 | E10: =E8+E9 | F10: =F8+F9 | G10: =G8+G9 | H10: =H8+H9 | I10: =I8+I9 | J10: =J8+J9 | ... AA10: =AA8+AA9
A11: Bill w/o System ($) | B11: 0 | C11: 2786.95 | D11: =C11*(1+Inputs!$C$11) | E11: =D11*(1+Inputs!$C$11) | F11: =E11*(1+Inputs!$C$11) | G11: =F11*(1+Inputs!$C$11) | H11: =G11*(1+Inputs!$C$11) | I11: =H11*(1+Inputs!$C$11) | J11: =I11*(1+Inputs!$C$11) | K11: =J11*(1+Inputs!$C$11) | ... AA11: =Z11*(1+Inputs!$C$11)
A12: Bill w/ System ($) | B12: 0 | C12: 1688.15 | D12: =D11-1098.8*(1+Inputs!$C$11)^(2-1) | E12: =E11-1098.8*(1+Inputs!$C$11)^(3-1) | F12: =F11-1098.8*(1+Inputs!$C$11)^(4-1) | G12: =G11-1098.8*(1+Inputs!$C$11)^(5-1) | H12: =H11-1098.8*(1+Inputs!$C$11)^(6-1) | I12: =I11-1098.8*(1+Inputs!$C$11)^(7-1) | J12: =J11-1098.8*(1+Inputs!$C$11)^(8-1) | K12: =K11-1098.8*(1+Inputs!$C$11)^(9-1) | L12: =L11-1098.8*(1+Inputs!$C$11)^(10-1) | M12: =M11-1098.8*(1+Inputs!$C$11)^(11-1) | N12: =N11-1098.8*(1+Inputs!$C$11)^(12-1) | O12: =O11-1098.8*(1+Inputs!$C$11)^(13-1) | P12: =P11-1098.8*(1+Inputs!$C$11)^(14-1) | Q12: =Q11-1098.8*(1+Inputs!$C$11)^(15-1) | R12: =R11-1098.8*(1+Inputs!$C$11)^(16-1) | S12: =S11-1098.8*(1+Inputs!$C$11)^(17-1) | T12: =T11-1098.8*(1+Inputs!$C$11)^(18-1) | U12: =U11-1098.8*(1+Inputs!$C$11)^(19-1) | V12: =V11-1098.8*(1+Inputs!$C$11)^(20-1) | W12: =W11-1098.8*(1+Inputs!$C$11)^(21-1) | X12: =X11-1098.8*(1+Inputs!$C$11)^(22-1) | Y12: =Y11-1098.8*(1+Inputs!$C$11)^(23-1) | Z12: =Z11-1098.8*(1+Inputs!$C$11)^(24-1) | AA12: =AA11-1098.8*(1+Inputs!$C$11)^(25-1)
A13: Bill Savings ($) | B13: 0 | C13: =C11-C12 | D13: =D11-D12 | E13: =E11-E12 | F13: =F11-F12 | G13: =G11-G12 | H13: =H11-H12 | I13: =I11-I12 | J13: =J11-J12 | ... AA13: =AA11-AA12
A14: VPP Revenue ($) | B14: 0 | C14: 0 | D14: 0 | E14: 0 | F14: 0 | G14: 0 | H14: 0 | I14: 0 | J14: 0 | K14: 0 | L14: 0 | M14: 0 | N14: 0 | O14: 0 | P14: 0 | Q14: 0 | R14: 0 | S14: 0 | T14: 0 | U14: 0 | V14: 0 | W14: 0 | X14: 0 | Y14: 0 | Z14: 0 | AA14: 0
A15: Total Savings ($) | B15: 0 | C15: =C13+C14 | D15: =D13+D14 | E15: =E13+E14 | F15: =F13+F14 | G15: =G13+G14 | H15: =H13+H14 | I15: =I13+I14 | J15: =J13+J14 | ... AA15: =AA13+AA14
A16: Net Savings ($) | B16: 0 | C16: =C15-C10 | D16: =D15-D10 | E16: =E15-E10 | F16: =F15-F10 | G16: =G15-G10 | H16: =H15-H10 | I16: =I15-I10 | J16: =J15-J10 | ... AA16: =AA15-AA10
A17: Cumulative NPV ($) | B17: 0 | C17: =C16/(1+Inputs!$C$10)^1 | D17: =C17+D16/(1+Inputs!$C$10)^2 | E17: =D17+E16/(1+Inputs!$C$10)^3 | F17: =E17+F16/(1+Inputs!$C$10)^4 | G17: =F17+G16/(1+Inputs!$C$10)^5 | H17: =G17+H16/(1+Inputs!$C$10)^6 | I17: =H17+I16/(1+Inputs!$C$10)^7 | J17: =I17+J16/(1+Inputs!$C$10)^8 | K17: =J17+K16/(1+Inputs!$C$10)^9 | L17: =K17+L16/(1+Inputs!$C$10)^10 | M17: =L17+M16/(1+Inputs!$C$10)^11 | N17: =M17+N16/(1+Inputs!$C$10)^12 | O17: =N17+O16/(1+Inputs!$C$10)^13 | P17: =O17+P16/(1+Inputs!$C$10)^14 | Q17: =P17+Q16/(1+Inputs!$C$10)^15 | R17: =Q17+R16/(1+Inputs!$C$10)^16 | S17: =R17+S16/(1+Inputs!$C$10)^17 | T17: =S17+T16/(1+Inputs!$C$10)^18 | U17: =T17+U16/(1+Inputs!$C$10)^19 | V17: =U17+V16/(1+Inputs!$C$10)^20 | W17: =V17+W16/(1+Inputs!$C$10)^21 | X17: =W17+X16/(1+Inputs!$C$10)^22 | Y17: =X17+Y16/(1+Inputs!$C$10)^23 | Z17: =Y17+Z16/(1+Inputs!$C$10)^24 | AA17: =Z17+AA16/(1+Inputs!$C$10)^25
A18: Simple Payback (yr) | B18: Simple Payback: 28.5 years
A22: PV+Storage — VPP ($253/yr)
A23: Year | B23: 0 | C23: 1 | D23: 2 | E23: 3 | F23: 4 | G23: 5 | H23: 6 | I23: 7 | J23: 8 | K23: 9 | L23: 10 | M23: 11 | N23: 12 | O23: 13 | P23: 14 | Q23: 15 | R23: 16 | S23: 17 | T23: 18 | U23: 19 | V23: 20 | W23: 21 | X23: 22 | Y23: 23 | Z23: 24 | AA23: 25
A24: Debt Balance ($) | B24: 31358.5 | C24: =B24-C26 | D24: =C24-D26 | E24: =D24-E26 | F24: =E24-F26 | G24: =F24-G26 | H24: =G24-H26 | I24: =H24-I26 | J24: =I24-J26 | ... AA24: =Z24-AA26
A25: Interest Payment ($) | B25: 0 | C25: =B24*Inputs!$C$8 | D25: =C24*Inputs!$C$8 | E25: =D24*Inputs!$C$8 | F25: =E24*Inputs!$C$8 | G25: =F24*Inputs!$C$8 | H25: =G24*Inputs!$C$8 | I25: =H24*Inputs!$C$8 | J25: =I24*Inputs!$C$8 | ... AA25: =Z24*Inputs!$C$8
A26: Principal Payment ($) | B26: 0 | C26: =-PMT(Inputs!$C$8,Inputs!$C$9,$B$24)-C25 | D26: =-PMT(Inputs!$C$8,Inputs!$C$9,$B$24)-D25 | E26: =-PMT(Inputs!$C$8,Inputs!$C$9,$B$24)-E25 | F26: =-PMT(Inputs!$C$8,Inputs!$C$9,$B$24)-F25 | G26: =-PMT(Inputs!$C$8,Inputs!$C$9,$B$24)-G25 | H26: =-PMT(Inputs!$C$8,Inputs!$C$9,$B$24)-H25 | I26: =-PMT(Inputs!$C$8,Inputs!$C$9,$B$24)-I25 | J26: =-PMT(Inputs!$C$8,Inputs!$C$9,$B$24)-J25 | ... AA26: =-PMT(Inputs!$C$8,Inputs!$C$9,$B$24)-AA25
A27: Total P&I Payment ($) | B27: 0 | C27: =C25+C26 | D27: =D25+D26 | E27: =E25+E26 | F27: =F25+F26 | G27: =G25+G26 | H27: =H25+H26 | I27: =I25+I26 | J27: =J25+J26 | ... AA27: =AA25+AA26
A28: Bill w/o System ($) | B28: 0 | C28: 2786.95 | D28: =C28*(1+Inputs!$C$11) | E28: =D28*(1+Inputs!$C$11) | F28: =E28*(1+Inputs!$C$11) | G28: =F28*(1+Inputs!$C$11) | H28: =G28*(1+Inputs!$C$11) | I28: =H28*(1+Inputs!$C$11) | J28: =I28*(1+Inputs!$C$11) | K28: =J28*(1+Inputs!$C$11) | ... AA28: =Z28*(1+Inputs!$C$11)
A29: Bill w/ System ($) | B29: 0 | C29: 1688.15 | D29: =D28-1098.8*(1+Inputs!$C$11)^(2-1) | E29: =E28-1098.8*(1+Inputs!$C$11)^(3-1) | F29: =F28-1098.8*(1+Inputs!$C$11)^(4-1) | G29: =G28-1098.8*(1+Inputs!$C$11)^(5-1) | H29: =H28-1098.8*(1+Inputs!$C$11)^(6-1) | I29: =I28-1098.8*(1+Inputs!$C$11)^(7-1) | J29: =J28-1098.8*(1+Inputs!$C$11)^(8-1) | K29: =K28-1098.8*(1+Inputs!$C$11)^(9-1) | L29: =L28-1098.8*(1+Inputs!$C$11)^(10-1) | M29: =M28-1098.8*(1+Inputs!$C$11)^(11-1) | N29: =N28-1098.8*(1+Inputs!$C$11)^(12-1) | O29: =O28-1098.8*(1+Inputs!$C$11)^(13-1) | P29: =P28-1098.8*(1+Inputs!$C$11)^(14-1) | Q29: =Q28-1098.8*(1+Inputs!$C$11)^(15-1) | R29: =R28-1098.8*(1+Inputs!$C$11)^(16-1) | S29: =S28-1098.8*(1+Inputs!$C$11)^(17-1) | T29: =T28-1098.8*(1+Inputs!$C$11)^(18-1) | U29: =U28-1098.8*(1+Inputs!$C$11)^(19-1) | V29: =V28-1098.8*(1+Inputs!$C$11)^(20-1) | W29: =W28-1098.8*(1+Inputs!$C$11)^(21-1) | X29: =X28-1098.8*(1+Inputs!$C$11)^(22-1) | Y29: =Y28-1098.8*(1+Inputs!$C$11)^(23-1) | Z29: =Z28-1098.8*(1+Inputs!$C$11)^(24-1) | AA29: =AA28-1098.8*(1+Inputs!$C$11)^(25-1)
A30: Bill Savings ($) | B30: 0 | C30: =C28-C29 | D30: =D28-D29 | E30: =E28-E29 | F30: =F28-F29 | G30: =G28-G29 | H30: =H28-H29 | I30: =I28-I29 | J30: =J28-J29 | ... AA30: =AA28-AA29
A31: VPP Revenue ($) | B31: 0 | C31: 253 | D31: 253 | E31: 253 | F31: 253 | G31: 253 | H31: 253 | I31: 253 | J31: 253 | K31: 253 | L31: 253 | M31: 253 | N31: 253 | O31: 253 | P31: 253 | Q31: 253 | R31: 253 | S31: 253 | T31: 253 | U31: 253 | V31: 253 | W31: 253 | X31: 253 | Y31: 253 | Z31: 253 | AA31: 253
A32: Total Savings ($) | B32: 0 | C32: =C30+C31 | D32: =D30+D31 | E32: =E30+E31 | F32: =F30+F31 | G32: =G30+G31 | H32: =H30+H31 | I32: =I30+I31 | J32: =J30+J31 | ... AA32: =AA30+AA31
A33: Net Savings ($) | B33: 0 | C33: =C32-C27 | D33: =D32-D27 | E33: =E32-E27 | F33: =F32-F27 | G33: =G32-G27 | H33: =H32-H27 | I33: =I32-I27 | J33: =J32-J27 | ... AA33: =AA32-AA27
A34: Cumulative NPV ($) | B34: 0 | C34: =C33/(1+Inputs!$C$10)^1 | D34: =C34+D33/(1+Inputs!$C$10)^2 | E34: =D34+E33/(1+Inputs!$C$10)^3 | F34: =E34+F33/(1+Inputs!$C$10)^4 | G34: =F34+G33/(1+Inputs!$C$10)^5 | H34: =G34+H33/(1+Inputs!$C$10)^6 | I34: =H34+I33/(1+Inputs!$C$10)^7 | J34: =I34+J33/(1+Inputs!$C$10)^8 | K34: =J34+K33/(1+Inputs!$C$10)^9 | L34: =K34+L33/(1+Inputs!$C$10)^10 | M34: =L34+M33/(1+Inputs!$C$10)^11 | N34: =M34+N33/(1+Inputs!$C$10)^12 | O34: =N34+O33/(1+Inputs!$C$10)^13 | P34: =O34+P33/(1+Inputs!$C$10)^14 | Q34: =P34+Q33/(1+Inputs!$C$10)^15 | R34: =Q34+R33/(1+Inputs!$C$10)^16 | S34: =R34+S33/(1+Inputs!$C$10)^17 | T34: =S34+T33/(1+Inputs!$C$10)^18 | U34: =T34+U33/(1+Inputs!$C$10)^19 | V34: =U34+V33/(1+Inputs!$C$10)^20 | W34: =V34+W33/(1+Inputs!$C$10)^21 | X34: =W34+X33/(1+Inputs!$C$10)^22 | Y34: =X34+Y33/(1+Inputs!$C$10)^23 | Z34: =Y34+Z33/(1+Inputs!$C$10)^24 | AA34: =Z34+AA33/(1+Inputs!$C$10)^25
A35: Simple Payback (yr) | B35: Simple Payback: 23.2 years
A39: Solar Only — No Incentives (Reference)
A40: Year | B40: 0 | C40: 1 | D40: 2 | E40: 3 | F40: 4 | G40: 5 | H40: 6 | I40: 7 | J40: 8 | K40: 9 | L40: 10 | M40: 11 | N40: 12 | O40: 13 | P40: 14 | Q40: 15 | R40: 16 | S40: 17 | T40: 18 | U40: 19 | V40: 20 | W40: 21 | X40: 22 | Y40: 23 | Z40: 24 | AA40: 25
A41: Debt Balance ($) | B41: 16481.5 | C41: =B41-C43 | D41: =C41-D43 | E41: =D41-E43 | F41: =E41-F43 | G41: =F41-G43 | H41: =G41-H43 | I41: =H41-I43 | J41: =I41-J43 | ... AA41: =Z41-AA43
A42: Interest Payment ($) | B42: 0 | C42: =B41*Inputs!$C$8 | D42: =C41*Inputs!$C$8 | E42: =D41*Inputs!$C$8 | F42: =E41*Inputs!$C$8 | G42: =F41*Inputs!$C$8 | H42: =G41*Inputs!$C$8 | I42: =H41*Inputs!$C$8 | J42: =I41*Inputs!$C$8 | ... AA42: =Z41*Inputs!$C$8
A43: Principal Payment ($) | B43: 0 | C43: =-PMT(Inputs!$C$8,Inputs!$C$9,$B$41)-C42 | D43: =-PMT(Inputs!$C$8,Inputs!$C$9,$B$41)-D42 | E43: =-PMT(Inputs!$C$8,Inputs!$C$9,$B$41)-E42 | F43: =-PMT(Inputs!$C$8,Inputs!$C$9,$B$41)-F42 | G43: =-PMT(Inputs!$C$8,Inputs!$C$9,$B$41)-G42 | H43: =-PMT(Inputs!$C$8,Inputs!$C$9,$B$41)-H42 | I43: =-PMT(Inputs!$C$8,Inputs!$C$9,$B$41)-I42 | J43: =-PMT(Inputs!$C$8,Inputs!$C$9,$B$41)-J42 | ... AA43: =-PMT(Inputs!$C$8,Inputs!$C$9,$B$41)-AA42
A44: Total P&I Payment ($) | B44: 0 | C44: =C42+C43 | D44: =D42+D43 | E44: =E42+E43 | F44: =F42+F43 | G44: =G42+G43 | H44: =H42+H43 | I44: =I42+I43 | J44: =J42+J43 | ... AA44: =AA42+AA43
A45: Bill w/o System ($) | B45: 0 | C45: 2786.95 | D45: =C45*(1+Inputs!$C$11) | E45: =D45*(1+Inputs!$C$11) | F45: =E45*(1+Inputs!$C$11) | G45: =F45*(1+Inputs!$C$11) | H45: =G45*(1+Inputs!$C$11) | I45: =H45*(1+Inputs!$C$11) | J45: =I45*(1+Inputs!$C$11) | K45: =J45*(1+Inputs!$C$11) | ... AA45: =Z45*(1+Inputs!$C$11)
A46: Bill w/ System ($) | B46: 0 | C46: 1698.93 | D46: =D45-1088.02*(1+Inputs!$C$11)^(2-1) | E46: =E45-1088.02*(1+Inputs!$C$11)^(3-1) | F46: =F45-1088.02*(1+Inputs!$C$11)^(4-1) | G46: =G45-1088.02*(1+Inputs!$C$11)^(5-1) | H46: =H45-1088.02*(1+Inputs!$C$11)^(6-1) | I46: =I45-1088.02*(1+Inputs!$C$11)^(7-1) | J46: =J45-1088.02*(1+Inputs!$C$11)^(8-1) | K46: =K45-1088.02*(1+Inputs!$C$11)^(9-1) | L46: =L45-1088.02*(1+Inputs!$C$11)^(10-1) | M46: =M45-1088.02*(1+Inputs!$C$11)^(11-1) | N46: =N45-1088.02*(1+Inputs!$C$11)^(12-1) | O46: =O45-1088.02*(1+Inputs!$C$11)^(13-1) | P46: =P45-1088.02*(1+Inputs!$C$11)^(14-1) | Q46: =Q45-1088.02*(1+Inputs!$C$11)^(15-1) | R46: =R45-1088.02*(1+Inputs!$C$11)^(16-1) | S46: =S45-1088.02*(1+Inputs!$C$11)^(17-1) | T46: =T45-1088.02*(1+Inputs!$C$11)^(18-1) | U46: =U45-1088.02*(1+Inputs!$C$11)^(19-1) | V46: =V45-1088.02*(1+Inputs!$C$11)^(20-1) | W46: =W45-1088.02*(1+Inputs!$C$11)^(21-1) | X46: =X45-1088.02*(1+Inputs!$C$11)^(22-1) | Y46: =Y45-1088.02*(1+Inputs!$C$11)^(23-1) | Z46: =Z45-1088.02*(1+Inputs!$C$11)^(24-1) | AA46: =AA45-1088.02*(1+Inputs!$C$11)^(25-1)
A47: Bill Savings ($) | B47: 0 | C47: =C45-C46 | D47: =D45-D46 | E47: =E45-E46 | F47: =F45-F46 | G47: =G45-G46 | H47: =H45-H46 | I47: =I45-I46 | J47: =J45-J46 | ... AA47: =AA45-AA46
A48: VPP Revenue ($) | B48: 0 | C48: 0 | D48: 0 | E48: 0 | F48: 0 | G48: 0 | H48: 0 | I48: 0 | J48: 0 | K48: 0 | L48: 0 | M48: 0 | N48: 0 | O48: 0 | P48: 0 | Q48: 0 | R48: 0 | S48: 0 | T48: 0 | U48: 0 | V48: 0 | W48: 0 | X48: 0 | Y48: 0 | Z48: 0 | AA48: 0
A49: Total Savings ($) | B49: 0 | C49: =C47+C48 | D49: =D47+D48 | E49: =E47+E48 | F49: =F47+F48 | G49: =G47+G48 | H49: =H47+H48 | I49: =I47+I48 | J49: =J47+J48 | ... AA49: =AA47+AA48
A50: Net Savings ($) | B50: 0 | C50: =C49-C44 | D50: =D49-D44 | E50: =E49-E44 | F50: =F49-F44 | G50: =G49-G44 | H50: =H49-H44 | I50: =I49-I44 | J50: =J49-J44 | ... AA50: =AA49-AA44
...
