Workbook

Sheet Inputs
B1: NC Solar Financing Model — Input Parameters
B2: Blue text = editable input | Black text = formula | Green text = cross-sheet link
B4: SYSTEM PARAMETERS
B5: PV + Storage System Cost | C5: 25085 | D5: $ | E5: Source: SAM model, Duke Energy NC residential config
B6: Solar Only System Cost | C6: 16302 | D6: $
B7: Solar PV Capacity | C7: 5.77 | D7: kW
B8: Battery Storage Capacity | C8: 13.5 | D8: kWh
B10: FINANCIAL PARAMETERS
B11: Debt Interest Rate | C11: 0.0724 | E11: Source: Prevailing NC residential solar loan rate
B12: Customer Discount Rate | C12: 0.064
B13: Loan Term | C13: 25 | D13: years
B14: Electricity Cost Escalation Rate | C14: 0.025 | E14: Source: EIA historical NC avg ~2-3%/yr
B16: INCENTIVES
B17: Federal ITC Rate | C17: 0.3 | E17: Expired Dec 2025; included for historical scenario comparison
B18: FedITC Amount — PV+Storage | C18: =C5*C17
B19: FedITC Amount — Solar Only | C19: =C6*C17
B20: PowerPair Rebate (calculated below) | C20: =C35 | E20: Source: Duke Energy NC PowerPair pilot program
B21: EnergyWise Annual Credit (calculated below) | C21: =C41 | D21: $/yr | E21: Source: Duke Energy EnergyWise Home Battery program
B23: YEAR 1 ELECTRICITY BILLS (from SAM simulation)
C24: Without System | D24: With System | E24: Annual Savings
B25: PV+Storage — RSC ($/yr) | C25: 1744 | D25: 1113 | E25: =C25-D25
B26: PV+Storage — Bridge ($/yr) | C26: 1624 | D26: 1048 | E26: =C26-D26
B27: Solar Only — RSC ($/yr) | C27: 1744 | D27: 1113 | E27: =C27-D27
B28: Solar Only — Bridge ($/yr) | C28: 1624 | D28: 1121 | E28: =C28-D28
B30: INCENTIVE CALCULATION DETAIL
B31: PowerPair Solar Rate | C31: 0.36 | D31: $/W | E31: Source: Duke Energy PowerPair program, NCUC approved
B32: PowerPair Solar Amount | C32: =C31*C7*1000 | E32: =rate × solar capacity (W), capped at $3,600
B33: PowerPair Battery Rate | C33: 400 | D33: $/kWh
B34: PowerPair Battery Amount | C34: =C33*C8 | E34: =rate × battery capacity (kWh), capped at $5,400
B35: PowerPair Total Rebate | C35: =MIN(C32,3600)+MIN(C34,5400) | E35: =solar (cap $3,600) + battery (cap $5,400), max $9,000
B37: EnergyWise Base Rate | C37: 6.5 | D37: $/kW/mo | E37: Source: Duke Energy EnergyWise Home Battery Control
B38: Capability Factor | C38: 0.709 | E38: Subject to change per Duke Energy program terms
B39: Battery Continuous Power Rating | C39: 5 | D39: kW | E39: Tesla Powerwall 2: 5kW continuous
B40: EnergyWise Net Rate | C40: =C37*C38 | D40: $/kW/mo | E40: =base rate × capability factor
B41: EnergyWise Annual Credit | C41: =C40*C39*12 | E41: =net rate × battery kW × 12 months

Sheet PV+Storage RSC
A1: PV + Storage — RSC Rate
A2: All formulas reference Inputs sheet
A4: Scenario 1: FedITC + State Incentives
A5: Year | B5: 0 | C5: 1 | D5: 2 | E5: 3 | F5: 4 | G5: 5 | H5: 6 | I5: 7 | J5: 8 | K5: 9 | L5: 10 | M5: 11 | N5: 12 | O5: 13 | P5: 14 | Q5: 15 | R5: 16 | S5: 17 | T5: 18 | U5: 19 | V5: 20 | W5: 21 | X5: 22 | Y5: 23 | Z5: 24 | AA5: 25 | AB5: 25yr Total | AC5: 25yr NPV
A6: Debt Balance ($) | B6: =Inputs!C5-Inputs!C18-Inputs!C20 | C6: =MAX(0,B6-C8) | D6: =MAX(0,C6-D8) | E6: =MAX(0,D6-E8) | F6: =MAX(0,E6-F8) | G6: =MAX(0,F6-G8) | H6: =MAX(0,G6-H8) | I6: =MAX(0,H6-I8) | J6: =MAX(0,I6-J8) | ... AA6: =MAX(0,Z6-AA8)
A7: Interest Payment ($) | B7: 0 | C7: =IF(B6<=0,0,B6*Inputs!$C$11) | D7: =IF(C6<=0,0,C6*Inputs!$C$11) | E7: =IF(D6<=0,0,D6*Inputs!$C$11) | F7: =IF(E6<=0,0,E6*Inputs!$C$11) | G7: =IF(F6<=0,0,F6*Inputs!$C$11) | H7: =IF(G6<=0,0,G6*Inputs!$C$11) | I7: =IF(H6<=0,0,H6*Inputs!$C$11) | J7: =IF(I6<=0,0,I6*Inputs!$C$11) | ... AA7: =IF(Z6<=0,0,Z6*Inputs!$C$11)
A8: Principal Payment ($) | B8: 0 | C8: =IF(B6<=0,0,C9-C7) | D8: =IF(B6<=0,0,D9-D7) | E8: =IF(B6<=0,0,E9-E7) | F8: =IF(B6<=0,0,F9-F7) | G8: =IF(B6<=0,0,G9-G7) | H8: =IF(B6<=0,0,H9-H7) | I8: =IF(B6<=0,0,I9-I7) | J8: =IF(B6<=0,0,J9-J7) | K8: =IF(B6<=0,0,K9-K7) | L8: =IF(B6<=0,0,L9-L7) | M8: =IF(B6<=0,0,M9-M7) | N8: =IF(B6<=0,0,N9-N7) | O8: =IF(B6<=0,0,O9-O7) | P8: =IF(B6<=0,0,P9-P7) | Q8: =IF(B6<=0,0,Q9-Q7) | R8: =IF(B6<=0,0,R9-R7) | S8: =IF(B6<=0,0,S9-S7) | T8: =IF(B6<=0,0,T9-T7) | U8: =IF(B6<=0,0,U9-U7) | V8: =IF(B6<=0,0,V9-V7) | W8: =IF(B6<=0,0,W9-W7) | X8: =IF(B6<=0,0,X9-X7) | Y8: =IF(B6<=0,0,Y9-Y7) | Z8: =IF(B6<=0,0,Z9-Z7) | AA8: =IF(B6<=0,0,AA9-AA7)
A9: Total Payment — P&I ($) | B9: 0 | C9: =IF(B6<=0,0,ABS(PMT(Inputs!$C$11,Inputs!$C$13,B6,0))) | D9: =IF(C6<=0,0,ABS(PMT(Inputs!$C$11,Inputs!$C$13,B6,0))) | E9: =IF(D6<=0,0,ABS(PMT(Inputs!$C$11,Inputs!$C$13,B6,0))) | F9: =IF(E6<=0,0,ABS(PMT(Inputs!$C$11,Inputs!$C$13,B6,0))) | G9: =IF(F6<=0,0,ABS(PMT(Inputs!$C$11,Inputs!$C$13,B6,0))) | H9: =IF(G6<=0,0,ABS(PMT(Inputs!$C$11,Inputs!$C$13,B6,0))) | I9: =IF(H6<=0,0,ABS(PMT(Inputs!$C$11,Inputs!$C$13,B6,0))) | J9: =IF(I6<=0,0,ABS(PMT(Inputs!$C$11,Inputs!$C$13,B6,0))) | K9: =IF(J6<=0,0,ABS(PMT(Inputs!$C$11,Inputs!$C$13,B6,0))) | L9: =IF(K6<=0,0,ABS(PMT(Inputs!$C$11,Inputs!$C$13,B6,0))) | M9: =IF(L6<=0,0,ABS(PMT(Inputs!$C$11,Inputs!$C$13,B6,0))) | N9: =IF(M6<=0,0,ABS(PMT(Inputs!$C$11,Inputs!$C$13,B6,0))) | O9: =IF(N6<=0,0,ABS(PMT(Inputs!$C$11,Inputs!$C$13,B6,0))) | P9: =IF(O6<=0,0,ABS(PMT(Inputs!$C$11,Inputs!$C$13,B6,0))) | Q9: =IF(P6<=0,0,ABS(PMT(Inputs!$C$11,Inputs!$C$13,B6,0))) | R9: =IF(Q6<=0,0,ABS(PMT(Inputs!$C$11,Inputs!$C$13,B6,0))) | S9: =IF(R6<=0,0,ABS(PMT(Inputs!$C$11,Inputs!$C$13,B6,0))) | T9: =IF(S6<=0,0,ABS(PMT(Inputs!$C$11,Inputs!$C$13,B6,0))) | U9: =IF(T6<=0,0,ABS(PMT(Inputs!$C$11,Inputs!$C$13,B6,0))) | V9: =IF(U6<=0,0,ABS(PMT(Inputs!$C$11,Inputs!$C$13,B6,0))) | W9: =IF(V6<=0,0,ABS(PMT(Inputs!$C$11,Inputs!$C$13,B6,0))) | X9: =IF(W6<=0,0,ABS(PMT(Inputs!$C$11,Inputs!$C$13,B6,0))) | Y9: =IF(X6<=0,0,ABS(PMT(Inputs!$C$11,Inputs!$C$13,B6,0))) | Z9: =IF(Y6<=0,0,ABS(PMT(Inputs!$C$11,Inputs!$C$13,B6,0))) | AA9: =IF(Z6<=0,0,ABS(PMT(Inputs!$C$11,Inputs!$C$13,B6,0))) | AB9: =SUM(C9:AA9) | AC9: =NPV(Inputs!$C$12,C9:AA9)
A11: Elec. Bill — No System ($) | B11: 0 | C11: =Inputs!C25 | D11: =C11*(1+Inputs!$C$14) | E11: =D11*(1+Inputs!$C$14) | F11: =E11*(1+Inputs!$C$14) | G11: =F11*(1+Inputs!$C$14) | H11: =G11*(1+Inputs!$C$14) | I11: =H11*(1+Inputs!$C$14) | J11: =I11*(1+Inputs!$C$14) | K11: =J11*(1+Inputs!$C$14) | ... AA11: =Z11*(1+Inputs!$C$14)
A12: Elec. Bill — With System ($) | B12: 0 | C12: =Inputs!D25 | D12: =C12*(1+Inputs!$C$14) | E12: =D12*(1+Inputs!$C$14) | F12: =E12*(1+Inputs!$C$14) | G12: =F12*(1+Inputs!$C$14) | H12: =G12*(1+Inputs!$C$14) | I12: =H12*(1+Inputs!$C$14) | J12: =I12*(1+Inputs!$C$14) | K12: =J12*(1+Inputs!$C$14) | ... AA12: =Z12*(1+Inputs!$C$14)
A13: Bill Savings ($) | B13: 0 | C13: =C11-C12 | D13: =D11-D12 | E13: =E11-E12 | F13: =F11-F12 | G13: =G11-G12 | H13: =H11-H12 | I13: =I11-I12 | J13: =J11-J12 | ... AA13: =AA11-AA12 | AB13: =SUM(C13:AA13) | AC13: =NPV(Inputs!$C$12,C13:AA13)
A14: Incentive Savings — Annual ($) | B14: 0 | C14: =Inputs!$C$21 | D14: =Inputs!$C$21 | E14: =Inputs!$C$21 | F14: =Inputs!$C$21 | G14: =Inputs!$C$21 | H14: =Inputs!$C$21 | I14: =Inputs!$C$21 | J14: =Inputs!$C$21 | ... AA14: =Inputs!$C$21 | AB14: =SUM(C14:AA14) | AC14: =NPV(Inputs!$C$12,C14:AA14)
A15: Total Savings ($) | B15: =B13+B14 | C15: =C13+C14 | D15: =D13+D14 | E15: =E13+E14 | F15: =F13+F14 | G15: =G13+G14 | H15: =H13+H14 | I15: =I13+I14 | ... AA15: =AA13+AA14 | AB15: =SUM(C15:AA15) | AC15: =NPV(Inputs!$C$12,C15:AA15)
A16: Net Savings ($) | B16: =B15-B9 | C16: =C15-C9 | D16: =D15-D9 | E16: =E15-E9 | F16: =F15-F9 | G16: =G15-G9 | H16: =H15-H9 | I16: =I15-I9 | ... AA16: =AA15-AA9 | AB16: =SUM(C16:AA16) | AC16: =NPV(Inputs!$C$12,C16:AA16)
A19: Scenario 2: State Incentives Only (No FedITC)
A20: Year | B20: 0 | C20: 1 | D20: 2 | E20: 3 | F20: 4 | G20: 5 | H20: 6 | I20: 7 | J20: 8 | K20: 9 | L20: 10 | M20: 11 | N20: 12 | O20: 13 | P20: 14 | Q20: 15 | R20: 16 | S20: 17 | T20: 18 | U20: 19 | V20: 20 | W20: 21 | X20: 22 | Y20: 23 | Z20: 24 | AA20: 25 | AB20: 25yr Total | AC20: 25yr NPV
A21: Debt Balance ($) | B21: =Inputs!C5-Inputs!C20 | C21: =MAX(0,B21-C23) | D21: =MAX(0,C21-D23) | E21: =MAX(0,D21-E23) | F21: =MAX(0,E21-F23) | G21: =MAX(0,F21-G23) | H21: =MAX(0,G21-H23) | I21: =MAX(0,H21-I23) | J21: =MAX(0,I21-J23) | ... AA21: =MAX(0,Z21-AA23)
A22: Interest Payment ($) | B22: 0 | C22: =IF(B21<=0,0,B21*Inputs!$C$11) | D22: =IF(C21<=0,0,C21*Inputs!$C$11) | E22: =IF(D21<=0,0,D21*Inputs!$C$11) | F22: =IF(E21<=0,0,E21*Inputs!$C$11) | G22: =IF(F21<=0,0,F21*Inputs!$C$11) | H22: =IF(G21<=0,0,G21*Inputs!$C$11) | I22: =IF(H21<=0,0,H21*Inputs!$C$11) | J22: =IF(I21<=0,0,I21*Inputs!$C$11) | ... AA22: =IF(Z21<=0,0,Z21*Inputs!$C$11)
A23: Principal Payment ($) | B23: 0 | C23: =IF(B21<=0,0,C24-C22) | D23: =IF(B21<=0,0,D24-D22) | E23: =IF(B21<=0,0,E24-E22) | F23: =IF(B21<=0,0,F24-F22) | G23: =IF(B21<=0,0,G24-G22) | H23: =IF(B21<=0,0,H24-H22) | I23: =IF(B21<=0,0,I24-I22) | J23: =IF(B21<=0,0,J24-J22) | K23: =IF(B21<=0,0,K24-K22) | L23: =IF(B21<=0,0,L24-L22) | M23: =IF(B21<=0,0,M24-M22) | N23: =IF(B21<=0,0,N24-N22) | O23: =IF(B21<=0,0,O24-O22) | P23: =IF(B21<=0,0,P24-P22) | Q23: =IF(B21<=0,0,Q24-Q22) | R23: =IF(B21<=0,0,R24-R22) | S23: =IF(B21<=0,0,S24-S22) | T23: =IF(B21<=0,0,T24-T22) | U23: =IF(B21<=0,0,U24-U22) | V23: =IF(B21<=0,0,V24-V22) | W23: =IF(B21<=0,0,W24-W22) | X23: =IF(B21<=0,0,X24-X22) | Y23: =IF(B21<=0,0,Y24-Y22) | Z23: =IF(B21<=0,0,Z24-Z22) | AA23: =IF(B21<=0,0,AA24-AA22)
A24: Total Payment — P&I ($) | B24: 0 | C24: =IF(B21<=0,0,ABS(PMT(Inputs!$C$11,Inputs!$C$13,B21,0))) | D24: =IF(C21<=0,0,ABS(PMT(Inputs!$C$11,Inputs!$C$13,B21,0))) | E24: =IF(D21<=0,0,ABS(PMT(Inputs!$C$11,Inputs!$C$13,B21,0))) | F24: =IF(E21<=0,0,ABS(PMT(Inputs!$C$11,Inputs!$C$13,B21,0))) | G24: =IF(F21<=0,0,ABS(PMT(Inputs!$C$11,Inputs!$C$13,B21,0))) | H24: =IF(G21<=0,0,ABS(PMT(Inputs!$C$11,Inputs!$C$13,B21,0))) | I24: =IF(H21<=0,0,ABS(PMT(Inputs!$C$11,Inputs!$C$13,B21,0))) | J24: =IF(I21<=0,0,ABS(PMT(Inputs!$C$11,Inputs!$C$13,B21,0))) | K24: =IF(J21<=0,0,ABS(PMT(Inputs!$C$11,Inputs!$C$13,B21,0))) | L24: =IF(K21<=0,0,ABS(PMT(Inputs!$C$11,Inputs!$C$13,B21,0))) | M24: =IF(L21<=0,0,ABS(PMT(Inputs!$C$11,Inputs!$C$13,B21,0))) | N24: =IF(M21<=0,0,ABS(PMT(Inputs!$C$11,Inputs!$C$13,B21,0))) | O24: =IF(N21<=0,0,ABS(PMT(Inputs!$C$11,Inputs!$C$13,B21,0))) | P24: =IF(O21<=0,0,ABS(PMT(Inputs!$C$11,Inputs!$C$13,B21,0))) | Q24: =IF(P21<=0,0,ABS(PMT(Inputs!$C$11,Inputs!$C$13,B21,0))) | R24: =IF(Q21<=0,0,ABS(PMT(Inputs!$C$11,Inputs!$C$13,B21,0))) | S24: =IF(R21<=0,0,ABS(PMT(Inputs!$C$11,Inputs!$C$13,B21,0))) | T24: =IF(S21<=0,0,ABS(PMT(Inputs!$C$11,Inputs!$C$13,B21,0))) | U24: =IF(T21<=0,0,ABS(PMT(Inputs!$C$11,Inputs!$C$13,B21,0))) | V24: =IF(U21<=0,0,ABS(PMT(Inputs!$C$11,Inputs!$C$13,B21,0))) | W24: =IF(V21<=0,0,ABS(PMT(Inputs!$C$11,Inputs!$C$13,B21,0))) | X24: =IF(W21<=0,0,ABS(PMT(Inputs!$C$11,Inputs!$C$13,B21,0))) | Y24: =IF(X21<=0,0,ABS(PMT(Inputs!$C$11,Inputs!$C$13,B21,0))) | Z24: =IF(Y21<=0,0,ABS(PMT(Inputs!$C$11,Inputs!$C$13,B21,0))) | AA24: =IF(Z21<=0,0,ABS(PMT(Inputs!$C$11,Inputs!$C$13,B21,0))) | AB24: =SUM(C24:AA24) | AC24: =NPV(Inputs!$C$12,C24:AA24)
A26: Elec. Bill — No System ($) | B26: 0 | C26: =Inputs!C25 | D26: =C26*(1+Inputs!$C$14) | E26: =D26*(1+Inputs!$C$14) | F26: =E26*(1+Inputs!$C$14) | G26: =F26*(1+Inputs!$C$14) | H26: =G26*(1+Inputs!$C$14) | I26: =H26*(1+Inputs!$C$14) | J26: =I26*(1+Inputs!$C$14) | K26: =J26*(1+Inputs!$C$14) | ... AA26: =Z26*(1+Inputs!$C$14)
A27: Elec. Bill — With System ($) | B27: 0 | C27: =Inputs!D25 | D27: =C27*(1+Inputs!$C$14) | E27: =D27*(1+Inputs!$C$14) | F27: =E27*(1+Inputs!$C$14) | G27: =F27*(1+Inputs!$C$14) | H27: =G27*(1+Inputs!$C$14) | I27: =H27*(1+Inputs!$C$14) | J27: =I27*(1+Inputs!$C$14) | K27: =J27*(1+Inputs!$C$14) | ... AA27: =Z27*(1+Inputs!$C$14)
A28: Bill Savings ($) | B28: 0 | C28: =C26-C27 | D28: =D26-D27 | E28: =E26-E27 | F28: =F26-F27 | G28: =G26-G27 | H28: =H26-H27 | I28: =I26-I27 | J28: =J26-J27 | ... AA28: =AA26-AA27 | AB28: =SUM(C28:AA28) | AC28: =NPV(Inputs!$C$12,C28:AA28)
A29: Incentive Savings — Annual ($) | B29: 0 | C29: =Inputs!$C$21 | D29: =Inputs!$C$21 | E29: =Inputs!$C$21 | F29: =Inputs!$C$21 | G29: =Inputs!$C$21 | H29: =Inputs!$C$21 | I29: =Inputs!$C$21 | J29: =Inputs!$C$21 | ... AA29: =Inputs!$C$21 | AB29: =SUM(C29:AA29) | AC29: =NPV(Inputs!$C$12,C29:AA29)
A30: Total Savings ($) | B30: =B28+B29 | C30: =C28+C29 | D30: =D28+D29 | E30: =E28+E29 | F30: =F28+F29 | G30: =G28+G29 | H30: =H28+H29 | I30: =I28+I29 | ... AA30: =AA28+AA29 | AB30: =SUM(C30:AA30) | AC30: =NPV(Inputs!$C$12,C30:AA30)
A31: Net Savings ($) | B31: =B30-B24 | C31: =C30-C24 | D31: =D30-D24 | E31: =E30-E24 | F31: =F30-F24 | G31: =G30-G24 | H31: =H30-H24 | I31: =I30-I24 | ... AA31: =AA30-AA24 | AB31: =SUM(C31:AA31) | AC31: =NPV(Inputs!$C$12,C31:AA31)
A34: Scenario 3: No Incentives
A35: Year | B35: 0 | C35: 1 | D35: 2 | E35: 3 | F35: 4 | G35: 5 | H35: 6 | I35: 7 | J35: 8 | K35: 9 | L35: 10 | M35: 11 | N35: 12 | O35: 13 | P35: 14 | Q35: 15 | R35: 16 | S35: 17 | T35: 18 | U35: 19 | V35: 20 | W35: 21 | X35: 22 | Y35: 23 | Z35: 24 | AA35: 25 | AB35: 25yr Total | AC35: 25yr NPV
A36: Debt Balance ($) | B36: =Inputs!C5 | C36: =MAX(0,B36-C38) | D36: =MAX(0,C36-D38) | E36: =MAX(0,D36-E38) | F36: =MAX(0,E36-F38) | G36: =MAX(0,F36-G38) | H36: =MAX(0,G36-H38) | I36: =MAX(0,H36-I38) | J36: =MAX(0,I36-J38) | ... AA36: =MAX(0,Z36-AA38)
A37: Interest Payment ($) | B37: 0 | C37: =IF(B36<=0,0,B36*Inputs!$C$11) | D37: =IF(C36<=0,0,C36*Inputs!$C$11) | E37: =IF(D36<=0,0,D36*Inputs!$C$11) | F37: =IF(E36<=0,0,E36*Inputs!$C$11) | G37: =IF(F36<=0,0,F36*Inputs!$C$11) | H37: =IF(G36<=0,0,G36*Inputs!$C$11) | I37: =IF(H36<=0,0,H36*Inputs!$C$11) | J37: =IF(I36<=0,0,I36*Inputs!$C$11) | ... AA37: =IF(Z36<=0,0,Z36*Inputs!$C$11)
A38: Principal Payment ($) | B38: 0 | C38: =IF(B36<=0,0,C39-C37) | D38: =IF(B36<=0,0,D39-D37) | E38: =IF(B36<=0,0,E39-E37) | F38: =IF(B36<=0,0,F39-F37) | G38: =IF(B36<=0,0,G39-G37) | H38: =IF(B36<=0,0,H39-H37) | I38: =IF(B36<=0,0,I39-I37) | J38: =IF(B36<=0,0,J39-J37) | K38: =IF(B36<=0,0,K39-K37) | L38: =IF(B36<=0,0,L39-L37) | M38: =IF(B36<=0,0,M39-M37) | N38: =IF(B36<=0,0,N39-N37) | O38: =IF(B36<=0,0,O39-O37) | P38: =IF(B36<=0,0,P39-P37) | Q38: =IF(B36<=0,0,Q39-Q37) | R38: =IF(B36<=0,0,R39-R37) | S38: =IF(B36<=0,0,S39-S37) | T38: =IF(B36<=0,0,T39-T37) | U38: =IF(B36<=0,0,U39-U37) | V38: =IF(B36<=0,0,V39-V37) | W38: =IF(B36<=0,0,W39-W37) | X38: =IF(B36<=0,0,X39-X37) | Y38: =IF(B36<=0,0,Y39-Y37) | Z38: =IF(B36<=0,0,Z39-Z37) | AA38: =IF(B36<=0,0,AA39-AA37)
A39: Total Payment — P&I ($) | B39: 0 | C39: =IF(B36<=0,0,ABS(PMT(Inputs!$C$11,Inputs!$C$13,B36,0))) | D39: =IF(C36<=0,0,ABS(PMT(Inputs!$C$11,Inputs!$C$13,B36,0))) | E39: =IF(D36<=0,0,ABS(PMT(Inputs!$C$11,Inputs!$C$13,B36,0))) | F39: =IF(E36<=0,0,ABS(PMT(Inputs!$C$11,Inputs!$C$13,B36,0))) | G39: =IF(F36<=0,0,ABS(PMT(Inputs!$C$11,Inputs!$C$13,B36,0))) | H39: =IF(G36<=0,0,ABS(PMT(Inputs!$C$11,Inputs!$C$13,B36,0))) | I39: =IF(H36<=0,0,ABS(PMT(Inputs!$C$11,Inputs!$C$13,B36,0))) | J39: =IF(I36<=0,0,ABS(PMT(Inputs!$C$11,Inputs!$C$13,B36,0))) | K39: =IF(J36<=0,0,ABS(PMT(Inputs!$C$11,Inputs!$C$13,B36,0))) | L39: =IF(K36<=0,0,ABS(PMT(Inputs!$C$11,Inputs!$C$13,B36,0))) | M39: =IF(L36<=0,0,ABS(PMT(Inputs!$C$11,Inputs!$C$13,B36,0))) | N39: =IF(M36<=0,0,ABS(PMT(Inputs!$C$11,Inputs!$C$13,B36,0))) | O39: =IF(N36<=0,0,ABS(PMT(Inputs!$C$11,Inputs!$C$13,B36,0))) | P39: =IF(O36<=0,0,ABS(PMT(Inputs!$C$11,Inputs!$C$13,B36,0))) | Q39: =IF(P36<=0,0,ABS(PMT(Inputs!$C$11,Inputs!$C$13,B36,0))) | R39: =IF(Q36<=0,0,ABS(PMT(Inputs!$C$11,Inputs!$C$13,B36,0))) | S39: =IF(R36<=0,0,ABS(PMT(Inputs!$C$11,Inputs!$C$13,B36,0))) | T39: =IF(S36<=0,0,ABS(PMT(Inputs!$C$11,Inputs!$C$13,B36,0))) | U39: =IF(T36<=0,0,ABS(PMT(Inputs!$C$11,Inputs!$C$13,B36,0))) | V39: =IF(U36<=0,0,ABS(PMT(Inputs!$C$11,Inputs!$C$13,B36,0))) | W39: =IF(V36<=0,0,ABS(PMT(Inputs!$C$11,Inputs!$C$13,B36,0))) | X39: =IF(W36<=0,0,ABS(PMT(Inputs!$C$11,Inputs!$C$13,B36,0))) | Y39: =IF(X36<=0,0,ABS(PMT(Inputs!$C$11,Inputs!$C$13,B36,0))) | Z39: =IF(Y36<=0,0,ABS(PMT(Inputs!$C$11,Inputs!$C$13,B36,0))) | AA39: =IF(Z36<=0,0,ABS(PMT(Inputs!$C$11,Inputs!$C$13,B36,0))) | AB39: =SUM(C39:AA39) | AC39: =NPV(Inputs!$C$12,C39:AA39)
A41: Elec. Bill — No System ($) | B41: 0 | C41: =Inputs!C25 | D41: =C41*(1+Inputs!$C$14) | E41: =D41*(1+Inputs!$C$14) | F41: =E41*(1+Inputs!$C$14) | G41: =F41*(1+Inputs!$C$14) | H41: =G41*(1+Inputs!$C$14) | I41: =H41*(1+Inputs!$C$14) | J41: =I41*(1+Inputs!$C$14) | K41: =J41*(1+Inputs!$C$14) | ... AA41: =Z41*(1+Inputs!$C$14)
A42: Elec. Bill — With System ($) | B42: 0 | C42: =Inputs!D25 | D42: =C42*(1+Inputs!$C$14) | E42: =D42*(1+Inputs!$C$14) | F42: =E42*(1+Inputs!$C$14) | G42: =F42*(1+Inputs!$C$14) | H42: =G42*(1+Inputs!$C$14) | I42: =H42*(1+Inputs!$C$14) | J42: =I42*(1+Inputs!$C$14) | K42: =J42*(1+Inputs!$C$14) | ... AA42: =Z42*(1+Inputs!$C$14)
A43: Bill Savings ($) | B43: 0 | C43: =C41-C42 | D43: =D41-D42 | E43: =E41-E42 | F43: =F41-F42 | G43: =G41-G42 | H43: =H41-H42 | I43: =I41-I42 | J43: =J41-J42 | ... AA43: =AA41-AA42 | AB43: =SUM(C43:AA43) | AC43: =NPV(Inputs!$C$12,C43:AA43)
A44: Incentive Savings — Annual ($) | B44: 0 | C44: 0 | D44: 0 | E44: 0 | F44: 0 | G44: 0 | H44: 0 | I44: 0 | J44: 0 | K44: 0 | L44: 0 | M44: 0 | N44: 0 | O44: 0 | P44: 0 | Q44: 0 | R44: 0 | S44: 0 | T44: 0 | U44: 0 | V44: 0 | W44: 0 | X44: 0 | Y44: 0 | Z44: 0 | AA44: 0 | AB44: =SUM(C44:AA44) | AC44: =NPV(Inputs!$C$12,C44:AA44)
A45: Total Savings ($) | B45: =B43+B44 | C45: =C43+C44 | D45: =D43+D44 | E45: =E43+E44 | F45: =F43+F44 | G45: =G43+G44 | H45: =H43+H44 | I45: =I43+I44 | ... AA45: =AA43+AA44 | AB45: =SUM(C45:AA45) | AC45: =NPV(Inputs!$C$12,C45:AA45)
A46: Net Savings ($) | B46: =B45-B39 | C46: =C45-C39 | D46: =D45-D39 | E46: =E45-E39 | F46: =F45-F39 | G46: =G45-G39 | H46: =H45-H39 | I46: =I45-I39 | ... AA46: =AA45-AA39 | AB46: =SUM(C46:AA46) | AC46: =NPV(Inputs!$C$12,C46:AA46)

Sheet PV+Storage Bridge
A1: PV + Storage — Bridge (NMB/TOU) Rate
A2: All formulas reference Inputs sheet
A4: Scenario 1: FedITC + State Incentives
A5: Year | B5: 0 | C5: 1 | D5: 2 | E5: 3 | F5: 4 | G5: 5 | H5: 6 | I5: 7 | J5: 8 | K5: 9 | L5: 10 | M5: 11 | N5: 12 | O5: 13 | P5: 14 | Q5: 15 | R5: 16 | S5: 17 | T5: 18 | U5: 19 | V5: 20 | W5: 21 | X5: 22 | Y5: 23 | Z5: 24 | AA5: 25 | AB5: 25yr Total | AC5: 25yr NPV
A6: Debt Balance ($) | B6: =Inputs!C5-Inputs!C18-Inputs!C20 | C6: =MAX(0,B6-C8) | D6: =MAX(0,C6-D8) | E6: =MAX(0,D6-E8) | F6: =MAX(0,E6-F8) | G6: =MAX(0,F6-G8) | H6: =MAX(0,G6-H8) | I6: =MAX(0,H6-I8) | J6: =MAX(0,I6-J8) | ... AA6: =MAX(0,Z6-AA8)
A7: Interest Payment ($) | B7: 0 | C7: =IF(B6<=0,0,B6*Inputs!$C$11) | D7: =IF(C6<=0,0,C6*Inputs!$C$11) | E7: =IF(D6<=0,0,D6*Inputs!$C$11) | F7: =IF(E6<=0,0,E6*Inputs!$C$11) | G7: =IF(F6<=0,0,F6*Inputs!$C$11) | H7: =IF(G6<=0,0,G6*Inputs!$C$11) | I7: =IF(H6<=0,0,H6*Inputs!$C$11) | J7: =IF(I6<=0,0,I6*Inputs!$C$11) | ... AA7: =IF(Z6<=0,0,Z6*Inputs!$C$11)
A8: Principal Payment ($) | B8: 0 | C8: =IF(B6<=0,0,C9-C7) | D8: =IF(B6<=0,0,D9-D7) | E8: =IF(B6<=0,0,E9-E7) | F8: =IF(B6<=0,0,F9-F7) | G8: =IF(B6<=0,0,G9-G7) | H8: =IF(B6<=0,0,H9-H7) | I8: =IF(B6<=0,0,I9-I7) | J8: =IF(B6<=0,0,J9-J7) | K8: =IF(B6<=0,0,K9-K7) | L8: =IF(B6<=0,0,L9-L7) | M8: =IF(B6<=0,0,M9-M7) | N8: =IF(B6<=0,0,N9-N7) | O8: =IF(B6<=0,0,O9-O7) | P8: =IF(B6<=0,0,P9-P7) | Q8: =IF(B6<=0,0,Q9-Q7) | R8: =IF(B6<=0,0,R9-R7) | S8: =IF(B6<=0,0,S9-S7) | T8: =IF(B6<=0,0,T9-T7) | U8: =IF(B6<=0,0,U9-U7) | V8: =IF(B6<=0,0,V9-V7) | W8: =IF(B6<=0,0,W9-W7) | X8: =IF(B6<=0,0,X9-X7) | Y8: =IF(B6<=0,0,Y9-Y7) | Z8: =IF(B6<=0,0,Z9-Z7) | AA8: =IF(B6<=0,0,AA9-AA7)
A9: Total Payment — P&I ($) | B9: 0 | C9: =IF(B6<=0,0,ABS(PMT(Inputs!$C$11,Inputs!$C$13,B6,0))) | D9: =IF(C6<=0,0,ABS(PMT(Inputs!$C$11,Inputs!$C$13,B6,0))) | E9: =IF(D6<=0,0,ABS(PMT(Inputs!$C$11,Inputs!$C$13,B6,0))) | F9: =IF(E6<=0,0,ABS(PMT(Inputs!$C$11,Inputs!$C$13,B6,0))) | G9: =IF(F6<=0,0,ABS(PMT(Inputs!$C$11,Inputs!$C$13,B6,0))) | H9: =IF(G6<=0,0,ABS(PMT(Inputs!$C$11,Inputs!$C$13,B6,0))) | I9: =IF(H6<=0,0,ABS(PMT(Inputs!$C$11,Inputs!$C$13,B6,0))) | J9: =IF(I6<=0,0,ABS(PMT(Inputs!$C$11,Inputs!$C$13,B6,0))) | K9: =IF(J6<=0,0,ABS(PMT(Inputs!$C$11,Inputs!$C$13,B6,0))) | L9: =IF(K6<=0,0,ABS(PMT(Inputs!$C$11,Inputs!$C$13,B6,0))) | M9: =IF(L6<=0,0,ABS(PMT(Inputs!$C$11,Inputs!$C$13,B6,0))) | N9: =IF(M6<=0,0,ABS(PMT(Inputs!$C$11,Inputs!$C$13,B6,0))) | O9: =IF(N6<=0,0,ABS(PMT(Inputs!$C$11,Inputs!$C$13,B6,0))) | P9: =IF(O6<=0,0,ABS(PMT(Inputs!$C$11,Inputs!$C$13,B6,0))) | Q9: =IF(P6<=0,0,ABS(PMT(Inputs!$C$11,Inputs!$C$13,B6,0))) | R9: =IF(Q6<=0,0,ABS(PMT(Inputs!$C$11,Inputs!$C$13,B6,0))) | S9: =IF(R6<=0,0,ABS(PMT(Inputs!$C$11,Inputs!$C$13,B6,0))) | T9: =IF(S6<=0,0,ABS(PMT(Inputs!$C$11,Inputs!$C$13,B6,0))) | U9: =IF(T6<=0,0,ABS(PMT(Inputs!$C$11,Inputs!$C$13,B6,0))) | V9: =IF(U6<=0,0,ABS(PMT(Inputs!$C$11,Inputs!$C$13,B6,0))) | W9: =IF(V6<=0,0,ABS(PMT(Inputs!$C$11,Inputs!$C$13,B6,0))) | X9: =IF(W6<=0,0,ABS(PMT(Inputs!$C$11,Inputs!$C$13,B6,0))) | Y9: =IF(X6<=0,0,ABS(PMT(Inputs!$C$11,Inputs!$C$13,B6,0))) | Z9: =IF(Y6<=0,0,ABS(PMT(Inputs!$C$11,Inputs!$C$13,B6,0))) | AA9: =IF(Z6<=0,0,ABS(PMT(Inputs!$C$11,Inputs!$C$13,B6,0))) | AB9: =SUM(C9:AA9) | AC9: =NPV(Inputs!$C$12,C9:AA9)
A11: Elec. Bill — No System ($) | B11: 0 | C11: =Inputs!C26 | D11: =C11*(1+Inputs!$C$14) | E11: =D11*(1+Inputs!$C$14) | F11: =E11*(1+Inputs!$C$14) | G11: =F11*(1+Inputs!$C$14) | H11: =G11*(1+Inputs!$C$14) | I11: =H11*(1+Inputs!$C$14) | J11: =I11*(1+Inputs!$C$14) | K11: =J11*(1+Inputs!$C$14) | ... AA11: =Z11*(1+Inputs!$C$14)
A12: Elec. Bill — With System ($) | B12: 0 | C12: =Inputs!D26 | D12: =C12*(1+Inputs!$C$14) | E12: =D12*(1+Inputs!$C$14) | F12: =E12*(1+Inputs!$C$14) | G12: =F12*(1+Inputs!$C$14) | H12: =G12*(1+Inputs!$C$14) | I12: =H12*(1+Inputs!$C$14) | J12: =I12*(1+Inputs!$C$14) | K12: =J12*(1+Inputs!$C$14) | ... AA12: =Z12*(1+Inputs!$C$14)
A13: Bill Savings ($) | B13: 0 | C13: =C11-C12 | D13: =D11-D12 | E13: =E11-E12 | F13: =F11-F12 | G13: =G11-G12 | H13: =H11-H12 | I13: =I11-I12 | J13: =J11-J12 | ... AA13: =AA11-AA12 | AB13: =SUM(C13:AA13) | AC13: =NPV(Inputs!$C$12,C13:AA13)
A14: Incentive Savings — Annual ($) | B14: 0 | C14: =Inputs!$C$21 | D14: =Inputs!$C$21 | E14: =Inputs!$C$21 | F14: =Inputs!$C$21 | G14: =Inputs!$C$21 | H14: =Inputs!$C$21 | I14: =Inputs!$C$21 | J14: =Inputs!$C$21 | ... AA14: =Inputs!$C$21 | AB14: =SUM(C14:AA14) | AC14: =NPV(Inputs!$C$12,C14:AA14)
A15: Total Savings ($) | B15: =B13+B14 | C15: =C13+C14 | D15: =D13+D14 | E15: =E13+E14 | F15: =F13+F14 | G15: =G13+G14 | H15: =H13+H14 | I15: =I13+I14 | ... AA15: =AA13+AA14 | AB15: =SUM(C15:AA15) | AC15: =NPV(Inputs!$C$12,C15:AA15)
A16: Net Savings ($) | B16: =B15-B9 | C16: =C15-C9 | D16: =D15-D9 | E16: =E15-E9 | F16: =F15-F9 | G16: =G15-G9 | H16: =H15-H9 | I16: =I15-I9 | ... AA16: =AA15-AA9 | AB16: =SUM(C16:AA16) | AC16: =NPV(Inputs!$C$12,C16:AA16)
A19: Scenario 2: State Incentives Only (No FedITC)
A20: Year | B20: 0 | C20: 1 | D20: 2 | E20: 3 | F20: 4 | G20: 5 | H20: 6 | I20: 7 | J20: 8 | K20: 9 | L20: 10 | M20: 11 | N20: 12 | O20: 13 | P20: 14 | Q20: 15 | R20: 16 | S20: 17 | T20: 18 | U20: 19 | V20: 20 | W20: 21 | X20: 22 | Y20: 23 | Z20: 24 | AA20: 25 | AB20: 25yr Total | AC20: 25yr NPV
A21: Debt Balance ($) | B21: =Inputs!C5-Inputs!C20 | C21: =MAX(0,B21-C23) | D21: =MAX(0,C21-D23) | E21: =MAX(0,D21-E23) | F21: =MAX(0,E21-F23) | G21: =MAX(0,F21-G23) | H21: =MAX(0,G21-H23) | I21: =MAX(0,H21-I23) | J21: =MAX(0,I21-J23) | ... AA21: =MAX(0,Z21-AA23)
A22: Interest Payment ($) | B22: 0 | C22: =IF(B21<=0,0,B21*Inputs!$C$11) | D22: =IF(C21<=0,0,C21*Inputs!$C$11) | E22: =IF(D21<=0,0,D21*Inputs!$C$11) | F22: =IF(E21<=0,0,E21*Inputs!$C$11) | G22: =IF(F21<=0,0,F21*Inputs!$C$11) | H22: =IF(G21<=0,0,G21*Inputs!$C$11) | I22: =IF(H21<=0,0,H21*Inputs!$C$11) | J22: =IF(I21<=0,0,I21*Inputs!$C$11) | ... AA22: =IF(Z21<=0,0,Z21*Inputs!$C$11)
A23: Principal Payment ($) | B23: 0 | C23: =IF(B21<=0,0,C24-C22) | D23: =IF(B21<=0,0,D24-D22) | E23: =IF(B21<=0,0,E24-E22) | F23: =IF(B21<=0,0,F24-F22) | G23: =IF(B21<=0,0,G24-G22) | H23: =IF(B21<=0,0,H24-H22) | I23: =IF(B21<=0,0,I24-I22) | J23: =IF(B21<=0,0,J24-J22) | K23: =IF(B21<=0,0,K24-K22) | L23: =IF(B21<=0,0,L24-L22) | M23: =IF(B21<=0,0,M24-M22) | N23: =IF(B21<=0,0,N24-N22) | O23: =IF(B21<=0,0,O24-O22) | P23: =IF(B21<=0,0,P24-P22) | Q23: =IF(B21<=0,0,Q24-Q22) | R23: =IF(B21<=0,0,R24-R22) | S23: =IF(B21<=0,0,S24-S22) | T23: =IF(B21<=0,0,T24-T22) | U23: =IF(B21<=0,0,U24-U22) | V23: =IF(B21<=0,0,V24-V22) | W23: =IF(B21<=0,0,W24-W22) | X23: =IF(B21<=0,0,X24-X22) | Y23: =IF(B21<=0,0,Y24-Y22) | Z23: =IF(B21<=0,0,Z24-Z22) | AA23: =IF(B21<=0,0,AA24-AA22)
A24: Total Payment — P&I ($) | B24: 0 | C24: =IF(B21<=0,0,ABS(PMT(Inputs!$C$11,Inputs!$C$13,B21,0))) | D24: =IF(C21<=0,0,ABS(PMT(Inputs!$C$11,Inputs!$C$13,B21,0))) | E24: =IF(D21<=0,0,ABS(PMT(Inputs!$C$11,Inputs!$C$13,B21,0))) | F24: =IF(E21<=0,0,ABS(PMT(Inputs!$C$11,Inputs!$C$13,B21,0))) | G24: =IF(F21<=0,0,ABS(PMT(Inputs!$C$11,Inputs!$C$13,B21,0))) | H24: =IF(G21<=0,0,ABS(PMT(Inputs!$C$11,Inputs!$C$13,B21,0))) | I24: =IF(H21<=0,0,ABS(PMT(Inputs!$C$11,Inputs!$C$13,B21,0))) | J24: =IF(I21<=0,0,ABS(PMT(Inputs!$C$11,Inputs!$C$13,B21,0))) | K24: =IF(J21<=0,0,ABS(PMT(Inputs!$C$11,Inputs!$C$13,B21,0))) | L24: =IF(K21<=0,0,ABS(PMT(Inputs!$C$11,Inputs!$C$13,B21,0))) | M24: =IF(L21<=0,0,ABS(PMT(Inputs!$C$11,Inputs!$C$13,B21,0))) | N24: =IF(M21<=0,0,ABS(PMT(Inputs!$C$11,Inputs!$C$13,B21,0))) | O24: =IF(N21<=0,0,ABS(PMT(Inputs!$C$11,Inputs!$C$13,B21,0))) | P24: =IF(O21<=0,0,ABS(PMT(Inputs!$C$11,Inputs!$C$13,B21,0))) | Q24: =IF(P21<=0,0,ABS(PMT(Inputs!$C$11,Inputs!$C$13,B21,0))) | R24: =IF(Q21<=0,0,ABS(PMT(Inputs!$C$11,Inputs!$C$13,B21,0))) | S24: =IF(R21<=0,0,ABS(PMT(Inputs!$C$11,Inputs!$C$13,B21,0))) | T24: =IF(S21<=0,0,ABS(PMT(Inputs!$C$11,Inputs!$C$13,B21,0))) | U24: =IF(T21<=0,0,ABS(PMT(Inputs!$C$11,Inputs!$C$13,B21,0))) | V24: =IF(U21<=0,0,ABS(PMT(Inputs!$C$11,Inputs!$C$13,B21,0))) | W24: =IF(V21<=0,0,ABS(PMT(Inputs!$C$11,Inputs!$C$13,B21,0))) | X24: =IF(W21<=0,0,ABS(PMT(Inputs!$C$11,Inputs!$C$13,B21,0))) | Y24: =IF(X21<=0,0,ABS(PMT(Inputs!$C$11,Inputs!$C$13,B21,0))) | Z24: =IF(Y21<=0,0,ABS(PMT(Inputs!$C$11,Inputs!$C$13,B21,0))) | AA24: =IF(Z21<=0,0,ABS(PMT(Inputs!$C$11,Inputs!$C$13,B21,0))) | AB24: =SUM(C24:AA24) | AC24: =NPV(Inputs!$C$12,C24:AA24)
A26: Elec. Bill — No System ($) | B26: 0 | C26: =Inputs!C26 | D26: =C26*(1+Inputs!$C$14) | E26: =D26*(1+Inputs!$C$14) | F26: =E26*(1+Inputs!$C$14) | G26: =F26*(1+Inputs!$C$14) | H26: =G26*(1+Inputs!$C$14) | I26: =H26*(1+Inputs!$C$14) | J26: =I26*(1+Inputs!$C$14) | K26: =J26*(1+Inputs!$C$14) | ... AA26: =Z26*(1+Inputs!$C$14)
A27: Elec. Bill — With System ($) | B27: 0 | C27: =Inputs!D26 | D27: =C27*(1+Inputs!$C$14) | E27: =D27*(1+Inputs!$C$14) | F27: =E27*(1+Inputs!$C$14) | G27: =F27*(1+Inputs!$C$14) | H27: =G27*(1+Inputs!$C$14) | I27: =H27*(1+Inputs!$C$14) | J27: =I27*(1+Inputs!$C$14) | K27: =J27*(1+Inputs!$C$14) | ... AA27: =Z27*(1+Inputs!$C$14)
A28: Bill Savings ($) | B28: 0 | C28: =C26-C27 | D28: =D26-D27 | E28: =E26-E27 | F28: =F26-F27 | G28: =G26-G27 | H28: =H26-H27 | I28: =I26-I27 | J28: =J26-J27 | ... AA28: =AA26-AA27 | AB28: =SUM(C28:AA28) | AC28: =NPV(Inputs!$C$12,C28:AA28)
A29: Incentive Savings — Annual ($) | B29: 0 | C29: =Inputs!$C$21 | D29: =Inputs!$C$21 | E29: =Inputs!$C$21 | F29: =Inputs!$C$21 | G29: =Inputs!$C$21 | H29: =Inputs!$C$21 | I29: =Inputs!$C$21 | J29: =Inputs!$C$21 | ... AA29: =Inputs!$C$21 | AB29: =SUM(C29:AA29) | AC29: =NPV(Inputs!$C$12,C29:AA29)
A30: Total Savings ($) | B30: =B28+B29 | C30: =C28+C29 | D30: =D28+D29 | E30: =E28+E29 | F30: =F28+F29 | G30: =G28+G29 | H30: =H28+H29 | I30: =I28+I29 | ... AA30: =AA28+AA29 | AB30: =SUM(C30:AA30) | AC30: =NPV(Inputs!$C$12,C30:AA30)
A31: Net Savings ($) | B31: =B30-B24 | C31: =C30-C24 | D31: =D30-D24 | E31: =E30-E24 | F31: =F30-F24 | G31: =G30-G24 | H31: =H30-H24 | I31: =I30-I24 | ... AA31: =AA30-AA24 | AB31: =SUM(C31:AA31) | AC31: =NPV(Inputs!$C$12,C31:AA31)
A34: Scenario 3: No Incentives
A35: Year | B35: 0 | C35: 1 | D35: 2 | E35: 3 | F35: 4 | G35: 5 | H35: 6 | I35: 7 | J35: 8 | K35: 9 | L35: 10 | M35: 11 | N35: 12 | O35: 13 | P35: 14 | Q35: 15 | R35: 16 | S35: 17 | T35: 18 | U35: 19 | V35: 20 | W35: 21 | X35: 22 | Y35: 23 | Z35: 24 | AA35: 25 | AB35: 25yr Total | AC35: 25yr NPV
A36: Debt Balance ($) | B36: =Inputs!C5 | C36: =MAX(0,B36-C38) | D36: =MAX(0,C36-D38) | E36: =MAX(0,D36-E38) | F36: =MAX(0,E36-F38) | G36: =MAX(0,F36-G38) | H36: =MAX(0,G36-H38) | I36: =MAX(0,H36-I38) | J36: =MAX(0,I36-J38) | ... AA36: =MAX(0,Z36-AA38)
A37: Interest Payment ($) | B37: 0 | C37: =IF(B36<=0,0,B36*Inputs!$C$11) | D37: =IF(C36<=0,0,C36*Inputs!$C$11) | E37: =IF(D36<=0,0,D36*Inputs!$C$11) | F37: =IF(E36<=0,0,E36*Inputs!$C$11) | G37: =IF(F36<=0,0,F36*Inputs!$C$11) | H37: =IF(G36<=0,0,G36*Inputs!$C$11) | I37: =IF(H36<=0,0,H36*Inputs!$C$11) | J37: =IF(I36<=0,0,I36*Inputs!$C$11) | ... AA37: =IF(Z36<=0,0,Z36*Inputs!$C$11)
A38: Principal Payment ($) | B38: 0 | C38: =IF(B36<=0,0,C39-C37) | D38: =IF(B36<=0,0,D39-D37) | E38: =IF(B36<=0,0,E39-E37) | F38: =IF(B36<=0,0,F39-F37) | G38: =IF(B36<=0,0,G39-G37) | H38: =IF(B36<=0,0,H39-H37) | I38: =IF(B36<=0,0,I39-I37) | J38: =IF(B36<=0,0,J39-J37) | K38: =IF(B36<=0,0,K39-K37) | L38: =IF(B36<=0,0,L39-L37) | M38: =IF(B36<=0,0,M39-M37) | N38: =IF(B36<=0,0,N39-N37) | O38: =IF(B36<=0,0,O39-O37) | P38: =IF(B36<=0,0,P39-P37) | Q38: =IF(B36<=0,0,Q39-Q37) | R38: =IF(B36<=0,0,R39-R37) | S38: =IF(B36<=0,0,S39-S37) | T38: =IF(B36<=0,0,T39-T37) | U38: =IF(B36<=0,0,U39-U37) | V38: =IF(B36<=0,0,V39-V37) | W38: =IF(B36<=0,0,W39-W37) | X38: =IF(B36<=0,0,X39-X37) | Y38: =IF(B36<=0,0,Y39-Y37) | Z38: =IF(B36<=0,0,Z39-Z37) | AA38: =IF(B36<=0,0,AA39-AA37)
A39: Total Payment — P&I ($) | B39: 0 | C39: =IF(B36<=0,0,ABS(PMT(Inputs!$C$11,Inputs!$C$13,B36,0))) | D39: =IF(C36<=0,0,ABS(PMT(Inputs!$C$11,Inputs!$C$13,B36,0))) | E39: =IF(D36<=0,0,ABS(PMT(Inputs!$C$11,Inputs!$C$13,B36,0))) | F39: =IF(E36<=0,0,ABS(PMT(Inputs!$C$11,Inputs!$C$13,B36,0))) | G39: =IF(F36<=0,0,ABS(PMT(Inputs!$C$11,Inputs!$C$13,B36,0))) | H39: =IF(G36<=0,0,ABS(PMT(Inputs!$C$11,Inputs!$C$13,B36,0))) | I39: =IF(H36<=0,0,ABS(PMT(Inputs!$C$11,Inputs!$C$13,B36,0))) | J39: =IF(I36<=0,0,ABS(PMT(Inputs!$C$11,Inputs!$C$13,B36,0))) | K39: =IF(J36<=0,0,ABS(PMT(Inputs!$C$11,Inputs!$C$13,B36,0))) | L39: =IF(K36<=0,0,ABS(PMT(Inputs!$C$11,Inputs!$C$13,B36,0))) | M39: =IF(L36<=0,0,ABS(PMT(Inputs!$C$11,Inputs!$C$13,B36,0))) | N39: =IF(M36<=0,0,ABS(PMT(Inputs!$C$11,Inputs!$C$13,B36,0))) | O39: =IF(N36<=0,0,ABS(PMT(Inputs!$C$11,Inputs!$C$13,B36,0))) | P39: =IF(O36<=0,0,ABS(PMT(Inputs!$C$11,Inputs!$C$13,B36,0))) | Q39: =IF(P36<=0,0,ABS(PMT(Inputs!$C$11,Inputs!$C$13,B36,0))) | R39: =IF(Q36<=0,0,ABS(PMT(Inputs!$C$11,Inputs!$C$13,B36,0))) | S39: =IF(R36<=0,0,ABS(PMT(Inputs!$C$11,Inputs!$C$13,B36,0))) | T39: =IF(S36<=0,0,ABS(PMT(Inputs!$C$11,Inputs!$C$13,B36,0))) | U39: =IF(T36<=0,0,ABS(PMT(Inputs!$C$11,Inputs!$C$13,B36,0))) | V39: =IF(U36<=0,0,ABS(PMT(Inputs!$C$11,Inputs!$C$13,B36,0))) | W39: =IF(V36<=0,0,ABS(PMT(Inputs!$C$11,Inputs!$C$13,B36,0))) | X39: =IF(W36<=0,0,ABS(PMT(Inputs!$C$11,Inputs!$C$13,B36,0))) | Y39: =IF(X36<=0,0,ABS(PMT(Inputs!$C$11,Inputs!$C$13,B36,0))) | Z39: =IF(Y36<=0,0,ABS(PMT(Inputs!$C$11,Inputs!$C$13,B36,0))) | AA39: =IF(Z36<=0,0,ABS(PMT(Inputs!$C$11,Inputs!$C$13,B36,0))) | AB39: =SUM(C39:AA39) | AC39: =NPV(Inputs!$C$12,C39:AA39)
A41: Elec. Bill — No System ($) | B41: 0 | C41: =Inputs!C26 | D41: =C41*(1+Inputs!$C$14) | E41: =D41*(1+Inputs!$C$14) | F41: =E41*(1+Inputs!$C$14) | G41: =F41*(1+Inputs!$C$14) | H41: =G41*(1+Inputs!$C$14) | I41: =H41*(1+Inputs!$C$14) | J41: =I41*(1+Inputs!$C$14) | K41: =J41*(1+Inputs!$C$14) | ... AA41: =Z41*(1+Inputs!$C$14)
A42: Elec. Bill — With System ($) | B42: 0 | C42: =Inputs!D26 | D42: =C42*(1+Inputs!$C$14) | E42: =D42*(1+Inputs!$C$14) | F42: =E42*(1+Inputs!$C$14) | G42: =F42*(1+Inputs!$C$14) | H42: =G42*(1+Inputs!$C$14) | I42: =H42*(1+Inputs!$C$14) | J42: =I42*(1+Inputs!$C$14) | K42: =J42*(1+Inputs!$C$14) | ... AA42: =Z42*(1+Inputs!$C$14)
A43: Bill Savings ($) | B43: 0 | C43: =C41-C42 | D43: =D41-D42 | E43: =E41-E42 | F43: =F41-F42 | G43: =G41-G42 | H43: =H41-H42 | I43: =I41-I42 | J43: =J41-J42 | ... AA43: =AA41-AA42 | AB43: =SUM(C43:AA43) | AC43: =NPV(Inputs!$C$12,C43:AA43)
A44: Incentive Savings — Annual ($) | B44: 0 | C44: 0 | D44: 0 | E44: 0 | F44: 0 | G44: 0 | H44: 0 | I44: 0 | J44: 0 | K44: 0 | L44: 0 | M44: 0 | N44: 0 | O44: 0 | P44: 0 | Q44: 0 | R44: 0 | S44: 0 | T44: 0 | U44: 0 | V44: 0 | W44: 0 | X44: 0 | Y44: 0 | Z44: 0 | AA44: 0 | AB44: =SUM(C44:AA44) | AC44: =NPV(Inputs!$C$12,C44:AA44)
A45: Total Savings ($) | B45: =B43+B44 | C45: =C43+C44 | D45: =D43+D44 | E45: =E43+E44 | F45: =F43+F44 | G45: =G43+G44 | H45: =H43+H44 | I45: =I43+I44 | ... AA45: =AA43+AA44 | AB45: =SUM(C45:AA45) | AC45: =NPV(Inputs!$C$12,C45:AA45)
A46: Net Savings ($) | B46: =B45-B39 | C46: =C45-C39 | D46: =D45-D39 | E46: =E45-E39 | F46: =F45-F39 | G46: =G45-G39 | H46: =H45-H39 | I46: =I45-I39 | ... AA46: =AA45-AA39 | AB46: =SUM(C46:AA46) | AC46: =NPV(Inputs!$C$12,C46:AA46)

Sheet Solar Only RSC
A1: Solar Only — RSC Rate
A2: All formulas reference Inputs sheet
A4: Scenario 1: With FedITC
A5: Year | B5: 0 | C5: 1 | D5: 2 | E5: 3 | F5: 4 | G5: 5 | H5: 6 | I5: 7 | J5: 8 | K5: 9 | L5: 10 | M5: 11 | N5: 12 | O5: 13 | P5: 14 | Q5: 15 | R5: 16 | S5: 17 | T5: 18 | U5: 19 | V5: 20 | W5: 21 | X5: 22 | Y5: 23 | Z5: 24 | AA5: 25 | AB5: 25yr Total | AC5: 25yr NPV
A6: Debt Balance ($) | B6: =Inputs!C6-Inputs!C19 | C6: =MAX(0,B6-C8) | D6: =MAX(0,C6-D8) | E6: =MAX(0,D6-E8) | F6: =MAX(0,E6-F8) | G6: =MAX(0,F6-G8) | H6: =MAX(0,G6-H8) | I6: =MAX(0,H6-I8) | J6: =MAX(0,I6-J8) | ... AA6: =MAX(0,Z6-AA8)
A7: Interest Payment ($) | B7: 0 | C7: =IF(B6<=0,0,B6*Inputs!$C$11) | D7: =IF(C6<=0,0,C6*Inputs!$C$11) | E7: =IF(D6<=0,0,D6*Inputs!$C$11) | F7: =IF(E6<=0,0,E6*Inputs!$C$11) | G7: =IF(F6<=0,0,F6*Inputs!$C$11) | H7: =IF(G6<=0,0,G6*Inputs!$C$11) | I7: =IF(H6<=0,0,H6*Inputs!$C$11) | J7: =IF(I6<=0,0,I6*Inputs!$C$11) | ... AA7: =IF(Z6<=0,0,Z6*Inputs!$C$11)
A8: Principal Payment ($) | B8: 0 | C8: =IF(B6<=0,0,C9-C7) | D8: =IF(B6<=0,0,D9-D7) | E8: =IF(B6<=0,0,E9-E7) | F8: =IF(B6<=0,0,F9-F7) | G8: =IF(B6<=0,0,G9-G7) | H8: =IF(B6<=0,0,H9-H7) | I8: =IF(B6<=0,0,I9-I7) | J8: =IF(B6<=0,0,J9-J7) | K8: =IF(B6<=0,0,K9-K7) | L8: =IF(B6<=0,0,L9-L7) | M8: =IF(B6<=0,0,M9-M7) | N8: =IF(B6<=0,0,N9-N7) | O8: =IF(B6<=0,0,O9-O7) | P8: =IF(B6<=0,0,P9-P7) | Q8: =IF(B6<=0,0,Q9-Q7) | R8: =IF(B6<=0,0,R9-R7) | S8: =IF(B6<=0,0,S9-S7) | T8: =IF(B6<=0,0,T9-T7) | U8: =IF(B6<=0,0,U9-U7) | V8: =IF(B6<=0,0,V9-V7) | W8: =IF(B6<=0,0,W9-W7) | X8: =IF(B6<=0,0,X9-X7) | Y8: =IF(B6<=0,0,Y9-Y7) | Z8: =IF(B6<=0,0,Z9-Z7) | AA8: =IF(B6<=0,0,AA9-AA7)
A9: Total Payment — P&I ($) | B9: 0 | C9: =IF(B6<=0,0,ABS(PMT(Inputs!$C$11,Inputs!$C$13,B6,0))) | D9: =IF(C6<=0,0,ABS(PMT(Inputs!$C$11,Inputs!$C$13,B6,0))) | E9: =IF(D6<=0,0,ABS(PMT(Inputs!$C$11,Inputs!$C$13,B6,0))) | F9: =IF(E6<=0,0,ABS(PMT(Inputs!$C$11,Inputs!$C$13,B6,0))) | G9: =IF(F6<=0,0,ABS(PMT(Inputs!$C$11,Inputs!$C$13,B6,0))) | H9: =IF(G6<=0,0,ABS(PMT(Inputs!$C$11,Inputs!$C$13,B6,0))) | I9: =IF(H6<=0,0,ABS(PMT(Inputs!$C$11,Inputs!$C$13,B6,0))) | J9: =IF(I6<=0,0,ABS(PMT(Inputs!$C$11,Inputs!$C$13,B6,0))) | K9: =IF(J6<=0,0,ABS(PMT(Inputs!$C$11,Inputs!$C$13,B6,0))) | L9: =IF(K6<=0,0,ABS(PMT(Inputs!$C$11,Inputs!$C$13,B6,0))) | M9: =IF(L6<=0,0,ABS(PMT(Inputs!$C$11,Inputs!$C$13,B6,0))) | N9: =IF(M6<=0,0,ABS(PMT(Inputs!$C$11,Inputs!$C$13,B6,0))) | O9: =IF(N6<=0,0,ABS(PMT(Inputs!$C$11,Inputs!$C$13,B6,0))) | P9: =IF(O6<=0,0,ABS(PMT(Inputs!$C$11,Inputs!$C$13,B6,0))) | Q9: =IF(P6<=0,0,ABS(PMT(Inputs!$C$11,Inputs!$C$13,B6,0))) | R9: =IF(Q6<=0,0,ABS(PMT(Inputs!$C$11,Inputs!$C$13,B6,0))) | S9: =IF(R6<=0,0,ABS(PMT(Inputs!$C$11,Inputs!$C$13,B6,0))) | T9: =IF(S6<=0,0,ABS(PMT(Inputs!$C$11,Inputs!$C$13,B6,0))) | U9: =IF(T6<=0,0,ABS(PMT(Inputs!$C$11,Inputs!$C$13,B6,0))) | V9: =IF(U6<=0,0,ABS(PMT(Inputs!$C$11,Inputs!$C$13,B6,0))) | W9: =IF(V6<=0,0,ABS(PMT(Inputs!$C$11,Inputs!$C$13,B6,0))) | X9: =IF(W6<=0,0,ABS(PMT(Inputs!$C$11,Inputs!$C$13,B6,0))) | Y9: =IF(X6<=0,0,ABS(PMT(Inputs!$C$11,Inputs!$C$13,B6,0))) | Z9: =IF(Y6<=0,0,ABS(PMT(Inputs!$C$11,Inputs!$C$13,B6,0))) | AA9: =IF(Z6<=0,0,ABS(PMT(Inputs!$C$11,Inputs!$C$13,B6,0))) | AB9: =SUM(C9:AA9) | AC9: =NPV(Inputs!$C$12,C9:AA9)
A11: Elec. Bill — No System ($) | B11: 0 | C11: =Inputs!C27 | D11: =C11*(1+Inputs!$C$14) | E11: =D11*(1+Inputs!$C$14) | F11: =E11*(1+Inputs!$C$14) | G11: =F11*(1+Inputs!$C$14) | H11: =G11*(1+Inputs!$C$14) | I11: =H11*(1+Inputs!$C$14) | J11: =I11*(1+Inputs!$C$14) | K11: =J11*(1+Inputs!$C$14) | ... AA11: =Z11*(1+Inputs!$C$14)
A12: Elec. Bill — With System ($) | B12: 0 | C12: =Inputs!D27 | D12: =C12*(1+Inputs!$C$14) | E12: =D12*(1+Inputs!$C$14) | F12: =E12*(1+Inputs!$C$14) | G12: =F12*(1+Inputs!$C$14) | H12: =G12*(1+Inputs!$C$14) | I12: =H12*(1+Inputs!$C$14) | J12: =I12*(1+Inputs!$C$14) | K12: =J12*(1+Inputs!$C$14) | ... AA12: =Z12*(1+Inputs!$C$14)
A13: Bill Savings ($) | B13: 0 | C13: =C11-C12 | D13: =D11-D12 | E13: =E11-E12 | F13: =F11-F12 | G13: =G11-G12 | H13: =H11-H12 | I13: =I11-I12 | J13: =J11-J12 | ... AA13: =AA11-AA12 | AB13: =SUM(C13:AA13) | AC13: =NPV(Inputs!$C$12,C13:AA13)
A14: Incentive Savings — Annual ($) | B14: 0 | C14: 0 | D14: 0 | E14: 0 | F14: 0 | G14: 0 | H14: 0 | I14: 0 | J14: 0 | K14: 0 | L14: 0 | M14: 0 | N14: 0 | O14: 0 | P14: 0 | Q14: 0 | R14: 0 | S14: 0 | T14: 0 | U14: 0 | V14: 0 | W14: 0 | X14: 0 | Y14: 0 | Z14: 0 | AA14: 0 | AB14: =SUM(C14:AA14) | AC14: =NPV(Inputs!$C$12,C14:AA14)
A15: Total Savings ($) | B15: =B13+B14 | C15: =C13+C14 | D15: =D13+D14 | E15: =E13+E14 | F15: =F13+F14 | G15: =G13+G14 | H15: =H13+H14 | I15: =I13+I14 | ... AA15: =AA13+AA14 | AB15: =SUM(C15:AA15) | AC15: =NPV(Inputs!$C$12,C15:AA15)
A16: Net Savings ($) | B16: =B15-B9 | C16: =C15-C9 | D16: =D15-D9 | E16: =E15-E9 | F16: =F15-F9 | G16: =G15-G9 | H16: =H15-H9 | I16: =I15-I9 | ... AA16: =AA15-AA9 | AB16: =SUM(C16:AA16) | AC16: =NPV(Inputs!$C$12,C16:AA16)
A19: Scenario 2: No Incentives
A20: Year | B20: 0 | C20: 1 | D20: 2 | E20: 3 | F20: 4 | G20: 5 | H20: 6 | I20: 7 | J20: 8 | K20: 9 | L20: 10 | M20: 11 | N20: 12 | O20: 13 | P20: 14 | Q20: 15 | R20: 16 | S20: 17 | T20: 18 | U20: 19 | V20: 20 | W20: 21 | X20: 22 | Y20: 23 | Z20: 24 | AA20: 25 | AB20: 25yr Total | AC20: 25yr NPV
A21: Debt Balance ($) | B21: =Inputs!C6 | C21: =MAX(0,B21-C23) | D21: =MAX(0,C21-D23) | E21: =MAX(0,D21-E23) | F21: =MAX(0,E21-F23) | G21: =MAX(0,F21-G23) | H21: =MAX(0,G21-H23) | I21: =MAX(0,H21-I23) | J21: =MAX(0,I21-J23) | ... AA21: =MAX(0,Z21-AA23)
A22: Interest Payment ($) | B22: 0 | C22: =IF(B21<=0,0,B21*Inputs!$C$11) | D22: =IF(C21<=0,0,C21*Inputs!$C$11) | E22: =IF(D21<=0,0,D21*Inputs!$C$11) | F22: =IF(E21<=0,0,E21*Inputs!$C$11) | G22: =IF(F21<=0,0,F21*Inputs!$C$11) | H22: =IF(G21<=0,0,G21*Inputs!$C$11) | I22: =IF(H21<=0,0,H21*Inputs!$C$11) | J22: =IF(I21<=0,0,I21*Inputs!$C$11) | ... AA22: =IF(Z21<=0,0,Z21*Inputs!$C$11)
A23: Principal Payment ($) | B23: 0 | C23: =IF(B21<=0,0,C24-C22) | D23: =IF(B21<=0,0,D24-D22) | E23: =IF(B21<=0,0,E24-E22) | F23: =IF(B21<=0,0,F24-F22) | G23: =IF(B21<=0,0,G24-G22) | H23: =IF(B21<=0,0,H24-H22) | I23: =IF(B21<=0,0,I24-I22) | J23: =IF(B21<=0,0,J24-J22) | K23: =IF(B21<=0,0,K24-K22) | L23: =IF(B21<=0,0,L24-L22) | M23: =IF(B21<=0,0,M24-M22) | N23: =IF(B21<=0,0,N24-N22) | O23: =IF(B21<=0,0,O24-O22) | P23: =IF(B21<=0,0,P24-P22) | Q23: =IF(B21<=0,0,Q24-Q22) | R23: =IF(B21<=0,0,R24-R22) | S23: =IF(B21<=0,0,S24-S22) | T23: =IF(B21<=0,0,T24-T22) | U23: =IF(B21<=0,0,U24-U22) | V23: =IF(B21<=0,0,V24-V22) | W23: =IF(B21<=0,0,W24-W22) | X23: =IF(B21<=0,0,X24-X22) | Y23: =IF(B21<=0,0,Y24-Y22) | Z23: =IF(B21<=0,0,Z24-Z22) | AA23: =IF(B21<=0,0,AA24-AA22)
A24: Total Payment — P&I ($) | B24: 0 | C24: =IF(B21<=0,0,ABS(PMT(Inputs!$C$11,Inputs!$C$13,B21,0))) | D24: =IF(C21<=0,0,ABS(PMT(Inputs!$C$11,Inputs!$C$13,B21,0))) | E24: =IF(D21<=0,0,ABS(PMT(Inputs!$C$11,Inputs!$C$13,B21,0))) | F24: =IF(E21<=0,0,ABS(PMT(Inputs!$C$11,Inputs!$C$13,B21,0))) | G24: =IF(F21<=0,0,ABS(PMT(Inputs!$C$11,Inputs!$C$13,B21,0))) | H24: =IF(G21<=0,0,ABS(PMT(Inputs!$C$11,Inputs!$C$13,B21,0))) | I24: =IF(H21<=0,0,ABS(PMT(Inputs!$C$11,Inputs!$C$13,B21,0))) | J24: =IF(I21<=0,0,ABS(PMT(Inputs!$C$11,Inputs!$C$13,B21,0))) | K24: =IF(J21<=0,0,ABS(PMT(Inputs!$C$11,Inputs!$C$13,B21,0))) | L24: =IF(K21<=0,0,ABS(PMT(Inputs!$C$11,Inputs!$C$13,B21,0))) | M24: =IF(L21<=0,0,ABS(PMT(Inputs!$C$11,Inputs!$C$13,B21,0))) | N24: =IF(M21<=0,0,ABS(PMT(Inputs!$C$11,Inputs!$C$13,B21,0))) | O24: =IF(N21<=0,0,ABS(PMT(Inputs!$C$11,Inputs!$C$13,B21,0))) | P24: =IF(O21<=0,0,ABS(PMT(Inputs!$C$11,Inputs!$C$13,B21,0))) | Q24: =IF(P21<=0,0,ABS(PMT(Inputs!$C$11,Inputs!$C$13,B21,0))) | R24: =IF(Q21<=0,0,ABS(PMT(Inputs!$C$11,Inputs!$C$13,B21,0))) | S24: =IF(R21<=0,0,ABS(PMT(Inputs!$C$11,Inputs!$C$13,B21,0))) | T24: =IF(S21<=0,0,ABS(PMT(Inputs!$C$11,Inputs!$C$13,B21,0))) | U24: =IF(T21<=0,0,ABS(PMT(Inputs!$C$11,Inputs!$C$13,B21,0))) | V24: =IF(U21<=0,0,ABS(PMT(Inputs!$C$11,Inputs!$C$13,B21,0))) | W24: =IF(V21<=0,0,ABS(PMT(Inputs!$C$11,Inputs!$C$13,B21,0))) | X24: =IF(W21<=0,0,ABS(PMT(Inputs!$C$11,Inputs!$C$13,B21,0))) | Y24: =IF(X21<=0,0,ABS(PMT(Inputs!$C$11,Inputs!$C$13,B21,0))) | Z24: =IF(Y21<=0,0,ABS(PMT(Inputs!$C$11,Inputs!$C$13,B21,0))) | AA24: =IF(Z21<=0,0,ABS(PMT(Inputs!$C$11,Inputs!$C$13,B21,0))) | AB24: =SUM(C24:AA24) | AC24: =NPV(Inputs!$C$12,C24:AA24)
A26: Elec. Bill — No System ($) | B26: 0 | C26: =Inputs!C27 | D26: =C26*(1+Inputs!$C$14) | E26: =D26*(1+Inputs!$C$14) | F26: =E26*(1+Inputs!$C$14) | G26: =F26*(1+Inputs!$C$14) | H26: =G26*(1+Inputs!$C$14) | I26: =H26*(1+Inputs!$C$14) | J26: =I26*(1+Inputs!$C$14) | K26: =J26*(1+Inputs!$C$14) | ... AA26: =Z26*(1+Inputs!$C$14)
A27: Elec. Bill — With System ($) | B27: 0 | C27: =Inputs!D27 | D27: =C27*(1+Inputs!$C$14) | E27: =D27*(1+Inputs!$C$14) | F27: =E27*(1+Inputs!$C$14) | G27: =F27*(1+Inputs!$C$14) | H27: =G27*(1+Inputs!$C$14) | I27: =H27*(1+Inputs!$C$14) | J27: =I27*(1+Inputs!$C$14) | K27: =J27*(1+Inputs!$C$14) | ... AA27: =Z27*(1+Inputs!$C$14)
A28: Bill Savings ($) | B28: 0 | C28: =C26-C27 | D28: =D26-D27 | E28: =E26-E27 | F28: =F26-F27 | G28: =G26-G27 | H28: =H26-H27 | I28: =I26-I27 | J28: =J26-J27 | ... AA28: =AA26-AA27 | AB28: =SUM(C28:AA28) | AC28: =NPV(Inputs!$C$12,C28:AA28)
A29: Incentive Savings — Annual ($) | B29: 0 | C29: 0 | D29: 0 | E29: 0 | F29: 0 | G29: 0 | H29: 0 | I29: 0 | J29: 0 | K29: 0 | L29: 0 | M29: 0 | N29: 0 | O29: 0 | P29: 0 | Q29: 0 | R29: 0 | S29: 0 | T29: 0 | U29: 0 | V29: 0 | W29: 0 | X29: 0 | Y29: 0 | Z29: 0 | AA29: 0 | AB29: =SUM(C29:AA29) | AC29: =NPV(Inputs!$C$12,C29:AA29)
A30: Total Savings ($) | B30: =B28+B29 | C30: =C28+C29 | D30: =D28+D29 | E30: =E28+E29 | F30: =F28+F29 | G30: =G28+G29 | H30: =H28+H29 | I30: =I28+I29 | ... AA30: =AA28+AA29 | AB30: =SUM(C30:AA30) | AC30: =NPV(Inputs!$C$12,C30:AA30)
A31: Net Savings ($) | B31: =B30-B24 | C31: =C30-C24 | D31: =D30-D24 | E31: =E30-E24 | F31: =F30-F24 | G31: =G30-G24 | H31: =H30-H24 | I31: =I30-I24 | ... AA31: =AA30-AA24 | AB31: =SUM(C31:AA31) | AC31: =NPV(Inputs!$C$12,C31:AA31)

Sheet Solar Only Bridge
A1: Solar Only — Bridge (NMB/TOU) Rate
A2: All formulas reference Inputs sheet
A4: Scenario 1: With FedITC
A5: Year | B5: 0 | C5: 1 | D5: 2 | E5: 3 | F5: 4 | G5: 5 | H5: 6 | I5: 7 | J5: 8 | K5: 9 | L5: 10 | M5: 11 | N5: 12 | O5: 13 | P5: 14 | Q5: 15 | R5: 16 | S5: 17 | T5: 18 | U5: 19 | V5: 20 | W5: 21 | X5: 22 | Y5: 23 | Z5: 24 | AA5: 25 | AB5: 25yr Total | AC5: 25yr NPV
A6: Debt Balance ($) | B6: =Inputs!C6-Inputs!C19 | C6: =MAX(0,B6-C8) | D6: =MAX(0,C6-D8) | E6: =MAX(0,D6-E8) | F6: =MAX(0,E6-F8) | G6: =MAX(0,F6-G8) | H6: =MAX(0,G6-H8) | I6: =MAX(0,H6-I8) | J6: =MAX(0,I6-J8) | ... AA6: =MAX(0,Z6-AA8)
A7: Interest Payment ($) | B7: 0 | C7: =IF(B6<=0,0,B6*Inputs!$C$11) | D7: =IF(C6<=0,0,C6*Inputs!$C$11) | E7: =IF(D6<=0,0,D6*Inputs!$C$11) | F7: =IF(E6<=0,0,E6*Inputs!$C$11) | G7: =IF(F6<=0,0,F6*Inputs!$C$11) | H7: =IF(G6<=0,0,G6*Inputs!$C$11) | I7: =IF(H6<=0,0,H6*Inputs!$C$11) | J7: =IF(I6<=0,0,I6*Inputs!$C$11) | ... AA7: =IF(Z6<=0,0,Z6*Inputs!$C$11)
A8: Principal Payment ($) | B8: 0 | C8: =IF(B6<=0,0,C9-C7) | D8: =IF(B6<=0,0,D9-D7) | E8: =IF(B6<=0,0,E9-E7) | F8: =IF(B6<=0,0,F9-F7) | G8: =IF(B6<=0,0,G9-G7) | H8: =IF(B6<=0,0,H9-H7) | I8: =IF(B6<=0,0,I9-I7) | J8: =IF(B6<=0,0,J9-J7) | K8: =IF(B6<=0,0,K9-K7) | L8: =IF(B6<=0,0,L9-L7) | M8: =IF(B6<=0,0,M9-M7) | N8: =IF(B6<=0,0,N9-N7) | O8: =IF(B6<=0,0,O9-O7) | P8: =IF(B6<=0,0,P9-P7) | Q8: =IF(B6<=0,0,Q9-Q7) | R8: =IF(B6<=0,0,R9-R7) | S8: =IF(B6<=0,0,S9-S7) | T8: =IF(B6<=0,0,T9-T7) | U8: =IF(B6<=0,0,U9-U7) | V8: =IF(B6<=0,0,V9-V7) | W8: =IF(B6<=0,0,W9-W7) | X8: =IF(B6<=0,0,X9-X7) | Y8: =IF(B6<=0,0,Y9-Y7) | Z8: =IF(B6<=0,0,Z9-Z7) | AA8: =IF(B6<=0,0,AA9-AA7)
A9: Total Payment — P&I ($) | B9: 0 | C9: =IF(B6<=0,0,ABS(PMT(Inputs!$C$11,Inputs!$C$13,B6,0))) | D9: =IF(C6<=0,0,ABS(PMT(Inputs!$C$11,Inputs!$C$13,B6,0))) | E9: =IF(D6<=0,0,ABS(PMT(Inputs!$C$11,Inputs!$C$13,B6,0))) | F9: =IF(E6<=0,0,ABS(PMT(Inputs!$C$11,Inputs!$C$13,B6,0))) | G9: =IF(F6<=0,0,ABS(PMT(Inputs!$C$11,Inputs!$C$13,B6,0))) | H9: =IF(G6<=0,0,ABS(PMT(Inputs!$C$11,Inputs!$C$13,B6,0))) | I9: =IF(H6<=0,0,ABS(PMT(Inputs!$C$11,Inputs!$C$13,B6,0))) | J9: =IF(I6<=0,0,ABS(PMT(Inputs!$C$11,Inputs!$C$13,B6,0))) | K9: =IF(J6<=0,0,ABS(PMT(Inputs!$C$11,Inputs!$C$13,B6,0))) | L9: =IF(K6<=0,0,ABS(PMT(Inputs!$C$11,Inputs!$C$13,B6,0))) | M9: =IF(L6<=0,0,ABS(PMT(Inputs!$C$11,Inputs!$C$13,B6,0))) | N9: =IF(M6<=0,0,ABS(PMT(Inputs!$C$11,Inputs!$C$13,B6,0))) | O9: =IF(N6<=0,0,ABS(PMT(Inputs!$C$11,Inputs!$C$13,B6,0))) | P9: =IF(O6<=0,0,ABS(PMT(Inputs!$C$11,Inputs!$C$13,B6,0))) | Q9: =IF(P6<=0,0,ABS(PMT(Inputs!$C$11,Inputs!$C$13,B6,0))) | R9: =IF(Q6<=0,0,ABS(PMT(Inputs!$C$11,Inputs!$C$13,B6,0))) | S9: =IF(R6<=0,0,ABS(PMT(Inputs!$C$11,Inputs!$C$13,B6,0))) | T9: =IF(S6<=0,0,ABS(PMT(Inputs!$C$11,Inputs!$C$13,B6,0))) | U9: =IF(T6<=0,0,ABS(PMT(Inputs!$C$11,Inputs!$C$13,B6,0))) | V9: =IF(U6<=0,0,ABS(PMT(Inputs!$C$11,Inputs!$C$13,B6,0))) | W9: =IF(V6<=0,0,ABS(PMT(Inputs!$C$11,Inputs!$C$13,B6,0))) | X9: =IF(W6<=0,0,ABS(PMT(Inputs!$C$11,Inputs!$C$13,B6,0))) | Y9: =IF(X6<=0,0,ABS(PMT(Inputs!$C$11,Inputs!$C$13,B6,0))) | Z9: =IF(Y6<=0,0,ABS(PMT(Inputs!$C$11,Inputs!$C$13,B6,0))) | AA9: =IF(Z6<=0,0,ABS(PMT(Inputs!$C$11,Inputs!$C$13,B6,0))) | AB9: =SUM(C9:AA9) | AC9: =NPV(Inputs!$C$12,C9:AA9)
A11: Elec. Bill — No System ($) | B11: 0 | C11: =Inputs!C28 | D11: =C11*(1+Inputs!$C$14) | E11: =D11*(1+Inputs!$C$14) | F11: =E11*(1+Inputs!$C$14) | G11: =F11*(1+Inputs!$C$14) | H11: =G11*(1+Inputs!$C$14) | I11: =H11*(1+Inputs!$C$14) | J11: =I11*(1+Inputs!$C$14) | K11: =J11*(1+Inputs!$C$14) | ... AA11: =Z11*(1+Inputs!$C$14)
A12: Elec. Bill — With System ($) | B12: 0 | C12: =Inputs!D28 | D12: =C12*(1+Inputs!$C$14) | E12: =D12*(1+Inputs!$C$14) | F12: =E12*(1+Inputs!$C$14) | G12: =F12*(1+Inputs!$C$14) | H12: =G12*(1+Inputs!$C$14) | I12: =H12*(1+Inputs!$C$14) | J12: =I12*(1+Inputs!$C$14) | K12: =J12*(1+Inputs!$C$14) | ... AA12: =Z12*(1+Inputs!$C$14)
A13: Bill Savings ($) | B13: 0 | C13: =C11-C12 | D13: =D11-D12 | E13: =E11-E12 | F13: =F11-F12 | G13: =G11-G12 | H13: =H11-H12 | I13: =I11-I12 | J13: =J11-J12 | ... AA13: =AA11-AA12 | AB13: =SUM(C13:AA13) | AC13: =NPV(Inputs!$C$12,C13:AA13)
A14: Incentive Savings — Annual ($) | B14: 0 | C14: 0 | D14: 0 | E14: 0 | F14: 0 | G14: 0 | H14: 0 | I14: 0 | J14: 0 | K14: 0 | L14: 0 | M14: 0 | N14: 0 | O14: 0 | P14: 0 | Q14: 0 | R14: 0 | S14: 0 | T14: 0 | U14: 0 | V14: 0 | W14: 0 | X14: 0 | Y14: 0 | Z14: 0 | AA14: 0 | AB14: =SUM(C14:AA14) | AC14: =NPV(Inputs!$C$12,C14:AA14)
A15: Total Savings ($) | B15: =B13+B14 | C15: =C13+C14 | D15: =D13+D14 | E15: =E13+E14 | F15: =F13+F14 | G15: =G13+G14 | H15: =H13+H14 | I15: =I13+I14 | ... AA15: =AA13+AA14 | AB15: =SUM(C15:AA15) | AC15: =NPV(Inputs!$C$12,C15:AA15)
A16: Net Savings ($) | B16: =B15-B9 | C16: =C15-C9 | D16: =D15-D9 | E16: =E15-E9 | F16: =F15-F9 | G16: =G15-G9 | H16: =H15-H9 | I16: =I15-I9 | ... AA16: =AA15-AA9 | AB16: =SUM(C16:AA16) | AC16: =NPV(Inputs!$C$12,C16:AA16)
A19: Scenario 2: No Incentives
A20: Year | B20: 0 | C20: 1 | D20: 2 | E20: 3 | F20: 4 | G20: 5 | H20: 6 | I20: 7 | J20: 8 | K20: 9 | L20: 10 | M20: 11 | N20: 12 | O20: 13 | P20: 14 | Q20: 15 | R20: 16 | S20: 17 | T20: 18 | U20: 19 | V20: 20 | W20: 21 | X20: 22 | Y20: 23 | Z20: 24 | AA20: 25 | AB20: 25yr Total | AC20: 25yr NPV
A21: Debt Balance ($) | B21: =Inputs!C6 | C21: =MAX(0,B21-C23) | D21: =MAX(0,C21-D23) | E21: =MAX(0,D21-E23) | F21: =MAX(0,E21-F23) | G21: =MAX(0,F21-G23) | H21: =MAX(0,G21-H23) | I21: =MAX(0,H21-I23) | J21: =MAX(0,I21-J23) | ... AA21: =MAX(0,Z21-AA23)
A22: Interest Payment ($) | B22: 0 | C22: =IF(B21<=0,0,B21*Inputs!$C$11) | D22: =IF(C21<=0,0,C21*Inputs!$C$11) | E22: =IF(D21<=0,0,D21*Inputs!$C$11) | F22: =IF(E21<=0,0,E21*Inputs!$C$11) | G22: =IF(F21<=0,0,F21*Inputs!$C$11) | H22: =IF(G21<=0,0,G21*Inputs!$C$11) | I22: =IF(H21<=0,0,H21*Inputs!$C$11) | J22: =IF(I21<=0,0,I21*Inputs!$C$11) | ... AA22: =IF(Z21<=0,0,Z21*Inputs!$C$11)
A23: Principal Payment ($) | B23: 0 | C23: =IF(B21<=0,0,C24-C22) | D23: =IF(B21<=0,0,D24-D22) | E23: =IF(B21<=0,0,E24-E22) | F23: =IF(B21<=0,0,F24-F22) | G23: =IF(B21<=0,0,G24-G22) | H23: =IF(B21<=0,0,H24-H22) | I23: =IF(B21<=0,0,I24-I22) | J23: =IF(B21<=0,0,J24-J22) | K23: =IF(B21<=0,0,K24-K22) | L23: =IF(B21<=0,0,L24-L22) | M23: =IF(B21<=0,0,M24-M22) | N23: =IF(B21<=0,0,N24-N22) | O23: =IF(B21<=0,0,O24-O22) | P23: =IF(B21<=0,0,P24-P22) | Q23: =IF(B21<=0,0,Q24-Q22) | R23: =IF(B21<=0,0,R24-R22) | S23: =IF(B21<=0,0,S24-S22) | T23: =IF(B21<=0,0,T24-T22) | U23: =IF(B21<=0,0,U24-U22) | V23: =IF(B21<=0,0,V24-V22) | W23: =IF(B21<=0,0,W24-W22) | X23: =IF(B21<=0,0,X24-X22) | Y23: =IF(B21<=0,0,Y24-Y22) | Z23: =IF(B21<=0,0,Z24-Z22) | AA23: =IF(B21<=0,0,AA24-AA22)
A24: Total Payment — P&I ($) | B24: 0 | C24: =IF(B21<=0,0,ABS(PMT(Inputs!$C$11,Inputs!$C$13,B21,0))) | D24: =IF(C21<=0,0,ABS(PMT(Inputs!$C$11,Inputs!$C$13,B21,0))) | E24: =IF(D21<=0,0,ABS(PMT(Inputs!$C$11,Inputs!$C$13,B21,0))) | F24: =IF(E21<=0,0,ABS(PMT(Inputs!$C$11,Inputs!$C$13,B21,0))) | G24: =IF(F21<=0,0,ABS(PMT(Inputs!$C$11,Inputs!$C$13,B21,0))) | H24: =IF(G21<=0,0,ABS(PMT(Inputs!$C$11,Inputs!$C$13,B21,0))) | I24: =IF(H21<=0,0,ABS(PMT(Inputs!$C$11,Inputs!$C$13,B21,0))) | J24: =IF(I21<=0,0,ABS(PMT(Inputs!$C$11,Inputs!$C$13,B21,0))) | K24: =IF(J21<=0,0,ABS(PMT(Inputs!$C$11,Inputs!$C$13,B21,0))) | L24: =IF(K21<=0,0,ABS(PMT(Inputs!$C$11,Inputs!$C$13,B21,0))) | M24: =IF(L21<=0,0,ABS(PMT(Inputs!$C$11,Inputs!$C$13,B21,0))) | N24: =IF(M21<=0,0,ABS(PMT(Inputs!$C$11,Inputs!$C$13,B21,0))) | O24: =IF(N21<=0,0,ABS(PMT(Inputs!$C$11,Inputs!$C$13,B21,0))) | P24: =IF(O21<=0,0,ABS(PMT(Inputs!$C$11,Inputs!$C$13,B21,0))) | Q24: =IF(P21<=0,0,ABS(PMT(Inputs!$C$11,Inputs!$C$13,B21,0))) | R24: =IF(Q21<=0,0,ABS(PMT(Inputs!$C$11,Inputs!$C$13,B21,0))) | S24: =IF(R21<=0,0,ABS(PMT(Inputs!$C$11,Inputs!$C$13,B21,0))) | T24: =IF(S21<=0,0,ABS(PMT(Inputs!$C$11,Inputs!$C$13,B21,0))) | U24: =IF(T21<=0,0,ABS(PMT(Inputs!$C$11,Inputs!$C$13,B21,0))) | V24: =IF(U21<=0,0,ABS(PMT(Inputs!$C$11,Inputs!$C$13,B21,0))) | W24: =IF(V21<=0,0,ABS(PMT(Inputs!$C$11,Inputs!$C$13,B21,0))) | X24: =IF(W21<=0,0,ABS(PMT(Inputs!$C$11,Inputs!$C$13,B21,0))) | Y24: =IF(X21<=0,0,ABS(PMT(Inputs!$C$11,Inputs!$C$13,B21,0))) | Z24: =IF(Y21<=0,0,ABS(PMT(Inputs!$C$11,Inputs!$C$13,B21,0))) | AA24: =IF(Z21<=0,0,ABS(PMT(Inputs!$C$11,Inputs!$C$13,B21,0))) | AB24: =SUM(C24:AA24) | AC24: =NPV(Inputs!$C$12,C24:AA24)
A26: Elec. Bill — No System ($) | B26: 0 | C26: =Inputs!C28 | D26: =C26*(1+Inputs!$C$14) | E26: =D26*(1+Inputs!$C$14) | F26: =E26*(1+Inputs!$C$14) | G26: =F26*(1+Inputs!$C$14) | H26: =G26*(1+Inputs!$C$14) | I26: =H26*(1+Inputs!$C$14) | J26: =I26*(1+Inputs!$C$14) | K26: =J26*(1+Inputs!$C$14) | ... AA26: =Z26*(1+Inputs!$C$14)
A27: Elec. Bill — With System ($) | B27: 0 | C27: =Inputs!D28 | D27: =C27*(1+Inputs!$C$14) | E27: =D27*(1+Inputs!$C$14) | F27: =E27*(1+Inputs!$C$14) | G27: =F27*(1+Inputs!$C$14) | H27: =G27*(1+Inputs!$C$14) | I27: =H27*(1+Inputs!$C$14) | J27: =I27*(1+Inputs!$C$14) | K27: =J27*(1+Inputs!$C$14) | ... AA27: =Z27*(1+Inputs!$C$14)
A28: Bill Savings ($) | B28: 0 | C28: =C26-C27 | D28: =D26-D27 | E28: =E26-E27 | F28: =F26-F27 | G28: =G26-G27 | H28: =H26-H27 | I28: =I26-I27 | J28: =J26-J27 | ... AA28: =AA26-AA27 | AB28: =SUM(C28:AA28) | AC28: =NPV(Inputs!$C$12,C28:AA28)
A29: Incentive Savings — Annual ($) | B29: 0 | C29: 0 | D29: 0 | E29: 0 | F29: 0 | G29: 0 | H29: 0 | I29: 0 | J29: 0 | K29: 0 | L29: 0 | M29: 0 | N29: 0 | O29: 0 | P29: 0 | Q29: 0 | R29: 0 | S29: 0 | T29: 0 | U29: 0 | V29: 0 | W29: 0 | X29: 0 | Y29: 0 | Z29: 0 | AA29: 0 | AB29: =SUM(C29:AA29) | AC29: =NPV(Inputs!$C$12,C29:AA29)
A30: Total Savings ($) | B30: =B28+B29 | C30: =C28+C29 | D30: =D28+D29 | E30: =E28+E29 | F30: =F28+F29 | G30: =G28+G29 | H30: =H28+H29 | I30: =I28+I29 | ... AA30: =AA28+AA29 | AB30: =SUM(C30:AA30) | AC30: =NPV(Inputs!$C$12,C30:AA30)
A31: Net Savings ($) | B31: =B30-B24 | C31: =C30-C24 | D31: =D30-D24 | E31: =E30-E24 | F31: =F30-F24 | G31: =G30-G24 | H31: =H30-H24 | I31: =I30-I24 | ... AA31: =AA30-AA24 | AB31: =SUM(C31:AA31) | AC31: =NPV(Inputs!$C$12,C31:AA31)

Sheet Summary
A1: NC Solar Financing — Summary Dashboard
A2: All values linked to cash flow sheets (green = cross-sheet formula)
A4: System | B4: Scenario | C4: Rate | D4: System Cost ($) | E4: 25yr NPV ($) | F4: Y1 Net Monthly ($)
A5: PV+Storage | B5: FedITC + State | C5: RSC | D5: =Inputs!C5 | E5: ='PV+Storage RSC'!AC16 | F5: ='PV+Storage RSC'!C16/12
A6: PV+Storage | B6: State Only | C6: RSC | D6: =Inputs!C5 | E6: ='PV+Storage RSC'!AC31 | F6: ='PV+Storage RSC'!C31/12
A7: PV+Storage | B7: No Incentives | C7: RSC | D7: =Inputs!C5 | E7: ='PV+Storage RSC'!AC46 | F7: ='PV+Storage RSC'!C46/12
A8: PV+Storage | B8: FedITC + State | C8: Bridge | D8: =Inputs!C5 | E8: ='PV+Storage Bridge'!AC16 | F8: ='PV+Storage Bridge'!C16/12
A9: PV+Storage | B9: State Only | C9: Bridge | D9: =Inputs!C5 | E9: ='PV+Storage Bridge'!AC31 | F9: ='PV+Storage Bridge'!C31/12
A10: PV+Storage | B10: No Incentives | C10: Bridge | D10: =Inputs!C5 | E10: ='PV+Storage Bridge'!AC46 | F10: ='PV+Storage Bridge'!C46/12
A11: Solar Only | B11: With FedITC | C11: RSC | D11: =Inputs!C6 | E11: ='Solar Only RSC'!AC16 | F11: ='Solar Only RSC'!C16/12
A12: Solar Only | B12: No Incentives | C12: RSC | D12: =Inputs!C6 | E12: ='Solar Only RSC'!AC31 | F12: ='Solar Only RSC'!C31/12
A13: Solar Only | B13: With FedITC | C13: Bridge | D13: =Inputs!C6 | E13: ='Solar Only Bridge'!AC16 | F13: ='Solar Only Bridge'!C16/12
A14: Solar Only | B14: No Incentives | C14: Bridge | D14: =Inputs!C6 | E14: ='Solar Only Bridge'!AC31 | F14: ='Solar Only Bridge'!C31/12

Sheet Monthly Cash Flow
A1: Monthly Cash Flow Analysis — Year 1 Average
A2: Shows whether monthly loan payment is covered by monthly bill savings from Day 1
A4: Scenario | B4: Monthly PMT ($) | C4: Monthly Savings ($) | D4: Monthly Net ($) | E4: Cash Flow Positive? | F4: Breakeven Year*
A5: PV+Storage RSC — FedITC + State | B5: ='PV+Storage RSC'!C9/12 | C5: ='PV+Storage RSC'!C15/12 | D5: =C5-B5 | E5: =IF(D5>0,"YES","NO") | F5: =IF(C5<=0,"Never",IF(C5>=B5,"Year 1",IF(B5/C5>=(1+Inputs!$C$14)^Inputs!$C$13,"Never","Year "&CEILING(LN(B5/C5)/LN(1+Inputs!$C$14)+1,1))))
A6: PV+Storage RSC — State Only | B6: ='PV+Storage RSC'!C24/12 | C6: ='PV+Storage RSC'!C30/12 | D6: =C6-B6 | E6: =IF(D6>0,"YES","NO") | F6: =IF(C6<=0,"Never",IF(C6>=B6,"Year 1",IF(B6/C6>=(1+Inputs!$C$14)^Inputs!$C$13,"Never","Year "&CEILING(LN(B6/C6)/LN(1+Inputs!$C$14)+1,1))))
A7: PV+Storage RSC — No Incentives | B7: ='PV+Storage RSC'!C39/12 | C7: ='PV+Storage RSC'!C45/12 | D7: =C7-B7 | E7: =IF(D7>0,"YES","NO") | F7: =IF(C7<=0,"Never",IF(C7>=B7,"Year 1",IF(B7/C7>=(1+Inputs!$C$14)^Inputs!$C$13,"Never","Year "&CEILING(LN(B7/C7)/LN(1+Inputs!$C$14)+1,1))))
A8: PV+Storage Bridge — FedITC + State | B8: ='PV+Storage Bridge'!C9/12 | C8: ='PV+Storage Bridge'!C15/12 | D8: =C8-B8 | E8: =IF(D8>0,"YES","NO") | F8: =IF(C8<=0,"Never",IF(C8>=B8,"Year 1",IF(B8/C8>=(1+Inputs!$C$14)^Inputs!$C$13,"Never","Year "&CEILING(LN(B8/C8)/LN(1+Inputs!$C$14)+1,1))))
A9: PV+Storage Bridge — State Only | B9: ='PV+Storage Bridge'!C24/12 | C9: ='PV+Storage Bridge'!C30/12 | D9: =C9-B9 | E9: =IF(D9>0,"YES","NO") | F9: =IF(C9<=0,"Never",IF(C9>=B9,"Year 1",IF(B9/C9>=(1+Inputs!$C$14)^Inputs!$C$13,"Never","Year "&CEILING(LN(B9/C9)/LN(1+Inputs!$C$14)+1,1))))
A10: PV+Storage Bridge — No Incentives | B10: ='PV+Storage Bridge'!C39/12 | C10: ='PV+Storage Bridge'!C45/12 | D10: =C10-B10 | E10: =IF(D10>0,"YES","NO") | F10: =IF(C10<=0,"Never",IF(C10>=B10,"Year 1",IF(B10/C10>=(1+Inputs!$C$14)^Inputs!$C$13,"Never","Year "&CEILING(LN(B10/C10)/LN(1+Inputs!$C$14)+1,1))))
A11: Solar Only RSC — FedITC | B11: ='Solar Only RSC'!C9/12 | C11: ='Solar Only RSC'!C15/12 | D11: =C11-B11 | E11: =IF(D11>0,"YES","NO") | F11: =IF(C11<=0,"Never",IF(C11>=B11,"Year 1",IF(B11/C11>=(1+Inputs!$C$14)^Inputs!$C$13,"Never","Year "&CEILING(LN(B11/C11)/LN(1+Inputs!$C$14)+1,1))))
A12: Solar Only RSC — No Incentives | B12: ='Solar Only RSC'!C24/12 | C12: ='Solar Only RSC'!C30/12 | D12: =C12-B12 | E12: =IF(D12>0,"YES","NO") | F12: =IF(C12<=0,"Never",IF(C12>=B12,"Year 1",IF(B12/C12>=(1+Inputs!$C$14)^Inputs!$C$13,"Never","Year "&CEILING(LN(B12/C12)/LN(1+Inputs!$C$14)+1,1))))
A13: Solar Only Bridge — FedITC | B13: ='Solar Only Bridge'!C9/12 | C13: ='Solar Only Bridge'!C15/12 | D13: =C13-B13 | E13: =IF(D13>0,"YES","NO") | F13: =IF(C13<=0,"Never",IF(C13>=B13,"Year 1",IF(B13/C13>=(1+Inputs!$C$14)^Inputs!$C$13,"Never","Year "&CEILING(LN(B13/C13)/LN(1+Inputs!$C$14)+1,1))))
A14: Solar Only Bridge — No Incentives | B14: ='Solar Only Bridge'!C24/12 | C14: ='Solar Only Bridge'!C30/12 | D14: =C14-B14 | E14: =IF(D14>0,"YES","NO") | F14: =IF(C14<=0,"Never",IF(C14>=B14,"Year 1",IF(B14/C14>=(1+Inputs!$C$14)^Inputs!$C$13,"Never","Year "&CEILING(LN(B14/C14)/LN(1+Inputs!$C$14)+1,1))))
A16: * Breakeven Year = first year where annual savings (growing at escalation rate) exceed annual loan payment.
A17: Monthly savings are computed as annual averages (annual total / 12). Actual monthly savings vary by season
A18: due to solar generation patterns: summer months produce higher savings, winter months lower. A January start
A19: may show negative cash flow in Month 1 even if the annual average is positive.
A21: Key assumptions:
A22: - Loan payment is fixed (level PMT) over 25 years at 7.24% interest rate
A23: - Bill savings grow annually at the electricity cost escalation rate (2.5%)
A24: - Incentives: FedITC reduces initial principal; EnergyWise is annual recurring credit
A25: - All bill data sourced from SAM simulation for Duke Energy NC residential customers

Sheet Sensitivity Analysis
B1: Sensitivity Analysis — Loan Feasibility Without Federal ITC
B2: All formulas reference Inputs sheet. Change assumptions there to update this analysis.
B4: KEY ASSUMPTIONS (from Inputs sheet)
B5: PV + Storage System Cost | C5: =Inputs!C5
B6: Solar Only System Cost | C6: =Inputs!C6
B7: PowerPair Rebate | C7: =Inputs!C20
B8: EnergyWise Annual Credit | C8: =Inputs!C21
B9: Loan Term | C9: =Inputs!C13
B10: Electricity Escalation Rate | C10: =Inputs!C14
B11: Current Debt Interest Rate | C11: =Inputs!C11
B12: Customer Discount Rate | C12: =Inputs!C12
B14: YEAR 1 ANNUAL BILL SAVINGS
C15: RSC | D15: Bridge
B16: PV+Storage Bill Savings | C16: =Inputs!E25 | D16: =Inputs!E26
B17: PV+Storage + EnergyWise | C17: =Inputs!E25+Inputs!C21 | D17: =Inputs!E26+Inputs!C21
B18: Solar Only Bill Savings | C18: =Inputs!E27 | D18: =Inputs!E28
B20: NET SYSTEM COST WITHOUT ITC
B21: PV+S, No incentives | C21: =C5
B22: PV+S, PowerPair only | C22: =C5-C7
B23: PV+S, PowerPair + EnergyWise* | C23: =C5-C7 | D23: EnergyWise reduces annual cost, not upfront; same loan as row above
B24: Solar Only, No incentives | C24: =C6
B26: SECTION 1: BREAKEVEN INTEREST RATE FOR YEAR 1 NET POSITIVE
B27: Maximum interest rate at which Annual Loan Payment ≤ Annual Savings (Year 1)
B28: Net Loan Amount | C28: Year 1 Savings | D28: Breakeven Rate | E28: Feasible at Market?
B29: PV+S RSC, No incentives | C29: =C21 | D29: =C16 | E29: =IFERROR(RATE(C$9,-D29,C29),0) | F29: =IF(E29>=0.05,"Yes — feasible",IF(E29>0,"No — requires subsidized rate","No — impossible even at 0%"))
